Workbook

Sheet Scenario Summary
A1: METHOD TERRAPIN — SCENARIO SUMMARY
A2: T12 (GL actual) · 2026 Forecast (status quo) · 2026 Modified (changes from Aug 1 go-live, see 2026 Bridge) · 2027 Plan · blue = external actuals
A4: LITTLE WING
B5: T12 (GL actual) | C5: 2026 Forecast | D5: 2026 Modified | E5: 2027 Plan
A6: Revenue | B6: 258287 | C6: 287305 | D6: =287305+'2026 Bridge'!$D$7*'LW Assumptions'!$C$43+'2026 Bridge'!$D$8*'LW Assumptions'!$C$47+'2026 Bridge'!$D$13*'LW Assumptions'!$C$36 -> 300862.55 | E6: ='LW Budget'!$Z$11 -> 298740.15
A7: Cost of goods sold | B7: 81599 | C7: 99691 | D7: =99691+'2026 Bridge'!$D$13*'LW Assumptions'!$C$36*'LW Assumptions'!$C$37 -> 102191 | E7: ='LW Budget'!$Z$18 -> 86932.346
A8: GROSS PROFIT | B8: =B6-B7 -> 176688 | C8: =C6-C7 -> 187614 | D8: =D6-D7 -> 198671.55 | E8: =E6-E7 -> 211807.8
A9: Labor | B9: 164857 | C9: 168162 | D9: =168162-'2026 Bridge'!$D$6*(168162-'LW Assumptions'!$C$25) -> 144741.97 | E9: ='LW Budget'!$Z$21 -> 111953.92
A10: Operating expenses (excl fees & rent) | B10: 105344 | C10: 112209 | D10: =112209+'LW Assumptions'!$C$31*('2026 Bridge'!$D$7*'LW Assumptions'!$C$43+'2026 Bridge'!$D$8*'LW Assumptions'!$C$47+'2026 Bridge'!$D$13*'LW Assumptions'!$C$36) -> 112547.94 | E10: ='LW Budget'!$Z$22+'LW Budget'!$Z$23+'LW Budget'!$Z$24 -> 102800.5
A11: Management fee | B11: 48000 | C11: 48000 | D11: =48000-'2026 Bridge'!$D$9*(48000-'LW Assumptions'!$C$40*(287305+'LW Assumptions'!$C$43+'LW Assumptions'!$C$47+'LW Assumptions'!$C$36)) -> 33330.719 | E11: ='LW Budget'!$Z$25 -> 11949.606
A12: Admin fee (Vessel 5% of F&B) | B12: 0 | C12: 0 | D12: =0 -> 0 | E12: =0 -> 0
A13: Rent / occupancy | B13: 15642 | C13: 17299 | D13: ='LW Assumptions'!$C$41*(287305+'2026 Bridge'!$D$7*'LW Assumptions'!$C$43+'2026 Bridge'!$D$8*'LW Assumptions'!$C$47+'2026 Bridge'!$D$13*'LW Assumptions'!$C$36) -> 18051.753 | E13: ='LW Budget'!$Z$26 -> 17924.409
A14: NET OPERATING INCOME | B14: =B6-B7-B9-B10-B11-B12-B13 -> -157155 | C14: =C6-C7-C9-C10-C11-C12-C13 -> -158056 | D14: =D6-D7-D9-D10-D11-D12-D13 -> -110000.82 | E14: =E6-E7-E9-E10-E11-E12-E13 -> -32820.635
A15: NOI margin | B15: =B14/B6 -> -0.60845106 | C15: =C14/C6 -> -0.55013313 | D15: =D14/D6 -> -0.36561819 | E15: =E14/E6 -> -0.10986349
A17: VESSEL
B18: T12 (GL actual) | C18: 2026 Forecast | D18: 2026 Modified | E18: 2027 Plan
A19: Revenue | B19: ='Vessel 2026 P&L'!$AB$16 -> 351975 | C19: ='Vessel 2026 P&L'!$AB$16 -> 351975 | D19: =C19 -> 351975 | E19: ='Vessel Budget'!$Z$10 -> 398400
A20: Cost of goods sold | B20: ='Vessel 2026 P&L'!$AB$24 -> 122932 | C20: ='Vessel 2026 P&L'!$AB$24 -> 122932 | D20: =C20 -> 122932 | E20: ='Vessel Budget'!$Z$14 -> 170033.8
A21: GROSS PROFIT | B21: =B19-B20 -> 229043 | C21: =C19-C20 -> 229043 | D21: =D19-D20 -> 229043 | E21: =E19-E20 -> 228366.2
A22: Labor | B22: ='Vessel 2026 P&L'!$AB$33 -> 77956 | C22: ='Vessel 2026 P&L'!$AB$33 -> 77956 | D22: =C22 -> 77956 | E22: ='Vessel Budget'!$Z$20 -> 75489.381
A23: Operating expenses (excl fees & rent) | B23: ='Vessel 2026 P&L'!$AB$44+'Vessel 2026 P&L'!$AB$53-'Vessel 2026 P&L'!$AB$50-'Vessel 2026 P&L'!$AB$48 -> 91608 | C23: ='Vessel 2026 P&L'!$AB$44+'Vessel 2026 P&L'!$AB$53-'Vessel 2026 P&L'!$AB$50-'Vessel 2026 P&L'!$AB$48 -> 91608 | D23: =C23 -> 91608 | E23: ='Vessel Budget'!$Z$24+'Vessel Budget'!$Z$23+'Vessel Budget'!$Z$25 -> 101568
A24: Management fee | B24: ='Vessel 2026 P&L'!$AB$50 -> 48000 | C24: ='Vessel 2026 P&L'!$AB$50 -> 48000 | D24: ='Vessel 2026 P&L'!$AB$50-'2026 Bridge'!$D$10*('Vessel 2026 P&L'!$AB$50-'Vessel Assumptions'!$C$30*'Vessel 2026 P&L'!$AB$16) -> 33866.25 | E24: ='Vessel Budget'!$Z$26 -> 15936
A25: Admin fee (Vessel 5% of F&B) | B25: 0 | C25: 0 | D25: ='2026 Bridge'!$D$12*'Vessel Assumptions'!$C$32*SUM('Vessel 2026 P&L'!$AB$9:$AB$13) -> 4823.4583 | E25: ='Vessel Budget'!$Z$27 -> 16600
A26: Rent / occupancy | B26: ='Vessel 2026 P&L'!$AB$48 -> 21342 | C26: ='Vessel 2026 P&L'!$AB$48 -> 21342 | D26: ='Vessel 2026 P&L'!$AB$48-'2026 Bridge'!$D$11*('Vessel 2026 P&L'!$AB$48-0) -> 12449.5 | E26: ='Vessel Budget'!$Z$28 -> 0
A27: NET OPERATING INCOME | B27: =B19-B20-B22-B23-B24-B25-B26 -> -9863 | C27: =C19-C20-C22-C23-C24-C25-C26 -> -9863 | D27: =D19-D20-D22-D23-D24-D25-D26 -> 8339.7917 | E27: =E19-E20-E22-E23-E24-E25-E26 -> 18772.819
A28: NOI margin | B28: =B27/B19 -> -0.028021877 | C28: =C27/C19 -> -0.028021877 | D28: =D27/D19 -> 0.023694273 | E28: =E27/E19 -> 0.04712053
A30: COMBINED
B31: T12 (GL actual) | C31: 2026 Forecast | D31: 2026 Modified | E31: 2027 Plan
A32: Revenue | B32: =B6+B19 -> 610262 | C32: =C6+C19 -> 639280 | D32: =D6+D19 -> 652837.55 | E32: =E6+E19 -> 697140.15
A33: Cost of goods sold | B33: =B7+B20 -> 204531 | C33: =C7+C20 -> 222623 | D33: =D7+D20 -> 225123 | E33: =E7+E20 -> 256966.15
A34: GROSS PROFIT | B34: =B32-B33 -> 405731 | C34: =C32-C33 -> 416657 | D34: =D32-D33 -> 427714.55 | E34: =E32-E33 -> 440174
A35: Labor | B35: =B9+B22 -> 242813 | C35: =C9+C22 -> 246118 | D35: =D9+D22 -> 222697.97 | E35: =E9+E22 -> 187443.3
A36: Operating expenses (excl fees & rent) | B36: =B10+B23 -> 196952 | C36: =C10+C23 -> 203817 | D36: =D10+D23 -> 204155.94 | E36: =E10+E23 -> 204368.5
A37: Management fee | B37: =B11+B24 -> 96000 | C37: =C11+C24 -> 96000 | D37: =D11+D24 -> 67196.969 | E37: =E11+E24 -> 27885.606
A38: Admin fee (Vessel 5% of F&B) | B38: =B12+B25 -> 0 | C38: =C12+C25 -> 0 | D38: =D12+D25 -> 4823.4583 | E38: =E12+E25 -> 16600
A39: Rent / occupancy | B39: =B13+B26 -> 36984 | C39: =C13+C26 -> 38641 | D39: =D13+D26 -> 30501.253 | E39: =E13+E26 -> 17924.409
A40: NET OPERATING INCOME | B40: =B32-B33-B35-B36-B37-B38-B39 -> -167018 | C40: =C32-C33-C35-C36-C37-C38-C39 -> -167919 | D40: =D32-D33-D35-D36-D37-D38-D39 -> -101661.03 | E40: =E32-E33-E35-E36-E37-E38-E39 -> -14047.816
A41: NOI margin | B41: =B40/B32 -> -0.27368245 | C41: =C40/C32 -> -0.26266894 | D41: =D40/D32 -> -0.15572179 | E41: =E40/E32 -> -0.020150634
A43: Vessel T12 seeded with 2026 actual/forecast. Admin fee = 5% of F&B (food+bev); did not exist in T12/Forecast. 2026 Modified = changes live from Aug 1, 2026 (edit dates on 2026 Bridge).

Sheet 2026 Bridge
A1: 2026 MODIFIED — TIME-STAMPED CHANGE BRIDGE
A2: Each change has an effective date (blue = editable). 2026 impact = full-year Δ × months live in 2026 ÷ 12. Base = 2026 status-quo forecast.
A5: Change | B5: Effective date | C5: Months live 2026 | D5: Proration | E5: Full-year Δ NOI | F5: 2026 Δ NOI
A6: Little Wing — Labor restructure (6a–4p, wknd 4h 2nd barista) | B6: 46235 | C6: =MAX(0,13-MONTH(B6)) -> 5 | D6: =C6/12 -> 0.41666667 | E6: =168162-'LW Assumptions'!$C$25 -> 56208.08 | F6: =E6*D6 -> 23420.033
A7: Little Wing — Menu pricing uplift (PMIX) | B7: 46235 | C7: =MAX(0,13-MONTH(B7)) -> 5 | D7: =C7/12 -> 0.41666667 | E7: ='LW Assumptions'!$C$43*(1-'LW Assumptions'!$C$31-'LW Assumptions'!$C$41) -> 16117.13 | F7: =E7*D7 -> 6715.4709
A8: Little Wing — Retail improvement uplift | B8: 46235 | C8: =MAX(0,13-MONTH(B8)) -> 5 | D8: =C8/12 -> 0.41666667 | E8: ='LW Assumptions'!$C$47*(1-'LW Assumptions'!$C$31-'LW Assumptions'!$C$41) -> 2675.2587 | F8: =E8*D8 -> 1114.6911
A9: Little Wing — Management fee: $48K flat → 4% of rev | B9: 46235 | C9: =MAX(0,13-MONTH(B9)) -> 5 | D9: =C9/12 -> 0.41666667 | E9: =48000-'LW Assumptions'!$C$40*(287305+'LW Assumptions'!$C$43+'LW Assumptions'!$C$47+'LW Assumptions'!$C$36) -> 35206.275 | F9: =E9*D9 -> 14669.281
A10: Vessel — Management fee: $48K flat → 4% of rev | B10: 46235 | C10: =MAX(0,13-MONTH(B10)) -> 5 | D10: =C10/12 -> 0.41666667 | E10: ='Vessel 2026 P&L'!$AB$50-'Vessel Assumptions'!$C$30*'Vessel 2026 P&L'!$AB$16 -> 33921 | F10: =E10*D10 -> 14133.75
A11: Vessel — Rent → $0 (waived) | B11: 46235 | C11: =MAX(0,13-MONTH(B11)) -> 5 | D11: =C11/12 -> 0.41666667 | E11: ='Vessel 2026 P&L'!$AB$48-0 -> 21342 | F11: =E11*D11 -> 8892.5
A12: Vessel — Admin fee: +5% of F&B revenue (new charge) | B12: 46235 | C12: =MAX(0,13-MONTH(B12)) -> 5 | D12: =C12/12 -> 0.41666667 | E12: =-'Vessel Assumptions'!$C$32*SUM('Vessel 2026 P&L'!$AB$9:$AB$13) -> -11576.3 | F12: =E12*D12 -> -4823.4583
A13: Little Wing — Retail programming expansion (new merch/goods) | B13: 46235 | C13: =MAX(0,13-MONTH(B13)) -> 5 | D13: =C13/12 -> 0.41666667 | E13: ='LW Assumptions'!$C$36*(1-'LW Assumptions'!$C$37-'LW Assumptions'!$C$31-'LW Assumptions'!$C$41) -> 4980 | F13: =E13*D13 -> 2075
A14: Little Wing — interaction / rounding (4% fee & 6% rent on added revenue) | F14: ='Scenario Summary'!$D$14-'Scenario Summary'!$C$14-(F6+F7+F8+F9+F13) -> 60.7
A17: RECONCILIATION — 2026 NOI
A18: Little Wing — 2026 Forecast (status quo) | F18: ='Scenario Summary'!$C$14 -> -158056
A19: + Little Wing changes (2026 Δ, time-stamped) | F19: =F6+F7+F8+F9+F13+F14 -> 48055.177
A20: Little Wing — 2026 MODIFIED | F20: ='Scenario Summary'!$D$14 -> -110000.82
A22: Vessel — 2026 Forecast (status quo) | F22: ='Scenario Summary'!$C$27 -> -9863
A23: + Vessel changes (2026 Δ, time-stamped) | F23: =F10+F11+F12 -> 18202.792
A24: Vessel — 2026 MODIFIED | F24: ='Scenario Summary'!$D$27 -> 8339.7917
A26: COMBINED — 2026 MODIFIED NOI | F26: ='Scenario Summary'!$D$40 -> -101661.03

Sheet Consolidated P&L
A1: METHOD TERRAPIN — CONSOLIDATED P&L 2027
A2: Vessel (events) + Little Wing (coffee) · FY roll-up · management fee (4%) & rent above NOI · $ and % of revenue
A4: FY 2027 | B4: Vessel | D4: Little Wing | F4: Consolidated
B5: $ | C5: % rev | D5: $ | E5: % rev | F5: $ | G5: % rev
A6: Revenue | B6: ='Vessel Budget'!$Z$10 -> 398400 | C6: =B6/$B$6 -> 1 | D6: ='LW Budget'!$Z$11 -> 298740.15 | E6: =D6/$D$6 -> 1 | F6: =B6+D6 -> 697140.15 | G6: =F6/$F$6 -> 1
A7: Cost of goods sold | B7: ='Vessel Budget'!$Z$14 -> 170033.8 | C7: =B7/$B$6 -> 0.42679167 | D7: ='LW Budget'!$Z$18 -> 86932.346 | E7: =D7/$D$6 -> 0.29099653 | F7: =B7+D7 -> 256966.15 | G7: =F7/$F$6 -> 0.36860041
A8: GROSS PROFIT | B8: =B6-B7 -> 228366.2 | C8: =B8/$B$6 -> 0.57320833 | D8: =D6-D7 -> 211807.8 | E8: =D8/$D$6 -> 0.70900347 | F8: =B8+D8 -> 440174 | G8: =F8/$F$6 -> 0.63139959
A10: Labor | B10: ='Vessel Budget'!$Z$20 -> 75489.381 | C10: =B10/$B$6 -> 0.18948138 | D10: ='LW Budget'!$Z$21 -> 111953.92 | E10: =D10/$D$6 -> 0.37475351 | F10: =B10+D10 -> 187443.3 | G10: =F10/$F$6 -> 0.26887463
A11: Credit card fees | B11: ='Vessel Budget'!$Z$24 -> 9960 | C11: =B11/$B$6 -> 0.025 | D11: ='LW Budget'!$Z$22 -> 7468.5037 | E11: =D11/$D$6 -> 0.025 | F11: =B11+D11 -> 17428.504 | G11: =F11/$F$6 -> 0.025
A12: Controllable expenses | B12: ='Vessel Budget'!$Z$23 -> 80848 | C12: =B12/$B$6 -> 0.20293173 | D12: ='LW Budget'!$Z$23 -> 89675 | E12: =D12/$D$6 -> 0.30017726 | F12: =B12+D12 -> 170523 | G12: =F12/$F$6 -> 0.24460361
A13: Non-controllable expenses | B13: ='Vessel Budget'!$Z$25 -> 10760 | C13: =B13/$B$6 -> 0.027008032 | D13: ='LW Budget'!$Z$24 -> 5657 | E13: =D13/$D$6 -> 0.018936189 | F13: =B13+D13 -> 16417 | G13: =F13/$F$6 -> 0.023549067
A14: Management fee (4% of revenue) | B14: ='Vessel Budget'!$Z$26 -> 15936 | C14: =B14/$B$6 -> 0.04 | D14: ='LW Budget'!$Z$25 -> 11949.606 | E14: =D14/$D$6 -> 0.04 | F14: =B14+D14 -> 27885.606 | G14: =F14/$F$6 -> 0.04
A15: Admin fee (Vessel 5% of F&B) | B15: ='Vessel Budget'!$Z$27 -> 16600 | C15: =B15/$B$6 -> 0.041666667 | D15: =0 -> 0 | E15: =D15/$D$6 -> 0 | F15: =B15+D15 -> 16600 | G15: =F15/$F$6 -> 0.023811568
A16: Rent (Vessel $0 / LW 6%) | B16: ='Vessel Budget'!$Z$28 -> 0 | C16: =B16/$B$6 -> 0 | D16: ='LW Budget'!$Z$26 -> 17924.409 | E16: =D16/$D$6 -> 0.06 | F16: =B16+D16 -> 17924.409 | G16: =F16/$F$6 -> 0.025711342
A17: Total operating expenses | B17: =B10+B11+B12+B13+B14+B15+B16 -> 209593.38 | C17: =B17/$B$6 -> 0.5260878 | D17: =D10+D11+D12+D13+D14+D15+D16 -> 244628.44 | E17: =D17/$D$6 -> 0.81886696 | F17: =B17+D17 -> 454221.82 | G17: =F17/$F$6 -> 0.65155022
A19: NET OPERATING INCOME (after mgmt fee, admin fee & rent) | B19: =B8-B17 -> 18772.819 | C19: =B19/$B$6 -> 0.04712053 | D19: =D8-D17 -> -32820.635 | E19: =D19/$D$6 -> -0.10986349 | F19: =B19+D19 -> -14047.816 | G19: =F19/$F$6 -> -0.020150634
A26: CONSOLIDATED NOI BY MONTH (after mgmt fee & rent)
A27: Month | B27: Vessel | C27: Little Wing | D27: Consolidated | E27: Cumulative
A28: Jan | B28: ='Vessel Budget'!B29 -> 6589.8495 | C28: ='LW Budget'!B27 -> -7042.8916 | D28: =B28+C28 -> -453.04209 | E28: =D28 -> -453.04209
A29: Feb | B29: ='Vessel Budget'!D29 -> -4819.2755 | C29: ='LW Budget'!D27 -> -5497.4199 | D29: =B29+C29 -> -10316.695 | E29: =E28+D29 -> -10769.738
A30: Mar | B30: ='Vessel Budget'!F29 -> 6589.8495 | C30: ='LW Budget'!F27 -> 257.02671 | D30: =B30+C30 -> 6846.8762 | E30: =E29+D30 -> -3922.8613
A31: Apr | B31: ='Vessel Budget'!H29 -> -4819.2755 | C31: ='LW Budget'!H27 -> -3745.4977 | D31: =B31+C31 -> -8564.7732 | E31: =E30+D31 -> -12487.635
A32: May | B32: ='Vessel Budget'!J29 -> 3330.0995 | C32: ='LW Budget'!J27 -> -946.78376 | D32: =B32+C32 -> 2383.3157 | E32: =E31+D32 -> -10104.319
A33: Jun | B33: ='Vessel Budget'!L29 -> 1700.2245 | C33: ='LW Budget'!L27 -> 565.24871 | D33: =B33+C33 -> 2265.4732 | E33: =E32+D33 -> -7838.8456
A34: Jul | B34: ='Vessel Budget'!N29 -> 1700.2245 | C34: ='LW Budget'!N27 -> -2735.0529 | D34: =B34+C34 -> -1034.8284 | E34: =E33+D34 -> -8873.674
A35: Aug | B35: ='Vessel Budget'!P29 -> 1700.2245 | C35: ='LW Budget'!P27 -> -2735.0529 | D35: =B35+C35 -> -1034.8284 | E35: =E34+D35 -> -9908.5024
A36: Sep | B36: ='Vessel Budget'!R29 -> 1700.2245 | C36: ='LW Budget'!R27 -> -2735.0529 | D36: =B36+C36 -> -1034.8284 | E36: =E35+D36 -> -10943.331
A37: Oct | B37: ='Vessel Budget'!T29 -> 1700.2245 | C37: ='LW Budget'!T27 -> -2735.0529 | D37: =B37+C37 -> -1034.8284 | E37: =E36+D37 -> -11978.159
A38: Nov | B38: ='Vessel Budget'!V29 -> 1700.2245 | C38: ='LW Budget'!V27 -> -2735.0529 | D38: =B38+C38 -> -1034.8284 | E38: =E37+D38 -> -13012.988
A39: Dec | B39: ='Vessel Budget'!X29 -> 1700.2245 | C39: ='LW Budget'!X27 -> -2735.0529 | D39: =B39+C39 -> -1034.8284 | E39: =E38+D39 -> -14047.816
A40: FY 2027 | B40: ='Vessel Budget'!$Z$29 -> 18772.819 | C40: ='LW Budget'!$Z$27 -> -32820.635 | D40: =B40+C40 -> -14047.816

Sheet Combined 12-Mo P&L
A1: METHOD TERRAPIN — COMBINED 12-MONTH P&L (2027 PLAN)
A2: Vessel + Little Wing · monthly · mgmt fee (4%), admin fee (Vessel 5% F&B) & rent above NOI
A4: ($) | B4: Jan | C4: Feb | D4: Mar | E4: Apr | F4: May | G4: Jun | H4: Jul | I4: Aug | J4: Sep | K4: Oct | L4: Nov | M4: Dec | N4: FY 2027
A6: Revenue | B6: ='Vessel Budget'!B10+'LW Budget'!B11 -> 65518.62 | C6: ='Vessel Budget'!D10+'LW Budget'!D11 -> 34564.96 | D6: ='Vessel Budget'!F10+'LW Budget'!F11 -> 78018.406 | E6: ='Vessel Budget'!H10+'LW Budget'!H11 -> 37564.809 | F6: ='Vessel Budget'!J10+'LW Budget'!J11 -> 66357.099 | G6: ='Vessel Budget'!L10+'LW Budget'!L11 -> 64146.18 | H6: ='Vessel Budget'!N10+'LW Budget'!N11 -> 58495.012 | I6: ='Vessel Budget'!P10+'LW Budget'!P11 -> 58495.012 | J6: ='Vessel Budget'!R10+'LW Budget'!R11 -> 58495.012 | K6: ='Vessel Budget'!T10+'LW Budget'!T11 -> 58495.012 | L6: ='Vessel Budget'!V10+'LW Budget'!V11 -> 58495.012 | M6: ='Vessel Budget'!X10+'LW Budget'!X11 -> 58495.012 | N6: ='Vessel Budget'!Z10+'LW Budget'!Z11 -> 697140.15
A7: Cost of goods sold | B7: ='Vessel Budget'!B14+'LW Budget'!B18 -> 25583.858 | C7: ='Vessel Budget'!D14+'LW Budget'!D18 -> 12013.733 | D7: ='Vessel Budget'!F14+'LW Budget'!F18 -> 29221.252 | E7: ='Vessel Budget'!H14+'LW Budget'!H18 -> 12886.679 | F7: ='Vessel Budget'!J14+'LW Budget'!J18 -> 24524.219 | G7: ='Vessel Budget'!L14+'LW Budget'!L18 -> 23229.032 | H7: ='Vessel Budget'!N14+'LW Budget'!N18 -> 21584.562 | I7: ='Vessel Budget'!P14+'LW Budget'!P18 -> 21584.562 | J7: ='Vessel Budget'!R14+'LW Budget'!R18 -> 21584.562 | K7: ='Vessel Budget'!T14+'LW Budget'!T18 -> 21584.562 | L7: ='Vessel Budget'!V14+'LW Budget'!V18 -> 21584.562 | M7: ='Vessel Budget'!X14+'LW Budget'!X18 -> 21584.562 | N7: ='Vessel Budget'!Z14+'LW Budget'!Z18 -> 256966.15
A8: GROSS PROFIT | B8: =B6-B7 -> 39934.763 | C8: =C6-C7 -> 22551.227 | D8: =D6-D7 -> 48797.154 | E8: =E6-E7 -> 24678.13 | F8: =F6-F7 -> 41832.88 | G8: =G6-G7 -> 40917.148 | H8: =H6-H7 -> 36910.45 | I8: =I6-I7 -> 36910.45 | ... N8: =N6-N7 -> 440174
A10: Labor | B10: ='Vessel Budget'!B20+'LW Budget'!B21 -> 17499.644 | C10: ='Vessel Budget'!D20+'LW Budget'!D21 -> 13232.969 | D10: ='Vessel Budget'!F20+'LW Budget'!F21 -> 17499.644 | E10: ='Vessel Budget'!H20+'LW Budget'!H21 -> 13232.969 | F10: ='Vessel Budget'!J20+'LW Budget'!J21 -> 16280.594 | G10: ='Vessel Budget'!L20+'LW Budget'!L21 -> 15671.069 | H10: ='Vessel Budget'!N20+'LW Budget'!N21 -> 15671.069 | I10: ='Vessel Budget'!P20+'LW Budget'!P21 -> 15671.069 | J10: ='Vessel Budget'!R20+'LW Budget'!R21 -> 15671.069 | K10: ='Vessel Budget'!T20+'LW Budget'!T21 -> 15671.069 | L10: ='Vessel Budget'!V20+'LW Budget'!V21 -> 15671.069 | M10: ='Vessel Budget'!X20+'LW Budget'!X21 -> 15671.069 | N10: ='Vessel Budget'!Z20+'LW Budget'!Z21 -> 187443.3
A11: Credit card fees | B11: ='Vessel Budget'!B24+'LW Budget'!B22 -> 1637.9655 | C11: ='Vessel Budget'!D24+'LW Budget'!D22 -> 864.124 | D11: ='Vessel Budget'!F24+'LW Budget'!F22 -> 1950.4602 | E11: ='Vessel Budget'!H24+'LW Budget'!H22 -> 939.12023 | F11: ='Vessel Budget'!J24+'LW Budget'!J22 -> 1658.9275 | G11: ='Vessel Budget'!L24+'LW Budget'!L22 -> 1603.6545 | H11: ='Vessel Budget'!N24+'LW Budget'!N22 -> 1462.3753 | I11: ='Vessel Budget'!P24+'LW Budget'!P22 -> 1462.3753 | J11: ='Vessel Budget'!R24+'LW Budget'!R22 -> 1462.3753 | K11: ='Vessel Budget'!T24+'LW Budget'!T22 -> 1462.3753 | L11: ='Vessel Budget'!V24+'LW Budget'!V22 -> 1462.3753 | M11: ='Vessel Budget'!X24+'LW Budget'!X22 -> 1462.3753 | N11: ='Vessel Budget'!Z24+'LW Budget'!Z22 -> 17428.504
A12: Controllable expenses | B12: ='Vessel Budget'!B23+'LW Budget'!B23 -> 14210.25 | C12: ='Vessel Budget'!D23+'LW Budget'!D23 -> 14210.25 | D12: ='Vessel Budget'!F23+'LW Budget'!F23 -> 14210.25 | E12: ='Vessel Budget'!H23+'LW Budget'!H23 -> 14210.25 | F12: ='Vessel Budget'!J23+'LW Budget'!J23 -> 14210.25 | G12: ='Vessel Budget'!L23+'LW Budget'!L23 -> 14210.25 | H12: ='Vessel Budget'!N23+'LW Budget'!N23 -> 14210.25 | I12: ='Vessel Budget'!P23+'LW Budget'!P23 -> 14210.25 | J12: ='Vessel Budget'!R23+'LW Budget'!R23 -> 14210.25 | K12: ='Vessel Budget'!T23+'LW Budget'!T23 -> 14210.25 | L12: ='Vessel Budget'!V23+'LW Budget'!V23 -> 14210.25 | M12: ='Vessel Budget'!X23+'LW Budget'!X23 -> 14210.25 | N12: ='Vessel Budget'!Z23+'LW Budget'!Z23 -> 170523
A13: Non-controllable expenses | B13: ='Vessel Budget'!B25+'LW Budget'!B24 -> 1368.0833 | C13: ='Vessel Budget'!D25+'LW Budget'!D24 -> 1368.0833 | D13: ='Vessel Budget'!F25+'LW Budget'!F24 -> 1368.0833 | E13: ='Vessel Budget'!H25+'LW Budget'!H24 -> 1368.0833 | F13: ='Vessel Budget'!J25+'LW Budget'!J24 -> 1368.0833 | G13: ='Vessel Budget'!L25+'LW Budget'!L24 -> 1368.0833 | H13: ='Vessel Budget'!N25+'LW Budget'!N24 -> 1368.0833 | I13: ='Vessel Budget'!P25+'LW Budget'!P24 -> 1368.0833 | J13: ='Vessel Budget'!R25+'LW Budget'!R24 -> 1368.0833 | K13: ='Vessel Budget'!T25+'LW Budget'!T24 -> 1368.0833 | L13: ='Vessel Budget'!V25+'LW Budget'!V24 -> 1368.0833 | M13: ='Vessel Budget'!X25+'LW Budget'!X24 -> 1368.0833 | N13: ='Vessel Budget'!Z25+'LW Budget'!Z24 -> 16417
A14: Management fee (4% of revenue) | B14: ='Vessel Budget'!B26+'LW Budget'!B25 -> 2620.7448 | C14: ='Vessel Budget'!D26+'LW Budget'!D25 -> 1382.5984 | D14: ='Vessel Budget'!F26+'LW Budget'!F25 -> 3120.7362 | E14: ='Vessel Budget'!H26+'LW Budget'!H25 -> 1502.5924 | F14: ='Vessel Budget'!J26+'LW Budget'!J25 -> 2654.284 | G14: ='Vessel Budget'!L26+'LW Budget'!L25 -> 2565.8472 | H14: ='Vessel Budget'!N26+'LW Budget'!N25 -> 2339.8005 | I14: ='Vessel Budget'!P26+'LW Budget'!P25 -> 2339.8005 | J14: ='Vessel Budget'!R26+'LW Budget'!R25 -> 2339.8005 | K14: ='Vessel Budget'!T26+'LW Budget'!T25 -> 2339.8005 | L14: ='Vessel Budget'!V26+'LW Budget'!V25 -> 2339.8005 | M14: ='Vessel Budget'!X26+'LW Budget'!X25 -> 2339.8005 | N14: ='Vessel Budget'!Z26+'LW Budget'!Z25 -> 27885.606
A15: Admin fee (Vessel 5% of F&B) | B15: ='Vessel Budget'!B27 -> 2000 | C15: ='Vessel Budget'!D27 -> 600 | D15: ='Vessel Budget'!F27 -> 2000 | E15: ='Vessel Budget'!H27 -> 600 | F15: ='Vessel Budget'!J27 -> 1600 | G15: ='Vessel Budget'!L27 -> 1400 | H15: ='Vessel Budget'!N27 -> 1400 | I15: ='Vessel Budget'!P27 -> 1400 | J15: ='Vessel Budget'!R27 -> 1400 | K15: ='Vessel Budget'!T27 -> 1400 | L15: ='Vessel Budget'!V27 -> 1400 | M15: ='Vessel Budget'!X27 -> 1400 | N15: ='Vessel Budget'!Z27 -> 16600
A16: Rent (Vessel $0 / LW 6%) | B16: ='Vessel Budget'!B28+'LW Budget'!B26 -> 1051.1172 | C16: ='Vessel Budget'!D28+'LW Budget'!D26 -> 1209.8976 | D16: ='Vessel Budget'!F28+'LW Budget'!F26 -> 1801.1044 | E16: ='Vessel Budget'!H28+'LW Budget'!H26 -> 1389.8885 | F16: ='Vessel Budget'!J28+'LW Budget'!J26 -> 1677.4259 | G16: ='Vessel Budget'!L28+'LW Budget'!L26 -> 1832.7708 | H16: ='Vessel Budget'!N28+'LW Budget'!N26 -> 1493.7007 | I16: ='Vessel Budget'!P28+'LW Budget'!P26 -> 1493.7007 | J16: ='Vessel Budget'!R28+'LW Budget'!R26 -> 1493.7007 | K16: ='Vessel Budget'!T28+'LW Budget'!T26 -> 1493.7007 | L16: ='Vessel Budget'!V28+'LW Budget'!V26 -> 1493.7007 | M16: ='Vessel Budget'!X28+'LW Budget'!X26 -> 1493.7007 | N16: ='Vessel Budget'!Z28+'LW Budget'!Z26 -> 17924.409
A18: NET OPERATING INCOME | B18: =B8-(B10+B11+B12+B13+B14+B15+B16) -> -453.04209 | C18: =C8-(C10+C11+C12+C13+C14+C15+C16) -> -10316.695 | D18: =D8-(D10+D11+D12+D13+D14+D15+D16) -> 6846.8762 | E18: =E8-(E10+E11+E12+E13+E14+E15+E16) -> -8564.7732 | F18: =F8-(F10+F11+F12+F13+F14+F15+F16) -> 2383.3157 | G18: =G8-(G10+G11+G12+G13+G14+G15+G16) -> 2265.4732 | H18: =H8-(H10+H11+H12+H13+H14+H15+H16) -> -1034.8284 | I18: =I8-(I10+I11+I12+I13+I14+I15+I16) -> -1034.8284 | ... N18: =N8-(N10+N11+N12+N13+N14+N15+N16) -> -14047.816

Sheet Vessel Summary
B2: VESSEL EVENTS — 2027 OPERATING SUMMARY
B3: ="$"&TEXT('Vessel Assumptions'!$C$6,"#,##0")&" F&B min · "&TEXT('Vessel Assumptions'!$C$7,"0%")&" volume · "&TEXT('Vessel Assumptions'!$C$30,"0%")&" mgmt fee" -> $4,000 F&B min · 80% volume · 4% mgmt fee
B5: ANNUAL P&L | C5: $ | D5: % rev | F5: KEY METRICS
B6: Total revenue | C6: ='Vessel Budget'!Z10 -> 398400 | D6: =C6/C6 -> 1 | F6: Net operating margin | G6: ='Vessel Budget'!Z28/'Vessel Budget'!Z10 -> 0
B7: Total COGS | C7: ='Vessel Budget'!Z14 -> 170033.8 | D7: =C7/C6 -> 0.42679167 | F7: Prime cost % | G7: ='Vessel Budget'!Z21/'Vessel Budget'!Z10 -> 0.61627304
B8: Gross profit | C8: ='Vessel Budget'!Z15 -> 228366.2 | D8: =C8/C6 -> 0.57320833 | F8: COGS % | G8: ='Vessel Budget'!Z14/'Vessel Budget'!Z10 -> 0.42679167
B9: Total labor (incl. mgmt) | C9: ='Vessel Budget'!Z20 -> 75489.381 | D9: =C9/C6 -> 0.18948138 | F9: Total events / year | G9: ='Vessel Budget'!Z6 -> 83
B10: Prime cost | C10: ='Vessel Budget'!Z21 -> 245523.18 | D10: =C10/C6 -> 0.61627304 | F10: Avg F&B / event | G10: ='Vessel Assumptions'!C6 -> 4000
B11: Controllable (excl CC) | C11: ='Vessel Budget'!Z23 -> 80848 | D11: =C11/C6 -> 0.20293173 | F11: Revenue / event | G11: ='Vessel Budget'!Z10/'Vessel Budget'!Z6 -> 4800
B12: Credit card fees (2.5%) | C12: ='Vessel Budget'!Z24 -> 9960 | D12: =C12/C6 -> 0.025
B13: Non-controllable | C13: ='Vessel Budget'!Z25 -> 10760 | D13: =C13/C6 -> 0.027008032
B14: Management fee (4% of revenue) | C14: ='Vessel Budget'!Z26 -> 15936 | D14: =C14/C6 -> 0.04
B15: Admin fee (5% of F&B) | C15: ='Vessel Budget'!Z27 -> 16600 | D15: =C15/C6 -> 0.041666667
B16: Rent / occupancy (none) | C16: ='Vessel Budget'!Z28 -> 0 | D16: =C16/C6 -> 0
B17: NET OPERATING INCOME | C17: ='Vessel Budget'!Z29 -> 18772.819 | D17: =C17/C6 -> 0.04712053
B20: Adjust inputs on the Vessel Assumptions tab — every figure recalculates. Management fee = 4% of revenue; no separate rent.

Sheet Vessel Assumptions
B2: VESSEL · EVENT OPERATING MODEL
B3: Model drivers — adjust any input and the 2027 budget recalculates
B5: REVENUE DRIVERS
B6: F&B minimum per event | C6: 4000 | D6: the recommended minimum
B7: Event volume (% of run-rate) | C7: 0.8 | D7: =TEXT($C$7,"0%")&" of Jan–May run-rate" -> 80% of Jan–May run-rate
B8: Food share of F&B | C8: 0.749 | D8: balance is beverage
B9: Service charge (% of F&B) | C9: 0.2 | D9: revenue, not billed labor
B11: COST OF SALES (% of that category's sales)
B12: Food cost % (of food sales) | C12: 0.6 | D12: =TEXT(1-$C$12,"0%")&" margin target" -> 40% margin target
B13: Beverage cost % (of bev sales) | C13: 0.25 | D13: =TEXT(1-$C$13,"0%")&" margin" -> 75% margin
B15: LABOR
B16: Bartenders per event | C16: 1
B17: Servers per event | C17: 2
B18: Hourly rate | C18: 35
B19: Shift hours | C19: 5
B20: Hourly labor per event (calc) | C20: =(C16+C17)*C18*C19 -> 525
B21: Management labor / month | C21: ='Vessel GL Basis'!D8 -> 1787.1667 | D21: linked ← Vessel GL Basis
B22: Payroll taxes & benefits % | C22: 0.161 | D22: on all wages (hourly + mgmt)
B24: OVERHEAD & VARIABLE
B25: Controllable exp / month (excl CC) | C25: ='Vessel GL Basis'!D18 -> 6737.3333 | D25: linked ← Vessel GL Basis
B26: Non-controllable / month | C26: ='Vessel GL Basis'!D24 -> 896.66667 | D26: linked ← Vessel GL Basis
B27: Credit card fee (% of revenue) | C27: 0.025 | D27: variable — own line
B29: OWNER CHARGES (above NOI)
B30: Management fee (% of revenue) | C30: 0.04 | D30: 4% of gross revenue → Method (replaces profit split)
B31: Rent (% of revenue) | C31: 0 | D31: Vessel carries no separate rent (owner)
B32: Admin fee (% of F&B revenue) | C32: 0.05 | D32: 5% of food + beverage sales → Method admin (above NOI)

Sheet Vessel Budget
A1: 2027 BUDGET
A2: $ per month · management fee (4% of revenue) & rent shown above NOI · driven by Vessel Assumptions
A4: ($ / % of revenue) | B4: Jan | D4: Feb | F4: Mar | H4: Apr | J4: May | L4: Jun | N4: Jul | P4: Aug | R4: Sep | T4: Oct | V4: Nov | X4: Dec | Z4: FY 2027
A5: Events (2026 run-rate) | B5: 13 | D5: 4 | F5: 13 | H5: 4 | J5: 10 | L5: =AVERAGE($B5,$D5,$F5,$H5,$J5) -> 8.8 | N5: =AVERAGE($B5,$D5,$F5,$H5,$J5) -> 8.8 | P5: =AVERAGE($B5,$D5,$F5,$H5,$J5) -> 8.8 | R5: =AVERAGE($B5,$D5,$F5,$H5,$J5) -> 8.8 | T5: =AVERAGE($B5,$D5,$F5,$H5,$J5) -> 8.8 | V5: =AVERAGE($B5,$D5,$F5,$H5,$J5) -> 8.8 | X5: =AVERAGE($B5,$D5,$F5,$H5,$J5) -> 8.8 | Z5: =B5+D5+F5+H5+J5+L5+N5+P5+R5+T5+V5+X5 -> 105.6
A6: Events (budgeted, whole) | B6: =ROUND(B5*'Vessel Assumptions'!$C$7,0) -> 10 | D6: =ROUND(D5*'Vessel Assumptions'!$C$7,0) -> 3 | F6: =ROUND(F5*'Vessel Assumptions'!$C$7,0) -> 10 | H6: =ROUND(H5*'Vessel Assumptions'!$C$7,0) -> 3 | J6: =ROUND(J5*'Vessel Assumptions'!$C$7,0) -> 8 | L6: =ROUND(L5*'Vessel Assumptions'!$C$7,0) -> 7 | N6: =ROUND(N5*'Vessel Assumptions'!$C$7,0) -> 7 | P6: =ROUND(P5*'Vessel Assumptions'!$C$7,0) -> 7 | R6: =ROUND(R5*'Vessel Assumptions'!$C$7,0) -> 7 | T6: =ROUND(T5*'Vessel Assumptions'!$C$7,0) -> 7 | V6: =ROUND(V5*'Vessel Assumptions'!$C$7,0) -> 7 | X6: =ROUND(X5*'Vessel Assumptions'!$C$7,0) -> 7 | Z6: =B6+D6+F6+H6+J6+L6+N6+P6+R6+T6+V6+X6 -> 83
A7: Food revenue | B7: =B6*'Vessel Assumptions'!$C$6*'Vessel Assumptions'!$C$8 -> 29960 | C7: =B7/B10 -> 0.62416667 | D7: =D6*'Vessel Assumptions'!$C$6*'Vessel Assumptions'!$C$8 -> 8988 | E7: =D7/D10 -> 0.62416667 | F7: =F6*'Vessel Assumptions'!$C$6*'Vessel Assumptions'!$C$8 -> 29960 | G7: =F7/F10 -> 0.62416667 | H7: =H6*'Vessel Assumptions'!$C$6*'Vessel Assumptions'!$C$8 -> 8988 | I7: =H7/H10 -> 0.62416667 | J7: =J6*'Vessel Assumptions'!$C$6*'Vessel Assumptions'!$C$8 -> 23968 | K7: =J7/J10 -> 0.62416667 | L7: =L6*'Vessel Assumptions'!$C$6*'Vessel Assumptions'!$C$8 -> 20972 | M7: =L7/L10 -> 0.62416667 | N7: =N6*'Vessel Assumptions'!$C$6*'Vessel Assumptions'!$C$8 -> 20972 | O7: =N7/N10 -> 0.62416667 | P7: =P6*'Vessel Assumptions'!$C$6*'Vessel Assumptions'!$C$8 -> 20972 | Q7: =P7/P10 -> 0.62416667 | R7: =R6*'Vessel Assumptions'!$C$6*'Vessel Assumptions'!$C$8 -> 20972 | S7: =R7/R10 -> 0.62416667 | T7: =T6*'Vessel Assumptions'!$C$6*'Vessel Assumptions'!$C$8 -> 20972 | U7: =T7/T10 -> 0.62416667 | V7: =V6*'Vessel Assumptions'!$C$6*'Vessel Assumptions'!$C$8 -> 20972 | W7: =V7/V10 -> 0.62416667 | X7: =X6*'Vessel Assumptions'!$C$6*'Vessel Assumptions'!$C$8 -> 20972 | Y7: =X7/X10 -> 0.62416667 | Z7: =B7+D7+F7+H7+J7+L7+N7+P7+R7+T7+V7+X7 -> 248668 | AA7: =Z7/Z10 -> 0.62416667
A8: Beverage revenue | B8: =B6*'Vessel Assumptions'!$C$6*(1-'Vessel Assumptions'!$C$8) -> 10040 | C8: =B8/B10 -> 0.20916667 | D8: =D6*'Vessel Assumptions'!$C$6*(1-'Vessel Assumptions'!$C$8) -> 3012 | E8: =D8/D10 -> 0.20916667 | F8: =F6*'Vessel Assumptions'!$C$6*(1-'Vessel Assumptions'!$C$8) -> 10040 | G8: =F8/F10 -> 0.20916667 | H8: =H6*'Vessel Assumptions'!$C$6*(1-'Vessel Assumptions'!$C$8) -> 3012 | I8: =H8/H10 -> 0.20916667 | J8: =J6*'Vessel Assumptions'!$C$6*(1-'Vessel Assumptions'!$C$8) -> 8032 | K8: =J8/J10 -> 0.20916667 | L8: =L6*'Vessel Assumptions'!$C$6*(1-'Vessel Assumptions'!$C$8) -> 7028 | M8: =L8/L10 -> 0.20916667 | N8: =N6*'Vessel Assumptions'!$C$6*(1-'Vessel Assumptions'!$C$8) -> 7028 | O8: =N8/N10 -> 0.20916667 | P8: =P6*'Vessel Assumptions'!$C$6*(1-'Vessel Assumptions'!$C$8) -> 7028 | Q8: =P8/P10 -> 0.20916667 | R8: =R6*'Vessel Assumptions'!$C$6*(1-'Vessel Assumptions'!$C$8) -> 7028 | S8: =R8/R10 -> 0.20916667 | T8: =T6*'Vessel Assumptions'!$C$6*(1-'Vessel Assumptions'!$C$8) -> 7028 | U8: =T8/T10 -> 0.20916667 | V8: =V6*'Vessel Assumptions'!$C$6*(1-'Vessel Assumptions'!$C$8) -> 7028 | W8: =V8/V10 -> 0.20916667 | X8: =X6*'Vessel Assumptions'!$C$6*(1-'Vessel Assumptions'!$C$8) -> 7028 | Y8: =X8/X10 -> 0.20916667 | Z8: =B8+D8+F8+H8+J8+L8+N8+P8+R8+T8+V8+X8 -> 83332 | AA8: =Z8/Z10 -> 0.20916667
A9: Service charge | B9: =B6*'Vessel Assumptions'!$C$6*'Vessel Assumptions'!$C$9 -> 8000 | C9: =B9/B10 -> 0.16666667 | D9: =D6*'Vessel Assumptions'!$C$6*'Vessel Assumptions'!$C$9 -> 2400 | E9: =D9/D10 -> 0.16666667 | F9: =F6*'Vessel Assumptions'!$C$6*'Vessel Assumptions'!$C$9 -> 8000 | G9: =F9/F10 -> 0.16666667 | H9: =H6*'Vessel Assumptions'!$C$6*'Vessel Assumptions'!$C$9 -> 2400 | I9: =H9/H10 -> 0.16666667 | J9: =J6*'Vessel Assumptions'!$C$6*'Vessel Assumptions'!$C$9 -> 6400 | K9: =J9/J10 -> 0.16666667 | L9: =L6*'Vessel Assumptions'!$C$6*'Vessel Assumptions'!$C$9 -> 5600 | M9: =L9/L10 -> 0.16666667 | N9: =N6*'Vessel Assumptions'!$C$6*'Vessel Assumptions'!$C$9 -> 5600 | O9: =N9/N10 -> 0.16666667 | P9: =P6*'Vessel Assumptions'!$C$6*'Vessel Assumptions'!$C$9 -> 5600 | Q9: =P9/P10 -> 0.16666667 | R9: =R6*'Vessel Assumptions'!$C$6*'Vessel Assumptions'!$C$9 -> 5600 | S9: =R9/R10 -> 0.16666667 | T9: =T6*'Vessel Assumptions'!$C$6*'Vessel Assumptions'!$C$9 -> 5600 | U9: =T9/T10 -> 0.16666667 | V9: =V6*'Vessel Assumptions'!$C$6*'Vessel Assumptions'!$C$9 -> 5600 | W9: =V9/V10 -> 0.16666667 | X9: =X6*'Vessel Assumptions'!$C$6*'Vessel Assumptions'!$C$9 -> 5600 | Y9: =X9/X10 -> 0.16666667 | Z9: =B9+D9+F9+H9+J9+L9+N9+P9+R9+T9+V9+X9 -> 66400 | AA9: =Z9/Z10 -> 0.16666667
A10: TOTAL REVENUE | B10: =SUM(B7:B9) -> 48000 | C10: =B10/B10 -> 1 | D10: =SUM(D7:D9) -> 14400 | E10: =D10/D10 -> 1 | F10: =SUM(F7:F9) -> 48000 | G10: =F10/F10 -> 1 | H10: =SUM(H7:H9) -> 14400 | I10: =H10/H10 -> 1 | J10: =SUM(J7:J9) -> 38400 | K10: =J10/J10 -> 1 | L10: =SUM(L7:L9) -> 33600 | M10: =L10/L10 -> 1 | N10: =SUM(N7:N9) -> 33600 | O10: =N10/N10 -> 1 | P10: =SUM(P7:P9) -> 33600 | Q10: =P10/P10 -> 1 | R10: =SUM(R7:R9) -> 33600 | S10: =R10/R10 -> 1 | T10: =SUM(T7:T9) -> 33600 | U10: =T10/T10 -> 1 | V10: =SUM(V7:V9) -> 33600 | W10: =V10/V10 -> 1 | X10: =SUM(X7:X9) -> 33600 | Y10: =X10/X10 -> 1 | Z10: =B10+D10+F10+H10+J10+L10+N10+P10+R10+T10+V10+X10 -> 398400 | AA10: =Z10/Z10 -> 1
A12: Food COGS (% of food sales) | B12: =B7*'Vessel Assumptions'!$C$12 -> 17976 | C12: =B12/B7 -> 0.6 | D12: =D7*'Vessel Assumptions'!$C$12 -> 5392.8 | E12: =D12/D7 -> 0.6 | F12: =F7*'Vessel Assumptions'!$C$12 -> 17976 | G12: =F12/F7 -> 0.6 | H12: =H7*'Vessel Assumptions'!$C$12 -> 5392.8 | I12: =H12/H7 -> 0.6 | J12: =J7*'Vessel Assumptions'!$C$12 -> 14380.8 | K12: =J12/J7 -> 0.6 | L12: =L7*'Vessel Assumptions'!$C$12 -> 12583.2 | M12: =L12/L7 -> 0.6 | N12: =N7*'Vessel Assumptions'!$C$12 -> 12583.2 | O12: =N12/N7 -> 0.6 | P12: =P7*'Vessel Assumptions'!$C$12 -> 12583.2 | Q12: =P12/P7 -> 0.6 | R12: =R7*'Vessel Assumptions'!$C$12 -> 12583.2 | S12: =R12/R7 -> 0.6 | T12: =T7*'Vessel Assumptions'!$C$12 -> 12583.2 | U12: =T12/T7 -> 0.6 | V12: =V7*'Vessel Assumptions'!$C$12 -> 12583.2 | W12: =V12/V7 -> 0.6 | X12: =X7*'Vessel Assumptions'!$C$12 -> 12583.2 | Y12: =X12/X7 -> 0.6 | Z12: =B12+D12+F12+H12+J12+L12+N12+P12+R12+T12+V12+X12 -> 149200.8 | AA12: =Z12/Z7 -> 0.6
A13: Beverage COGS (% of bev sales) | B13: =B8*'Vessel Assumptions'!$C$13 -> 2510 | C13: =B13/B8 -> 0.25 | D13: =D8*'Vessel Assumptions'!$C$13 -> 753 | E13: =D13/D8 -> 0.25 | F13: =F8*'Vessel Assumptions'!$C$13 -> 2510 | G13: =F13/F8 -> 0.25 | H13: =H8*'Vessel Assumptions'!$C$13 -> 753 | I13: =H13/H8 -> 0.25 | J13: =J8*'Vessel Assumptions'!$C$13 -> 2008 | K13: =J13/J8 -> 0.25 | L13: =L8*'Vessel Assumptions'!$C$13 -> 1757 | M13: =L13/L8 -> 0.25 | N13: =N8*'Vessel Assumptions'!$C$13 -> 1757 | O13: =N13/N8 -> 0.25 | P13: =P8*'Vessel Assumptions'!$C$13 -> 1757 | Q13: =P13/P8 -> 0.25 | R13: =R8*'Vessel Assumptions'!$C$13 -> 1757 | S13: =R13/R8 -> 0.25 | T13: =T8*'Vessel Assumptions'!$C$13 -> 1757 | U13: =T13/T8 -> 0.25 | V13: =V8*'Vessel Assumptions'!$C$13 -> 1757 | W13: =V13/V8 -> 0.25 | X13: =X8*'Vessel Assumptions'!$C$13 -> 1757 | Y13: =X13/X8 -> 0.25 | Z13: =B13+D13+F13+H13+J13+L13+N13+P13+R13+T13+V13+X13 -> 20833 | AA13: =Z13/Z8 -> 0.25
A14: TOTAL COGS | B14: =B12+B13 -> 20486 | C14: =B14/B10 -> 0.42679167 | D14: =D12+D13 -> 6145.8 | E14: =D14/D10 -> 0.42679167 | F14: =F12+F13 -> 20486 | G14: =F14/F10 -> 0.42679167 | H14: =H12+H13 -> 6145.8 | I14: =H14/H10 -> 0.42679167 | J14: =J12+J13 -> 16388.8 | K14: =J14/J10 -> 0.42679167 | L14: =L12+L13 -> 14340.2 | M14: =L14/L10 -> 0.42679167 | N14: =N12+N13 -> 14340.2 | O14: =N14/N10 -> 0.42679167 | P14: =P12+P13 -> 14340.2 | Q14: =P14/P10 -> 0.42679167 | R14: =R12+R13 -> 14340.2 | S14: =R14/R10 -> 0.42679167 | T14: =T12+T13 -> 14340.2 | U14: =T14/T10 -> 0.42679167 | V14: =V12+V13 -> 14340.2 | W14: =V14/V10 -> 0.42679167 | X14: =X12+X13 -> 14340.2 | Y14: =X14/X10 -> 0.42679167 | Z14: =B14+D14+F14+H14+J14+L14+N14+P14+R14+T14+V14+X14 -> 170033.8 | AA14: =Z14/Z10 -> 0.42679167
A15: GROSS PROFIT | B15: =B10-B14 -> 27514 | C15: =B15/B10 -> 0.57320833 | D15: =D10-D14 -> 8254.2 | E15: =D15/D10 -> 0.57320833 | F15: =F10-F14 -> 27514 | G15: =F15/F10 -> 0.57320833 | H15: =H10-H14 -> 8254.2 | I15: =H15/H10 -> 0.57320833 | J15: =J10-J14 -> 22011.2 | K15: =J15/J10 -> 0.57320833 | L15: =L10-L14 -> 19259.8 | M15: =L15/L10 -> 0.57320833 | N15: =N10-N14 -> 19259.8 | O15: =N15/N10 -> 0.57320833 | P15: =P10-P14 -> 19259.8 | Q15: =P15/P10 -> 0.57320833 | R15: =R10-R14 -> 19259.8 | S15: =R15/R10 -> 0.57320833 | T15: =T10-T14 -> 19259.8 | U15: =T15/T10 -> 0.57320833 | V15: =V10-V14 -> 19259.8 | W15: =V15/V10 -> 0.57320833 | X15: =X10-X14 -> 19259.8 | Y15: =X15/X10 -> 0.57320833 | Z15: =B15+D15+F15+H15+J15+L15+N15+P15+R15+T15+V15+X15 -> 228366.2 | AA15: =Z15/Z10 -> 0.57320833
A17: ="Hourly labor ("&'Vessel Assumptions'!$C$16&" bartender"&IF('Vessel Assumptions'!$C$16=1,"","s")&" + "&'Vessel Assumptions'!$C$17&" server"&IF('Vessel Assumptions'!$C$17=1,"","s")&")" -> Hourly labor (1 bartender + 2 servers) | B17: =B6*'Vessel Assumptions'!$C$20 -> 5250 | C17: =B17/B10 -> 0.109375 | D17: =D6*'Vessel Assumptions'!$C$20 -> 1575 | E17: =D17/D10 -> 0.109375 | F17: =F6*'Vessel Assumptions'!$C$20 -> 5250 | G17: =F17/F10 -> 0.109375 | H17: =H6*'Vessel Assumptions'!$C$20 -> 1575 | I17: =H17/H10 -> 0.109375 | J17: =J6*'Vessel Assumptions'!$C$20 -> 4200 | K17: =J17/J10 -> 0.109375 | L17: =L6*'Vessel Assumptions'!$C$20 -> 3675 | M17: =L17/L10 -> 0.109375 | N17: =N6*'Vessel Assumptions'!$C$20 -> 3675 | O17: =N17/N10 -> 0.109375 | P17: =P6*'Vessel Assumptions'!$C$20 -> 3675 | Q17: =P17/P10 -> 0.109375 | R17: =R6*'Vessel Assumptions'!$C$20 -> 3675 | S17: =R17/R10 -> 0.109375 | T17: =T6*'Vessel Assumptions'!$C$20 -> 3675 | U17: =T17/T10 -> 0.109375 | V17: =V6*'Vessel Assumptions'!$C$20 -> 3675 | W17: =V17/V10 -> 0.109375 | X17: =X6*'Vessel Assumptions'!$C$20 -> 3675 | Y17: =X17/X10 -> 0.109375 | Z17: =B17+D17+F17+H17+J17+L17+N17+P17+R17+T17+V17+X17 -> 43575 | AA17: =Z17/Z10 -> 0.109375
A18: Management labor (GL FOH mgmt) | B18: ='Vessel Assumptions'!$C$21 -> 1787.1667 | C18: =B18/B10 -> 0.037232639 | D18: ='Vessel Assumptions'!$C$21 -> 1787.1667 | E18: =D18/D10 -> 0.1241088 | F18: ='Vessel Assumptions'!$C$21 -> 1787.1667 | G18: =F18/F10 -> 0.037232639 | H18: ='Vessel Assumptions'!$C$21 -> 1787.1667 | I18: =H18/H10 -> 0.1241088 | J18: ='Vessel Assumptions'!$C$21 -> 1787.1667 | K18: =J18/J10 -> 0.046540799 | L18: ='Vessel Assumptions'!$C$21 -> 1787.1667 | M18: =L18/L10 -> 0.053189484 | N18: ='Vessel Assumptions'!$C$21 -> 1787.1667 | O18: =N18/N10 -> 0.053189484 | P18: ='Vessel Assumptions'!$C$21 -> 1787.1667 | Q18: =P18/P10 -> 0.053189484 | R18: ='Vessel Assumptions'!$C$21 -> 1787.1667 | S18: =R18/R10 -> 0.053189484 | T18: ='Vessel Assumptions'!$C$21 -> 1787.1667 | U18: =T18/T10 -> 0.053189484 | V18: ='Vessel Assumptions'!$C$21 -> 1787.1667 | W18: =V18/V10 -> 0.053189484 | X18: ='Vessel Assumptions'!$C$21 -> 1787.1667 | Y18: =X18/X10 -> 0.053189484 | Z18: =B18+D18+F18+H18+J18+L18+N18+P18+R18+T18+V18+X18 -> 21446 | AA18: =Z18/Z10 -> 0.053830321
A19: Payroll taxes & benefits | B19: =(B17+B18)*'Vessel Assumptions'!$C$22 -> 1132.9838 | C19: =B19/B10 -> 0.02360383 | D19: =(D17+D18)*'Vessel Assumptions'!$C$22 -> 541.30883 | E19: =D19/D10 -> 0.037590891 | F19: =(F17+F18)*'Vessel Assumptions'!$C$22 -> 1132.9838 | G19: =F19/F10 -> 0.02360383 | H19: =(H17+H18)*'Vessel Assumptions'!$C$22 -> 541.30883 | I19: =H19/H10 -> 0.037590891 | J19: =(J17+J18)*'Vessel Assumptions'!$C$22 -> 963.93383 | K19: =J19/J10 -> 0.025102444 | L19: =(L17+L18)*'Vessel Assumptions'!$C$22 -> 879.40883 | M19: =L19/L10 -> 0.026172882 | N19: =(N17+N18)*'Vessel Assumptions'!$C$22 -> 879.40883 | O19: =N19/N10 -> 0.026172882 | P19: =(P17+P18)*'Vessel Assumptions'!$C$22 -> 879.40883 | Q19: =P19/P10 -> 0.026172882 | R19: =(R17+R18)*'Vessel Assumptions'!$C$22 -> 879.40883 | S19: =R19/R10 -> 0.026172882 | T19: =(T17+T18)*'Vessel Assumptions'!$C$22 -> 879.40883 | U19: =T19/T10 -> 0.026172882 | V19: =(V17+V18)*'Vessel Assumptions'!$C$22 -> 879.40883 | W19: =V19/V10 -> 0.026172882 | X19: =(X17+X18)*'Vessel Assumptions'!$C$22 -> 879.40883 | Y19: =X19/X10 -> 0.026172882 | Z19: =B19+D19+F19+H19+J19+L19+N19+P19+R19+T19+V19+X19 -> 10468.381 | AA19: =Z19/Z10 -> 0.026276057
A20: TOTAL LABOR | B20: =B17+B18+B19 -> 8170.1505 | C20: =B20/B10 -> 0.17021147 | D20: =D17+D18+D19 -> 3903.4755 | E20: =D20/D10 -> 0.27107469 | F20: =F17+F18+F19 -> 8170.1505 | G20: =F20/F10 -> 0.17021147 | H20: =H17+H18+H19 -> 3903.4755 | I20: =H20/H10 -> 0.27107469 | J20: =J17+J18+J19 -> 6951.1005 | K20: =J20/J10 -> 0.18101824 | L20: =L17+L18+L19 -> 6341.5755 | M20: =L20/L10 -> 0.18873737 | N20: =N17+N18+N19 -> 6341.5755 | O20: =N20/N10 -> 0.18873737 | P20: =P17+P18+P19 -> 6341.5755 | Q20: =P20/P10 -> 0.18873737 | R20: =R17+R18+R19 -> 6341.5755 | S20: =R20/R10 -> 0.18873737 | T20: =T17+T18+T19 -> 6341.5755 | U20: =T20/T10 -> 0.18873737 | V20: =V17+V18+V19 -> 6341.5755 | W20: =V20/V10 -> 0.18873737 | X20: =X17+X18+X19 -> 6341.5755 | Y20: =X20/X10 -> 0.18873737 | Z20: =B20+D20+F20+H20+J20+L20+N20+P20+R20+T20+V20+X20 -> 75489.381 | AA20: =Z20/Z10 -> 0.18948138
A21: PRIME COST | B21: =B14+B20 -> 28656.15 | C21: =B21/B10 -> 0.59700314 | D21: =D14+D20 -> 10049.275 | E21: =D21/D10 -> 0.69786635 | F21: =F14+F20 -> 28656.15 | G21: =F21/F10 -> 0.59700314 | H21: =H14+H20 -> 10049.275 | I21: =H21/H10 -> 0.69786635 | J21: =J14+J20 -> 23339.9 | K21: =J21/J10 -> 0.60780991 | L21: =L14+L20 -> 20681.775 | M21: =L21/L10 -> 0.61552903 | N21: =N14+N20 -> 20681.775 | O21: =N21/N10 -> 0.61552903 | P21: =P14+P20 -> 20681.775 | Q21: =P21/P10 -> 0.61552903 | R21: =R14+R20 -> 20681.775 | S21: =R21/R10 -> 0.61552903 | T21: =T14+T20 -> 20681.775 | U21: =T21/T10 -> 0.61552903 | V21: =V14+V20 -> 20681.775 | W21: =V21/V10 -> 0.61552903 | X21: =X14+X20 -> 20681.775 | Y21: =X21/X10 -> 0.61552903 | Z21: =B21+D21+F21+H21+J21+L21+N21+P21+R21+T21+V21+X21 -> 245523.18 | AA21: =Z21/Z10 -> 0.61627304
A23: Controllable expenses (excl CC) | B23: ='Vessel Assumptions'!$C$25 -> 6737.3333 | C23: =B23/B10 -> 0.14036111 | D23: ='Vessel Assumptions'!$C$25 -> 6737.3333 | E23: =D23/D10 -> 0.46787037 | F23: ='Vessel Assumptions'!$C$25 -> 6737.3333 | G23: =F23/F10 -> 0.14036111 | H23: ='Vessel Assumptions'!$C$25 -> 6737.3333 | I23: =H23/H10 -> 0.46787037 | J23: ='Vessel Assumptions'!$C$25 -> 6737.3333 | K23: =J23/J10 -> 0.17545139 | L23: ='Vessel Assumptions'!$C$25 -> 6737.3333 | M23: =L23/L10 -> 0.20051587 | N23: ='Vessel Assumptions'!$C$25 -> 6737.3333 | O23: =N23/N10 -> 0.20051587 | P23: ='Vessel Assumptions'!$C$25 -> 6737.3333 | Q23: =P23/P10 -> 0.20051587 | R23: ='Vessel Assumptions'!$C$25 -> 6737.3333 | S23: =R23/R10 -> 0.20051587 | T23: ='Vessel Assumptions'!$C$25 -> 6737.3333 | U23: =T23/T10 -> 0.20051587 | V23: ='Vessel Assumptions'!$C$25 -> 6737.3333 | W23: =V23/V10 -> 0.20051587 | X23: ='Vessel Assumptions'!$C$25 -> 6737.3333 | Y23: =X23/X10 -> 0.20051587 | Z23: =B23+D23+F23+H23+J23+L23+N23+P23+R23+T23+V23+X23 -> 80848 | AA23: =Z23/Z10 -> 0.20293173
A24: Credit card fees (2.5% of revenue) | B24: =B10*'Vessel Assumptions'!$C$27 -> 1200 | C24: =B24/B10 -> 0.025 | D24: =D10*'Vessel Assumptions'!$C$27 -> 360 | E24: =D24/D10 -> 0.025 | F24: =F10*'Vessel Assumptions'!$C$27 -> 1200 | G24: =F24/F10 -> 0.025 | H24: =H10*'Vessel Assumptions'!$C$27 -> 360 | I24: =H24/H10 -> 0.025 | J24: =J10*'Vessel Assumptions'!$C$27 -> 960 | K24: =J24/J10 -> 0.025 | L24: =L10*'Vessel Assumptions'!$C$27 -> 840 | M24: =L24/L10 -> 0.025 | N24: =N10*'Vessel Assumptions'!$C$27 -> 840 | O24: =N24/N10 -> 0.025 | P24: =P10*'Vessel Assumptions'!$C$27 -> 840 | Q24: =P24/P10 -> 0.025 | R24: =R10*'Vessel Assumptions'!$C$27 -> 840 | S24: =R24/R10 -> 0.025 | T24: =T10*'Vessel Assumptions'!$C$27 -> 840 | U24: =T24/T10 -> 0.025 | V24: =V10*'Vessel Assumptions'!$C$27 -> 840 | W24: =V24/V10 -> 0.025 | X24: =X10*'Vessel Assumptions'!$C$27 -> 840 | Y24: =X24/X10 -> 0.025 | Z24: =B24+D24+F24+H24+J24+L24+N24+P24+R24+T24+V24+X24 -> 9960 | AA24: =Z24/Z10 -> 0.025
A25: Non-controllable (insurance, legal, reserves) | B25: ='Vessel Assumptions'!$C$26 -> 896.66667 | C25: =B25/B10 -> 0.018680556 | D25: ='Vessel Assumptions'!$C$26 -> 896.66667 | E25: =D25/D10 -> 0.062268519 | F25: ='Vessel Assumptions'!$C$26 -> 896.66667 | G25: =F25/F10 -> 0.018680556 | H25: ='Vessel Assumptions'!$C$26 -> 896.66667 | I25: =H25/H10 -> 0.062268519 | J25: ='Vessel Assumptions'!$C$26 -> 896.66667 | K25: =J25/J10 -> 0.023350694 | L25: ='Vessel Assumptions'!$C$26 -> 896.66667 | M25: =L25/L10 -> 0.026686508 | N25: ='Vessel Assumptions'!$C$26 -> 896.66667 | O25: =N25/N10 -> 0.026686508 | P25: ='Vessel Assumptions'!$C$26 -> 896.66667 | Q25: =P25/P10 -> 0.026686508 | R25: ='Vessel Assumptions'!$C$26 -> 896.66667 | S25: =R25/R10 -> 0.026686508 | T25: ='Vessel Assumptions'!$C$26 -> 896.66667 | U25: =T25/T10 -> 0.026686508 | V25: ='Vessel Assumptions'!$C$26 -> 896.66667 | W25: =V25/V10 -> 0.026686508 | X25: ='Vessel Assumptions'!$C$26 -> 896.66667 | Y25: =X25/X10 -> 0.026686508 | Z25: =B25+D25+F25+H25+J25+L25+N25+P25+R25+T25+V25+X25 -> 10760 | AA25: =Z25/Z10 -> 0.027008032
A26: Management fee (4% of revenue → Method) | B26: =B10*'Vessel Assumptions'!$C$30 -> 1920 | C26: =B26/B10 -> 0.04 | D26: =D10*'Vessel Assumptions'!$C$30 -> 576 | E26: =D26/D10 -> 0.04 | F26: =F10*'Vessel Assumptions'!$C$30 -> 1920 | G26: =F26/F10 -> 0.04 | H26: =H10*'Vessel Assumptions'!$C$30 -> 576 | I26: =H26/H10 -> 0.04 | J26: =J10*'Vessel Assumptions'!$C$30 -> 1536 | K26: =J26/J10 -> 0.04 | L26: =L10*'Vessel Assumptions'!$C$30 -> 1344 | M26: =L26/L10 -> 0.04 | N26: =N10*'Vessel Assumptions'!$C$30 -> 1344 | O26: =N26/N10 -> 0.04 | P26: =P10*'Vessel Assumptions'!$C$30 -> 1344 | Q26: =P26/P10 -> 0.04 | R26: =R10*'Vessel Assumptions'!$C$30 -> 1344 | S26: =R26/R10 -> 0.04 | T26: =T10*'Vessel Assumptions'!$C$30 -> 1344 | U26: =T26/T10 -> 0.04 | V26: =V10*'Vessel Assumptions'!$C$30 -> 1344 | W26: =V26/V10 -> 0.04 | X26: =X10*'Vessel Assumptions'!$C$30 -> 1344 | Y26: =X26/X10 -> 0.04 | Z26: =B26+D26+F26+H26+J26+L26+N26+P26+R26+T26+V26+X26 -> 15936 | AA26: =Z26/Z10 -> 0.04
A27: Admin fee (5% of F&B revenue → Method) | B27: =(B7+B8)*'Vessel Assumptions'!$C$32 -> 2000 | D27: =(D7+D8)*'Vessel Assumptions'!$C$32 -> 600 | F27: =(F7+F8)*'Vessel Assumptions'!$C$32 -> 2000 | H27: =(H7+H8)*'Vessel Assumptions'!$C$32 -> 600 | J27: =(J7+J8)*'Vessel Assumptions'!$C$32 -> 1600 | L27: =(L7+L8)*'Vessel Assumptions'!$C$32 -> 1400 | N27: =(N7+N8)*'Vessel Assumptions'!$C$32 -> 1400 | P27: =(P7+P8)*'Vessel Assumptions'!$C$32 -> 1400 | R27: =(R7+R8)*'Vessel Assumptions'!$C$32 -> 1400 | T27: =(T7+T8)*'Vessel Assumptions'!$C$32 -> 1400 | V27: =(V7+V8)*'Vessel Assumptions'!$C$32 -> 1400 | X27: =(X7+X8)*'Vessel Assumptions'!$C$32 -> 1400 | Z27: =B27+D27+F27+H27+J27+L27+N27+P27+R27+T27+V27+X27 -> 16600
A28: Rent / occupancy (Vessel: none) | B28: =B10*'Vessel Assumptions'!$C$31 -> 0 | C28: =B28/B10 -> 0 | D28: =D10*'Vessel Assumptions'!$C$31 -> 0 | E28: =D28/D10 -> 0 | F28: =F10*'Vessel Assumptions'!$C$31 -> 0 | G28: =F28/F10 -> 0 | H28: =H10*'Vessel Assumptions'!$C$31 -> 0 | I28: =H28/H10 -> 0 | J28: =J10*'Vessel Assumptions'!$C$31 -> 0 | K28: =J28/J10 -> 0 | L28: =L10*'Vessel Assumptions'!$C$31 -> 0 | M28: =L28/L10 -> 0 | N28: =N10*'Vessel Assumptions'!$C$31 -> 0 | O28: =N28/N10 -> 0 | P28: =P10*'Vessel Assumptions'!$C$31 -> 0 | Q28: =P28/P10 -> 0 | R28: =R10*'Vessel Assumptions'!$C$31 -> 0 | S28: =R28/R10 -> 0 | T28: =T10*'Vessel Assumptions'!$C$31 -> 0 | U28: =T28/T10 -> 0 | V28: =V10*'Vessel Assumptions'!$C$31 -> 0 | W28: =V28/V10 -> 0 | X28: =X10*'Vessel Assumptions'!$C$31 -> 0 | Y28: =X28/X10 -> 0 | Z28: =B28+D28+F28+H28+J28+L28+N28+P28+R28+T28+V28+X28 -> 0 | AA28: =Z28/Z10 -> 0
A29: NET OPERATING INCOME (after mgmt fee, admin fee & rent) | B29: =B15-B20-(B23+B24+B25+B26+B27+B28) -> 6589.8495 | D29: =D15-D20-(D23+D24+D25+D26+D27+D28) -> -4819.2755 | F29: =F15-F20-(F23+F24+F25+F26+F27+F28) -> 6589.8495 | H29: =H15-H20-(H23+H24+H25+H26+H27+H28) -> -4819.2755 | J29: =J15-J20-(J23+J24+J25+J26+J27+J28) -> 3330.0995 | L29: =L15-L20-(L23+L24+L25+L26+L27+L28) -> 1700.2245 | N29: =N15-N20-(N23+N24+N25+N26+N27+N28) -> 1700.2245 | P29: =P15-P20-(P23+P24+P25+P26+P27+P28) -> 1700.2245 | R29: =R15-R20-(R23+R24+R25+R26+R27+R28) -> 1700.2245 | T29: =T15-T20-(T23+T24+T25+T26+T27+T28) -> 1700.2245 | V29: =V15-V20-(V23+V24+V25+V26+V27+V28) -> 1700.2245 | X29: =X15-X20-(X23+X24+X25+X26+X27+X28) -> 1700.2245 | Z29: =Z15-Z20-(Z23+Z24+Z25+Z26+Z27+Z28) -> 18772.819
C30: =B30/B10 -> 0 | E30: =D30/D10 -> 0 | G30: =F30/F10 -> 0 | I30: =H30/H10 -> 0 | K30: =J30/J10 -> 0 | M30: =L30/L10 -> 0 | O30: =N30/N10 -> 0 | Q30: =P30/P10 -> 0 | S30: =R30/R10 -> 0 | U30: =T30/T10 -> 0 | W30: =V30/V10 -> 0 | Y30: =X30/X10 -> 0 | AA30: =Z30/Z10 -> 0
C31: =B31/B10 -> 0 | E31: =D31/D10 -> 0 | G31: =F31/F10 -> 0 | I31: =H31/H10 -> 0 | K31: =J31/J10 -> 0 | M31: =L31/L10 -> 0 | O31: =N31/N10 -> 0 | Q31: =P31/P10 -> 0 | S31: =R31/R10 -> 0 | U31: =T31/T10 -> 0 | W31: =V31/V10 -> 0 | Y31: =X31/X10 -> 0 | AA31: =Z31/Z10 -> 0
A33: Management fee = 4% of revenue; admin fee = 5% of food+beverage; Vessel has no separate rent. NOI is the bottom line.

Sheet Vessel GL Basis
A1: VESSEL — GL COST BASIS
A2: Cost basis now linked to Vessel 2026 P&L (Act/For) · controllable vs non-controllable (CC fees excluded)
B4: Expense group | C4: Annual | D4: Monthly
B6: LABOR (in model)
B8: Management labor – FOH mgmt (610300) | C8: ='Vessel 2026 P&L'!$AB$28 -> 21446 | D8: =C8/12 -> 1787.1667
B10: CONTROLLABLE (excl credit card fees)
B11: Direct operating (supplies, linen, equip) | C11: 18543 | D11: =C11/12 -> 1545.25
B12: G&A / accounting / bank | C12: 30300 | D12: =C12/12 -> 2525
B13: Marketing | C13: 13917 | D13: =C13/12 -> 1159.75
B14: Music & entertainment | C14: 6750 | D14: =C14/12 -> 562.5
B15: Repairs & maintenance | C15: 5748 | D15: =C15/12 -> 479
B16: Utilities | C16: 5602 | D16: =C16/12 -> 466.83333
B17: Total controllable (excl CC) | C17: =SUM(C11:C16) -> 80860 | D17: =C17/12 -> 6738.3333
B18: → Controllable / month feed | C18: ='Vessel 2026 P&L'!$AB$44 -> 80848 | D18: =C18/12 -> 6737.3333
B20: NON-CONTROLLABLE (in model)
B21: Insurance – liability | C21: 2106 | D21: =C21/12 -> 175.5
B22: Legal & accounting | C22: 1800 | D22: =C22/12 -> 150
B23: Replacement reserves | C23: 4855 | D23: =C23/12 -> 404.58333
B24: Total non-controllable | C24: ='Vessel 2026 P&L'!$AB$47+'Vessel 2026 P&L'!$AB$49+'Vessel 2026 P&L'!$AB$51+'Vessel 2026 P&L'!$AB$52 -> 10760 | D24: =C24/12 -> 896.66667
B26: VARIABLE / EXCLUDED
B27: Credit card fees (actual GL → now variable 2.5%) | C27: 2745 | D27: =C27/12 -> 228.75
B28: Management fee (→ profit split) | C28: 48000 | D28: =C28/12 -> 4000
B29: Rent / RE tax (owner) | C29: ='Vessel 2026 P&L'!$AB$48 -> 21342 | D29: =C29/12 -> 1778.5

Sheet Vessel 2026 P&L
A1: Vessel
A2: Profit & Loss Summary
A3: 2026
C5: January | E5: February | G5: March | I5: April | K5: May | M5: June | O5: July | Q5: August | S5: September | U5: October | W5: November | Y5: December | AB5: 2026
C6: Actual | E6: Actual | G6: Actual | I6: Actual | K6: Actual | M6: Actual | O6: Forecast | Q6: Forecast | S6: Forecast | U6: Forecast | W6: Forecast | Y6: Forecast | AB6: Act/For/Bud
C7: Amount $ | D7: % | E7: Amount $ | F7: % | G7: Amount $ | H7: % | I7: Amount $ | J7: % | K7: Amount $ | L7: % | M7: Amount $ | N7: % | O7: Amount $ | P7: % | Q7: Amount $ | R7: % | S7: Amount $ | T7: % | U7: Amount $ | V7: % | W7: Amount $ | X7: % | Y7: Amount $ | Z7: % | AB7: Amount $ | AC7: %
A8: Income
A9: Food Sales | C9: 28343 | D9: =IFERROR(C9/C$16,0) -> 0.74355947 | E9: 9119 | F9: =IFERROR(E9/E$16,0) -> 0.54630961 | G9: 21950 | H9: =IFERROR(G9/G$16,0) -> 0.55143826 | I9: 4645 | J9: =IFERROR(I9/I$16,0) -> 0.37079907 | K9: 14241 | L9: =IFERROR(K9/K$16,0) -> 0.34785901 | M9: 15390 | N9: =IFERROR(M9/M$16,0) -> 0.33585754 | O9: 11504 | P9: =IFERROR(O9/O$16,0) -> 0.34786816 | Q9: 8697 | R9: =IFERROR(Q9/Q$16,0) -> 0.34786609 | S9: 8697 | T9: =IFERROR(S9/S$16,0) -> 0.34786609 | U9: 6957 | V9: =IFERROR(U9/U$16,0) -> 0.34785 | W9: 6957 | X9: =IFERROR(W9/W$16,0) -> 0.34785 | Y9: 12175 | Z9: =IFERROR(Y9/Y$16,0) -> 0.34786708 | AB9: =SUM(C9,E9,G9,I9,K9,M9,O9,Q9,S9,U9,W9,Y9) -> 148675 | AC9: =IFERROR(AB9/AB$16,0) -> 0.42240216
A10: Non-Alcoholic Beverage Sales | C10: 5992 | D10: =IFERROR(C10/C$16,0) -> 0.15719608 | E10: 4542 | F10: =IFERROR(E10/E$16,0) -> 0.2721064 | G10: 3907 | H10: =IFERROR(G10/G$16,0) -> 0.098153498 | I10: 1012 | J10: =IFERROR(I10/I$16,0) -> 0.080785503 | K10: 2090 | L10: =IFERROR(K10/K$16,0) -> 0.051051565 | M10: 2193 | N10: =IFERROR(M10/M$16,0) -> 0.047858063 | O10: 1688 | P10: =IFERROR(O10/O$16,0) -> 0.051043242 | Q10: 1276 | R10: =IFERROR(Q10/Q$16,0) -> 0.051037958 | S10: 1276 | T10: =IFERROR(S10/S$16,0) -> 0.051037958 | U10: 1021 | V10: =IFERROR(U10/U$16,0) -> 0.05105 | W10: 1021 | X10: =IFERROR(W10/W$16,0) -> 0.05105 | Y10: 1786 | Z10: =IFERROR(Y10/Y$16,0) -> 0.051030029 | AB10: =SUM(C10,E10,G10,I10,K10,M10,O10,Q10,S10,U10,W10,Y10) -> 27804 | AC10: =IFERROR(AB10/AB$16,0) -> 0.078994247
A11: Liquor Sales | C11: 1351 | D11: =IFERROR(C11/C$16,0) -> 0.035442573 | E11: 2141 | F11: =IFERROR(E11/E$16,0) -> 0.12826504 | G11: 10278 | H11: =IFERROR(G11/G$16,0) -> 0.25820877 | I11: 1836 | J11: =IFERROR(I11/I$16,0) -> 0.14656342 | K11: 5557 | L11: =IFERROR(K11/K$16,0) -> 0.13573854 | M11: 4142 | N11: =IFERROR(M11/M$16,0) -> 0.090391288 | O11: 4489 | P11: =IFERROR(O11/O$16,0) -> 0.13574236 | Q11: 3394 | R11: =IFERROR(Q11/Q$16,0) -> 0.13575457 | S11: 3394 | T11: =IFERROR(S11/S$16,0) -> 0.13575457 | U11: 2715 | V11: =IFERROR(U11/U$16,0) -> 0.13575 | W11: 2715 | X11: =IFERROR(W11/W$16,0) -> 0.13575 | Y11: 4751 | Z11: =IFERROR(Y11/Y$16,0) -> 0.13574674 | AB11: =SUM(C11,E11,G11,I11,K11,M11,O11,Q11,S11,U11,W11,Y11) -> 46763 | AC11: =IFERROR(AB11/AB$16,0) -> 0.13285887
A12: Beer Sales | C12: 40 | D12: =IFERROR(C12/C$16,0) -> 0.001049373 | E12: 0 | F12: =IFERROR(E12/E$16,0) -> 0 | G12: 187 | H12: =IFERROR(G12/G$16,0) -> 0.0046979023 | I12: 34 | J12: =IFERROR(I12/I$16,0) -> 0.0027141375 | K12: 193 | L12: =IFERROR(K12/K$16,0) -> 0.0047143311 | M12: 525 | N12: =IFERROR(M12/M$16,0) -> 0.011457129 | O12: 156 | P12: =IFERROR(O12/O$16,0) -> 0.0047172664 | Q12: 118 | R12: =IFERROR(Q12/Q$16,0) -> 0.0047198112 | S12: 118 | T12: =IFERROR(S12/S$16,0) -> 0.0047198112 | U12: 94 | V12: =IFERROR(U12/U$16,0) -> 0.0047 | W12: 94 | X12: =IFERROR(W12/W$16,0) -> 0.0047 | Y12: 165 | Z12: =IFERROR(Y12/Y$16,0) -> 0.0047144204 | AB12: =SUM(C12,E12,G12,I12,K12,M12,O12,Q12,S12,U12,W12,Y12) -> 1724 | AC12: =IFERROR(AB12/AB$16,0) -> 0.0048980751
A13: Wine Sales | C13: 758 | D13: =IFERROR(C13/C$16,0) -> 0.019885618 | E13: 471 | F13: =IFERROR(E13/E$16,0) -> 0.02821711 | G13: 729 | H13: =IFERROR(G13/G$16,0) -> 0.018314282 | I13: 426 | J13: =IFERROR(I13/I$16,0) -> 0.034006546 | K13: 770 | L13: =IFERROR(K13/K$16,0) -> 0.018808471 | M13: 434 | N13: =IFERROR(M13/M$16,0) -> 0.0094712262 | O13: 622 | P13: =IFERROR(O13/O$16,0) -> 0.018808588 | Q13: 470 | R13: =IFERROR(Q13/Q$16,0) -> 0.018799248 | S13: 470 | T13: =IFERROR(S13/S$16,0) -> 0.018799248 | U13: 376 | V13: =IFERROR(U13/U$16,0) -> 0.0188 | W13: 376 | X13: =IFERROR(W13/W$16,0) -> 0.0188 | Y13: 658 | Z13: =IFERROR(Y13/Y$16,0) -> 0.018800537 | AB13: =SUM(C13,E13,G13,I13,K13,M13,O13,Q13,S13,U13,W13,Y13) -> 6560 | AC13: =IFERROR(AB13/AB$16,0) -> 0.018637687
A14: Other Operating Income | C14: 3280 | D14: =IFERROR(C14/C$16,0) -> 0.086048586 | E14: 419 | F14: =IFERROR(E14/E$16,0) -> 0.025101845 | G14: 2754 | H14: =IFERROR(G14/G$16,0) -> 0.069187288 | I14: 4574 | J14: =IFERROR(I14/I$16,0) -> 0.36513132 | K14: 18088 | L14: =IFERROR(K14/K$16,0) -> 0.44182809 | M14: 23139 | N14: =IFERROR(M14/M$16,0) -> 0.50496476 | O14: 14611 | P14: =IFERROR(O14/O$16,0) -> 0.44182038 | Q14: 11046 | R14: =IFERROR(Q14/Q$16,0) -> 0.44182233 | S14: 11046 | T14: =IFERROR(S14/S$16,0) -> 0.44182233 | U14: 8837 | V14: =IFERROR(U14/U$16,0) -> 0.44185 | W14: 8837 | X14: =IFERROR(W14/W$16,0) -> 0.44185 | Y14: 15464 | Z14: =IFERROR(Y14/Y$16,0) -> 0.4418412 | AB14: =SUM(C14,E14,G14,I14,K14,M14,O14,Q14,S14,U14,W14,Y14) -> 122095 | AC14: =IFERROR(AB14/AB$16,0) -> 0.34688543
A15: Discounts & Comps | C15: -1646 | D15: =IFERROR(C15/C$16,0) -> -0.043181699 | E15: 0 | F15: =IFERROR(E15/E$16,0) -> 0 | G15: 0 | H15: =IFERROR(G15/G$16,0) -> 0 | I15: 0 | J15: =IFERROR(I15/I$16,0) -> 0 | K15: 0 | L15: =IFERROR(K15/K$16,0) -> 0 | M15: 0 | N15: =IFERROR(M15/M$16,0) -> 0 | O15: 0 | P15: =IFERROR(O15/O$16,0) -> 0 | Q15: 0 | R15: =IFERROR(Q15/Q$16,0) -> 0 | S15: 0 | T15: =IFERROR(S15/S$16,0) -> 0 | U15: 0 | V15: =IFERROR(U15/U$16,0) -> 0 | W15: 0 | X15: =IFERROR(W15/W$16,0) -> 0 | Y15: 0 | Z15: =IFERROR(Y15/Y$16,0) -> 0 | AB15: =SUM(C15,E15,G15,I15,K15,M15,O15,Q15,S15,U15,W15,Y15) -> -1646 | AC15: =IFERROR(AB15/AB$16,0) -> -0.0046764685
A16: Total Income | C16: =SUM(C9:C15) -> 38118 | D16: =IFERROR(C16/C$16,0) -> 1 | E16: =SUM(E9:E15) -> 16692 | F16: =IFERROR(E16/E$16,0) -> 1 | G16: =SUM(G9:G15) -> 39805 | H16: =IFERROR(G16/G$16,0) -> 1 | I16: =SUM(I9:I15) -> 12527 | J16: =IFERROR(I16/I$16,0) -> 1 | K16: =SUM(K9:K15) -> 40939 | L16: =IFERROR(K16/K$16,0) -> 1 | M16: =SUM(M9:M15) -> 45823 | N16: =IFERROR(M16/M$16,0) -> 1 | O16: =SUM(O9:O15) -> 33070 | P16: =IFERROR(O16/O$16,0) -> 1 | Q16: =SUM(Q9:Q15) -> 25001 | R16: =IFERROR(Q16/Q$16,0) -> 1 | S16: =SUM(S9:S15) -> 25001 | T16: =IFERROR(S16/S$16,0) -> 1 | U16: =SUM(U9:U15) -> 20000 | V16: =IFERROR(U16/U$16,0) -> 1 | W16: =SUM(W9:W15) -> 20000 | X16: =IFERROR(W16/W$16,0) -> 1 | Y16: =SUM(Y9:Y15) -> 34999 | Z16: =IFERROR(Y16/Y$16,0) -> 1 | AB16: =SUM(AB9:AB15) -> 351975 | AC16: =IFERROR(AB16/AB$16,0) -> 1
A18: Cost of Goods Sold
A19: Food Cost | C19: 18631 | D19: =IFERROR(C19/C$9,0) -> 0.65734044 | E19: 8386 | F19: =IFERROR(E19/E$9,0) -> 0.91961838 | G19: 14740 | H19: =IFERROR(G19/G$9,0) -> 0.6715262 | I19: 4280 | J19: =IFERROR(I19/I$9,0) -> 0.92142088 | K19: 11232 | L19: =IFERROR(K19/K$9,0) -> 0.78870866 | M19: 10735 | N19: =IFERROR(M19/M$9,0) -> 0.69753086 | O19: 7478 | P19: =IFERROR(O19/O$9,0) -> 0.65003477 | Q19: 5653 | R19: =IFERROR(Q19/Q$9,0) -> 0.64999425 | S19: 5653 | T19: =IFERROR(S19/S$9,0) -> 0.64999425 | U19: 4522 | V19: =IFERROR(U19/U$9,0) -> 0.64999281 | W19: 4522 | X19: =IFERROR(W19/W$9,0) -> 0.64999281 | Y19: 7914 | Z19: =IFERROR(Y19/Y$9,0) -> 0.65002053 | AB19: =SUM(C19,E19,G19,I19,K19,M19,O19,Q19,S19,U19,W19,Y19) -> 103746 | AC19: =IFERROR(AB19/AB$9,0) -> 0.69780393
A20: Non-Alcoholic Beverage Cost | C20: 1198 | D20: =IFERROR(C20/C$10,0) -> 0.19993324 | E20: 895 | F20: =IFERROR(E20/E$10,0) -> 0.19704976 | G20: 1888 | H20: =IFERROR(G20/G$10,0) -> 0.48323522 | I20: 0 | J20: =IFERROR(I20/I$10,0) -> 0 | K20: 0 | L20: =IFERROR(K20/K$10,0) -> 0 | M20: 0 | N20: =IFERROR(M20/M$10,0) -> 0 | O20: 506 | P20: =IFERROR(O20/O$10,0) -> 0.29976303 | Q20: 383 | R20: =IFERROR(Q20/Q$10,0) -> 0.30015674 | S20: 383 | T20: =IFERROR(S20/S$10,0) -> 0.30015674 | U20: 306 | V20: =IFERROR(U20/U$10,0) -> 0.29970617 | W20: 306 | X20: =IFERROR(W20/W$10,0) -> 0.29970617 | Y20: 536 | Z20: =IFERROR(Y20/Y$10,0) -> 0.30011198 | AB20: =SUM(C20,E20,G20,I20,K20,M20,O20,Q20,S20,U20,W20,Y20) -> 6401 | AC20: =IFERROR(AB20/AB$10,0) -> 0.23021867
A21: Liquor Cost | C21: 243 | D21: =IFERROR(C21/C$11,0) -> 0.17986677 | E21: 931 | F21: =IFERROR(E21/E$11,0) -> 0.43484353 | G21: 723 | H21: =IFERROR(G21/G$11,0) -> 0.070344425 | I21: 0 | J21: =IFERROR(I21/I$11,0) -> 0 | K21: 1308 | L21: =IFERROR(K21/K$11,0) -> 0.2353788 | M21: 5238 | N21: =IFERROR(M21/M$11,0) -> 1.2646065 | O21: 0 | P21: =IFERROR(O21/O$11,0) -> 0 | Q21: 0 | R21: =IFERROR(Q21/Q$11,0) -> 0 | S21: 0 | T21: =IFERROR(S21/S$11,0) -> 0 | U21: 0 | V21: =IFERROR(U21/U$11,0) -> 0 | W21: 0 | X21: =IFERROR(W21/W$11,0) -> 0 | Y21: 0 | Z21: =IFERROR(Y21/Y$11,0) -> 0 | AB21: =SUM(C21,E21,G21,I21,K21,M21,O21,Q21,S21,U21,W21,Y21) -> 8443 | AC21: =IFERROR(AB21/AB$11,0) -> 0.18054872
A22: Beer Cost | C22: 8 | D22: =IFERROR(C22/C$12,0) -> 0.2 | E22: 707 | F22: =IFERROR(E22/E$12,0) -> 0 | G22: 239 | H22: =IFERROR(G22/G$12,0) -> 1.2780749 | I22: 0 | J22: =IFERROR(I22/I$12,0) -> 0 | K22: 0 | L22: =IFERROR(K22/K$12,0) -> 0 | M22: 180 | N22: =IFERROR(M22/M$12,0) -> 0.34285714 | O22: 47 | P22: =IFERROR(O22/O$12,0) -> 0.30128205 | Q22: 35 | R22: =IFERROR(Q22/Q$12,0) -> 0.29661017 | S22: 35 | T22: =IFERROR(S22/S$12,0) -> 0.29661017 | U22: 29 | V22: =IFERROR(U22/U$12,0) -> 0.30851064 | W22: 29 | X22: =IFERROR(W22/W$12,0) -> 0.30851064 | Y22: 49 | Z22: =IFERROR(Y22/Y$12,0) -> 0.2969697 | AB22: =SUM(C22,E22,G22,I22,K22,M22,O22,Q22,S22,U22,W22,Y22) -> 1358 | AC22: =IFERROR(AB22/AB$12,0) -> 0.78770302
A23: Wine/Sake Cost | C23: 190 | D23: =IFERROR(C23/C$13,0) -> 0.25065963 | E23: 888 | F23: =IFERROR(E23/E$13,0) -> 1.8853503 | G23: 699 | H23: =IFERROR(G23/G$13,0) -> 0.95884774 | I23: 252 | J23: =IFERROR(I23/I$13,0) -> 0.5915493 | K23: 404 | L23: =IFERROR(K23/K$13,0) -> 0.52467532 | M23: 551 | N23: =IFERROR(M23/M$13,0) -> 1.2695853 | O23: 0 | P23: =IFERROR(O23/O$13,0) -> 0 | Q23: 0 | R23: =IFERROR(Q23/Q$13,0) -> 0 | S23: 0 | T23: =IFERROR(S23/S$13,0) -> 0 | U23: 0 | V23: =IFERROR(U23/U$13,0) -> 0 | W23: 0 | X23: =IFERROR(W23/W$13,0) -> 0 | Y23: 0 | Z23: =IFERROR(Y23/Y$13,0) -> 0 | AB23: =SUM(C23,E23,G23,I23,K23,M23,O23,Q23,S23,U23,W23,Y23) -> 2984 | AC23: =IFERROR(AB23/AB$13,0) -> 0.45487805
