Workbook

Sheet Deck Tie-Out (LW)
A1: LITTLE WING — DECK TIE-OUT
A2: Every financial claim in LW_Vessel_Plan_of_Action → its live model source. Model values recalculate; if a Status turns ⚠, deck and model have diverged.
A4: Slide | B4: Claim in deck | C4: Deck value | D4: Model source | E4: Model value (live) | F4: Status / note
A5: 2 | B5: 2026 revenue (Act/For) | C5: $288.7K | D5: LW 2026 P&L AB16 | E5: ='LW 2026 P&L'!$AB$16 -> 288692 | F5: ✓
A6: 2 | B6: 2026 net operating loss | C6: ($164.0K) | D6: LW 2026 P&L AB55 | E6: ='LW 2026 P&L'!$AB$55 -> -164007 | F6: ✓
A7: 2 | B7: Labor as % of revenue | C7: 59% | D7: AB33 / AB16 | E7: ='LW 2026 P&L'!$AB$33/'LW 2026 P&L'!$AB$16 -> 0.58979812 | F7: ✓
A8: 2 | B8: Prime cost % | C8: 95.2% | D8: (AB24+AB33)/AB16 | E8: =('LW 2026 P&L'!$AB$24+'LW 2026 P&L'!$AB$33)/'LW 2026 P&L'!$AB$16 -> 0.9522259 | F8: ✓
A9: 2 | B9: Flat mgmt fee + rent today | C9: $65.4K | D9: AB50 + AB48 | E9: ='LW 2026 P&L'!$AB$50+'LW 2026 P&L'!$AB$48 -> 65381 | F9: ✓
A10: 2 | B10: Discounts & comps | C10: ($18.6K) | D10: LW 2026 P&L AB15 | E10: ='LW 2026 P&L'!$AB$15 -> -18574 | F10: ✓
A11: 4 | B11: Product mix by group (8 categories) | C11: $250.5K total | D11: TTM PMIX export (external workbook) | F11: ≈ ties within mapping of $10.6K uncategorized rings — rebuild from TTM export for exact figures
A12: 5 | B12: Self-serve window share of sales | C12: 17% | D12: Daypart Analysis — TTM post-4pm % | E12: ='LW Daypart Analysis'!$D$59 -> 0.173 | F12: ✓ (17.3%)
A13: 5 | B13: "Three biggest hours ~39% of the day" | C13: ~39% | D13: TTM: 8–10am = $87.2K of $254.9K | E13: =87226/254946 -> 0.3421352 | F13: ⚠ TTM says 34.2% — fix deck copy
A14: 6 | B14: Labor lever (chip) | C14: +$39K/yr | D14: Weekly Compare D29 (annualized savings) | E14: =-'LW Weekly Compare'!$D$29 -> 39027.04 | F14: ✓ · actual-week basis; plan-year basis is $35.3K (170.3→135.0)
A15: 6 | B15: Pricing lever (chip) | C15: +$9K/yr | D15: Menu Pricing C53 (net @90% capture) | E15: ='LW Menu Pricing'!$C$53 -> 9160.92 | F15: ✓
A16: 6 | B16: Retail lever (chip) | C16: +$24K GP/yr | D16: base uplift + programming × margin | E16: ='LW Assumptions'!$C$47+'LW Assumptions'!$C$36*(1-'LW Assumptions'!$C$37) -> 23923.89 | F16: ✓ ($23.9K)
A17: 6 | B17: Owner charges today → plan | C17: $65.4K → $14.5K | D17: LW 2026 P&L AB50+AB48 → LW Budget AB56 | E17: ='LW Budget'!$AB$56 -> 14484.517 | F17: ✓ (plan side; today side row above)
A18: 6 | B18: Owner charges saving (chip) | C18: −$51K/yr | D18: difference of the two | E18: =('LW 2026 P&L'!$AB$50+'LW 2026 P&L'!$AB$48)-'LW Budget'!$AB$56 -> 50896.483 | F18: ✓ ($50.9K)
A19: 6 | B19: Owner charges % of revenue | C19: 22.6% → 4.0% | D19: fee+rent ÷ revenue, both years | E19: ='LW Budget'!$AB$56/'LW Budget'!$AB$20 -> 0.04 | F19: ✓ (plan side 4.0%)
A20: 6 | B20: Programming lever | C20: $xxK → $xxK | D20: NOT MODELED | F20: ⚠ still placeholder in deck AND absent from model — needs event cost/revenue data
A21: 7 | B21: Post-4pm share of sales (TTM) | C21: 17.3% | D21: Daypart Analysis TTM block | E21: ='LW Daypart Analysis'!$D$59 -> 0.173 | F21: ✓
A22: 7 | B22: Barista-required share of post-4pm | C22: 21.5% | D22: Daypart Analysis TTM block | E22: ='LW Daypart Analysis'!$D$60 -> 0.215 | F22: ✓
A23: 7 | B23: Net sales at risk | C23: ~3.7% | D23: barista-required ÷ TTM total | E23: ='LW Daypart Analysis'!$C$60/244323 -> 0.03731945 | F23: ✓
A24: 8 | B24: Proposed loaded labor / week | C24: $2,441 | D24: Weekly Compare C20 | E24: ='LW Weekly Compare'!$C$20 -> 2440.2831 | F24: ✓ whole table = Weekly Compare tab, cols B (current) & C (proposed)
A25: 8 | B25: Weekly savings → annualized | C25: −$750 / ~$39.0K | D25: Weekly Compare C29 / D29 | E25: ='LW Weekly Compare'!$C$29 -> 750.52 | F25: ✓
A26: 9 | B26: Item prices, units & bumps (10 rows) | C26: per deck | D26: LW Menu Pricing rows 6–15 | F26: ✓ tab rebuilt FROM the deck (TTM units, list prices) — deck is source of truth
A27: 11 | B27: Today shelf run-rate | C27: $1,346/wk | D27: Retail Plan B15 ÷ 52 | E27: ='LW Retail Plan'!$B$15/52 -> 1346.0769 | F27: ✓
A28: 11 | B28: Plan-year shelf revenue | C28: $114.9K | D28: Retail Plan E15 | E28: ='LW Retail Plan'!$E$15 -> 114920 | F28: ✓
A29: 11 | B29: Shelf % of go-forward top line | C29: 31.7% | D29: Retail Plan E15 ÷ LW Budget AB20 | E29: ='LW Retail Plan'!$E$15/'LW Budget'!$AB$20 -> 0.31735957 | F29: ✓
A30: 11 | B30: Incremental gross profit | C30: $23.9K/yr | D30: base uplift (0% COGS) + programming margin | E30: ='LW Assumptions'!$C$47+'LW Assumptions'!$C$36*(1-'LW Assumptions'!$C$37) -> 23923.89 | F30: ✓ note: Retail Plan F15 shows $22.5K because it applies blended COGS to the base uplift too — model is the truth
A31: 14 | B31: Total income (Act/For → Mod → 2027) | C31: $288.7/311.2/362.1K | D31: Scenario Summary row 6 (C/D/E) | E31: ='Scenario Summary'!$E$6 -> 362112.92 | F31: ✓ (2027 shown; whole table = Scenario Summary LW block)
A32: 14 | B32: NOP (Act/For → Mod → 2027) | C32: (164.0)/(114.3)/(42.5)K | D32: Scenario Summary row 14 | E32: ='Scenario Summary'!$E$14 -> -42459.19 | F32: ✓
A33: 14 | B33: Loss cut vs Act/For | C33: 74% | D33: 1 − E14/C14 | E33: =1-'Scenario Summary'!$E$14/'Scenario Summary'!$C$14 -> 0.74111355 | F33: ✓
A34: 14 | B34: Combined 2027 (with Vessel) | C34: +$11.8K | D34: Scenario Summary E40 | E34: ='Scenario Summary'!$E$40 -> 11768.405 | F34: ✓
A36: Open items: (1) slide 5 "~39%" should read ~34% (top three hours, TTM); (2) slide 6 programming lever has no model support yet; (3) slide 4 product-mix slide should be regenerated from the TTM export for exact category figures. Everything else ties live.

Sheet Scenario Summary
A1: Method Terrapin
A2: Scenario Summary — T12 · 2026 Forecast · 2026 Modified (changes from effective dates) · 2027 Plan
A4: LITTLE WING
B5: T12 (GL actual) | C5: 2026 Act/For (unmodified) | D5: 2026 Act/For MODIFIED | E5: 2027 Plan
A6: Total Income | B6: 258287 | C6: ='LW 2026 P&L'!$AB$16 -> 288692 | D6: ='LW 2026 Modified'!$AB$20 -> 311227.38 | E6: ='LW Budget'!$AB$20 -> 362112.92
A7: Total COGS | B7: 81599 | C7: ='LW 2026 P&L'!$AB$24 -> 104630 | D7: ='LW 2026 Modified'!$AB$29 -> 113380.05 | E7: ='LW Budget'!$AB$29 -> 134412.11
A8: Gross Profit | B8: =B6-B7 -> 176688 | C8: =C6-C7 -> 184062 | D8: =D6-D7 -> 197847.34 | E8: =E6-E7 -> 227700.81
A9: Total Labor Cost | B9: 164857 | C9: ='LW 2026 P&L'!$AB$33 -> 170270 | D9: ='LW 2026 Modified'!$AB$38 -> 155478.07 | E9: ='LW Budget'!$AB$38 -> 135019.36
A10: Operating Expenses (excl fees & occupancy) | B10: 105344 | C10: ='LW 2026 P&L'!$AB$44+'LW 2026 P&L'!$AB$53-'LW 2026 P&L'!$AB$50-'LW 2026 P&L'!$AB$48 -> 112418 | D10: ='LW 2026 Modified'!$AB$50+'LW 2026 Modified'!$AB$60-'LW 2026 Modified'!$AB$54-'LW 2026 Modified'!$AB$56-'LW 2026 Modified'!$AB$57 -> 112981.38 | E10: ='LW Budget'!$AB$50+'LW Budget'!$AB$60-'LW Budget'!$AB$54-'LW Budget'!$AB$56-'LW Budget'!$AB$57 -> 120656.12
A11: Management Fee | B11: 48000 | C11: ='LW 2026 P&L'!$AB$50 -> 48000 | D11: ='LW 2026 Modified'!$AB$56 -> 34035.215 | E11: ='LW Budget'!$AB$56 -> 14484.517
A12: Admin Fee (Vessel — billed to clients, in income) | B12: 0 | C12: 0 | D12: ='LW 2026 Modified'!$AB$57 -> 0 | E12: =0 -> 0
A13: Occupancy / Rent | B13: 15642 | C13: ='LW 2026 P&L'!$AB$48 -> 17381 | D13: ='LW 2026 Modified'!$AB$54 -> 9681 | E13: ='LW Budget'!$AB$54 -> 0
A14: Net Operating Profit | B14: =B6-B7-B9-B10-B11-B12-B13 -> -157155 | C14: =C6-C7-C9-C10-C11-C12-C13 -> -164007 | D14: =D6-D7-D9-D10-D11-D12-D13 -> -114328.33 | E14: =E6-E7-E9-E10-E11-E12-E13 -> -42459.19
A15: NOP margin | B15: =B14/B6 -> -0.60845106 | C15: =C14/C6 -> -0.56810372 | D15: =D14/D6 -> -0.36734663 | E15: =E14/E6 -> -0.117254
A17: VESSEL
B18: T12 (GL actual) | C18: 2026 Act/For (unmodified) | D18: 2026 Act/For MODIFIED | E18: 2027 Plan
A19: Total Income | B19: ='Vessel 2026 P&L'!$AB$16 -> 351975 | C19: ='Vessel 2026 P&L'!$AB$16 -> 351975 | D19: ='Vessel 2026 Modified'!$AB$20 -> 355463.55 | E19: ='Vessel Budget'!$AB$20 -> 415000
A20: Total COGS | B20: ='Vessel 2026 P&L'!$AB$24 -> 122932 | C20: ='Vessel 2026 P&L'!$AB$24 -> 122932 | D20: ='Vessel 2026 Modified'!$AB$29 -> 122932 | E20: ='Vessel Budget'!$AB$29 -> 170033.8
A21: Gross Profit | B21: =B19-B20 -> 229043 | C21: =C19-C20 -> 229043 | D21: =D19-D20 -> 232531.55 | E21: =E19-E20 -> 244966.2
A22: Total Labor Cost | B22: ='Vessel 2026 P&L'!$AB$33 -> 80034 | C22: ='Vessel 2026 P&L'!$AB$33 -> 80034 | D22: ='Vessel 2026 Modified'!$AB$38 -> 80034 | E22: ='Vessel Budget'!$AB$38 -> 70594.605
A23: Operating Expenses (excl fees & occupancy) | B23: ='Vessel 2026 P&L'!$AB$44+'Vessel 2026 P&L'!$AB$53-'Vessel 2026 P&L'!$AB$50-'Vessel 2026 P&L'!$AB$48 -> 93169 | C23: ='Vessel 2026 P&L'!$AB$44+'Vessel 2026 P&L'!$AB$53-'Vessel 2026 P&L'!$AB$50-'Vessel 2026 P&L'!$AB$48 -> 93169 | D23: ='Vessel 2026 Modified'!$AB$50+'Vessel 2026 Modified'!$AB$60-'Vessel 2026 Modified'!$AB$54-'Vessel 2026 Modified'!$AB$56-'Vessel 2026 Modified'!$AB$57 -> 93169 | E23: ='Vessel Budget'!$AB$50+'Vessel Budget'!$AB$60-'Vessel Budget'!$AB$54-'Vessel Budget'!$AB$56-'Vessel Budget'!$AB$57 -> 103544
A24: Management Fee | B24: ='Vessel 2026 P&L'!$AB$50 -> 48000 | C24: ='Vessel 2026 P&L'!$AB$50 -> 48000 | D24: ='Vessel 2026 Modified'!$AB$56 -> 33139.582 | E24: ='Vessel Budget'!$AB$56 -> 16600
A25: Admin Fee (Vessel — billed to clients, in income) | B25: 0 | C25: 0 | D25: ='Vessel 2026 Modified'!$AB$57 -> 0 | E25: ='Vessel Budget'!$AB$57 -> 0
A26: Occupancy / Rent | B26: ='Vessel 2026 P&L'!$AB$48 -> 21341 | C26: ='Vessel 2026 P&L'!$AB$48 -> 21341 | D26: ='Vessel 2026 Modified'!$AB$54 -> 13841 | E26: ='Vessel Budget'!$AB$54 -> 0
A27: Net Operating Profit | B27: =B19-B20-B22-B23-B24-B25-B26 -> -13501 | C27: =C19-C20-C22-C23-C24-C25-C26 -> -13501 | D27: =D19-D20-D22-D23-D24-D25-D26 -> 12347.968 | E27: =E19-E20-E22-E23-E24-E25-E26 -> 54227.595
A28: NOP margin | B28: =B27/B19 -> -0.038357838 | C28: =C27/C19 -> -0.038357838 | D28: =D27/D19 -> 0.034737649 | E28: =E27/E19 -> 0.1306689
A30: COMBINED
B31: T12 (GL actual) | C31: 2026 Act/For (unmodified) | D31: 2026 Act/For MODIFIED | E31: 2027 Plan
A32: Total Income | B32: =B6+B19 -> 610262 | C32: =C6+C19 -> 640667 | D32: =D6+D19 -> 666690.93 | E32: =E6+E19 -> 777112.92
A33: Total COGS | B33: =B7+B20 -> 204531 | C33: =C7+C20 -> 227562 | D33: =D7+D20 -> 236312.05 | E33: =E7+E20 -> 304445.91
A34: Gross Profit | B34: =B32-B33 -> 405731 | C34: =C32-C33 -> 413105 | D34: =D32-D33 -> 430378.89 | E34: =E32-E33 -> 472667.01
A35: Total Labor Cost | B35: =B9+B22 -> 244891 | C35: =C9+C22 -> 250304 | D35: =D9+D22 -> 235512.07 | E35: =E9+E22 -> 205613.96
A36: Operating Expenses (excl fees & occupancy) | B36: =B10+B23 -> 198513 | C36: =C10+C23 -> 205587 | D36: =D10+D23 -> 206150.38 | E36: =E10+E23 -> 224200.12
A37: Management Fee | B37: =B11+B24 -> 96000 | C37: =C11+C24 -> 96000 | D37: =D11+D24 -> 67174.797 | E37: =E11+E24 -> 31084.517
A38: Admin Fee (Vessel — billed to clients, in income) | B38: =B12+B25 -> 0 | C38: =C12+C25 -> 0 | D38: =D12+D25 -> 0 | E38: =E12+E25 -> 0
A39: Occupancy / Rent | B39: =B13+B26 -> 36983 | C39: =C13+C26 -> 38722 | D39: =D13+D26 -> 23522 | E39: =E13+E26 -> 0
A40: Net Operating Profit | B40: =B32-B33-B35-B36-B37-B38-B39 -> -170656 | C40: =C32-C33-C35-C36-C37-C38-C39 -> -177508 | D40: =D32-D33-D35-D36-D37-D38-D39 -> -101980.36 | E40: =E32-E33-E35-E36-E37-E38-E39 -> 11768.405
A41: NOP margin | B41: =B40/B32 -> -0.27964383 | C41: =C40/C32 -> -0.27706749 | D41: =D40/D32 -> -0.15296497 | E41: =E40/E32 -> 0.015143752
A43: Vessel T12 seeded with 2026 Act/For. Unmodified = accountant Act/For statements (Jan–Jun actual). MODIFIED = monthly build on the 2026 Modified tabs — levers live from the go-live date input (default 2026-08-01, editable on each Modified tab). 2027 Plan: LW = annualized modified run-rate; Vessel = event-driven plan ($4K F&B min × 80% volume).

Sheet 2026 Bridge
A1: 2026 CHANGE RECONCILIATION
A2: Unmodified Act/For → Modified 2026 · driven by the monthly Modified tabs (levers gated by each tab's go-live date input)
B4: Unmodified 2026 NOP | C4: Δ from changes | D4: MODIFIED 2026 NOP | E4: Go-live
A5: Little Wing | B5: ='LW 2026 P&L'!$AB$55 -> -164007 | C5: ='LW 2026 Modified'!$AB$62-'LW 2026 P&L'!$AB$55 -> 49678.671 | D5: ='LW 2026 Modified'!$AB$62 -> -114328.33 | E5: ='LW 2026 Modified'!$C$4 -> 46235
A6: Vessel | B6: ='Vessel 2026 P&L'!$AB$55 -> -13501 | C6: ='Vessel 2026 Modified'!$AB$62-'Vessel 2026 P&L'!$AB$55 -> 25848.968 | D6: ='Vessel 2026 Modified'!$AB$62 -> 12347.968 | E6: ='Vessel 2026 Modified'!$C$4 -> 46235
A7: COMBINED | B7: =B5+B6 -> -177508 | C7: =C5+C6 -> 75527.639 | D7: =D5+D6 -> -101980.36
A9: LEVERS IN THE MODIFIED MONTHS (edit on LW Assumptions / LW Menu Pricing / Vessel Assumptions):
A10: LW — Single-shift staffing: FOH 6:30am–4pm (C20) + wknd 2nd barista (C21) @ $20/hr (C23) + BOH cook $296/wk (C26) + GL mgmt labor kept
A11: LW — Menu pricing uplift (item-level, LW Menu Pricing) × capture % → Food/NA lines, pure margin
A12: LW — Retail: existing-base uplift (C46) + new programming $ (C36) with programming COGS % (C37)
A13: LW — Management fee: $4,000/mo → 4% of revenue (C40) · rent WAIVED (C41=0%) · CC 2.5% on added revenue (C31)
A14: Vessel — Management fee: $4,000/mo → 4% of revenue (C30) · rent waived (C31=0%) · NEW 5% admin fee on F&B billed to clients → Other Operating Income (C32)
A16: 2027: LW Budget = annualized modified run-rate (Dec-2026 forecast base × 12, all levers on). Vessel Budget = event-driven plan.

Sheet Consolidated P&L
A1: Method Terrapin
A2: Consolidated Profit & Loss — FY 2027
A3: 2027
C5: Vessel | F5: Little Wing | I5: Consolidated
C6: FY 2027 | F6: FY 2027 | I6: FY 2027
C7: Amount $ | D7: % | F7: Amount $ | G7: % | I7: Amount $ | J7: %
A11: Income
A12: Food Sales | C12: ='Vessel Budget'!$AB$12 -> 248668 | D12: =IFERROR(C12/C$20,0) -> 0.5992 | F12: ='LW Budget'!$AB$12 -> 135366.3 | G12: =IFERROR(F12/F$20,0) -> 0.37382345 | I12: =C12+F12 -> 384034.3 | J12: =IFERROR(I12/I$20,0) -> 0.49418082
A13: Non-Alcoholic Beverage Sales | C13: ='Vessel Budget'!$AB$13 -> 27965.419 | D13: =IFERROR(C13/C$20,0) -> 0.067386552 | F13: ='LW Budget'!$AB$13 -> 168766.62 | G13: =IFERROR(F13/F$20,0) -> 0.46606075 | I13: =C13+F13 -> 196732.04 | J13: =IFERROR(I13/I$20,0) -> 0.2531576
A14: Liquor Sales | C14: ='Vessel Budget'!$AB$14 -> 47034.487 | D14: =IFERROR(C14/C$20,0) -> 0.11333611 | F14: ='LW Budget'!$AB$14 -> 7308 | G14: =IFERROR(F14/F$20,0) -> 0.02018155 | I14: =C14+F14 -> 54342.487 | J14: =IFERROR(I14/I$20,0) -> 0.069928689
A15: Beer Sales | C15: ='Vessel Budget'!$AB$15 -> 1734.0089 | D15: =IFERROR(C15/C$20,0) -> 0.0041783346 | F15: ='LW Budget'!$AB$15 -> 7380 | G15: =IFERROR(F15/F$20,0) -> 0.020380383 | I15: =C15+F15 -> 9114.0089 | J15: =IFERROR(I15/I$20,0) -> 0.011728037
A16: Wine Sales | C16: ='Vessel Budget'!$AB$16 -> 6598.0848 | D16: =IFERROR(C16/C$20,0) -> 0.015898999 | F16: ='LW Budget'!$AB$16 -> 12540 | G16: =IFERROR(F16/F$20,0) -> 0.034630082 | I16: =C16+F16 -> 19138.085 | J16: =IFERROR(I16/I$20,0) -> 0.024627161
A17: Retail / Merch Sales | C17: ='Vessel Budget'!$AB$17 -> 0 | D17: =IFERROR(C17/C$20,0) -> 0 | F17: ='LW Budget'!$AB$17 -> 44924 | G17: =IFERROR(F17/F$20,0) -> 0.12406075 | I17: =C17+F17 -> 44924 | J17: =IFERROR(I17/I$20,0) -> 0.057808845
A18: Other Operating Income | C18: ='Vessel Budget'!$AB$18 -> 83000 | D18: =IFERROR(C18/C$20,0) -> 0.2 | F18: ='LW Budget'!$AB$18 -> 4080 | G18: =IFERROR(F18/F$20,0) -> 0.011267204 | I18: =C18+F18 -> 87080 | J18: =IFERROR(I18/I$20,0) -> 0.11205579
A19: Discounts & Comps | C19: ='Vessel Budget'!$AB$19 -> 0 | D19: =IFERROR(C19/C$20,0) -> 0 | F19: ='LW Budget'!$AB$19 -> -18252 | G19: =IFERROR(F19/F$20,0) -> -0.050404167 | I19: =C19+F19 -> -18252 | J19: =IFERROR(I19/I$20,0) -> -0.023486934
A20: Total Income | C20: ='Vessel Budget'!$AB$20 -> 415000 | D20: =IFERROR(C20/C$20,0) -> 1 | F20: ='LW Budget'!$AB$20 -> 362112.92 | G20: =IFERROR(F20/F$20,0) -> 1 | I20: =C20+F20 -> 777112.92 | J20: =IFERROR(I20/I$20,0) -> 1
A22: Cost of Goods Sold
A23: Food Cost | C23: ='Vessel Budget'!$AB$23 -> 149200.8 | D23: =IFERROR(C23/C$12,0) -> 0.6 | F23: ='LW Budget'!$AB$23 -> 71928 | G23: =IFERROR(F23/F$12,0) -> 0.53135825 | I23: =C23+F23 -> 221128.8 | J23: =IFERROR(I23/I$12,0) -> 0.57580482
A24: Non-Alcoholic Beverage Cost | C24: ='Vessel Budget'!$AB$24 -> 6991.3547 | D24: =IFERROR(C24/C$13,0) -> 0.25 | F24: ='LW Budget'!$AB$24 -> 33996 | G24: =IFERROR(F24/F$13,0) -> 0.20143794 | I24: =C24+F24 -> 40987.355 | J24: =IFERROR(I24/I$13,0) -> 0.20834103
A25: Liquor Cost | C25: ='Vessel Budget'!$AB$25 -> 11758.622 | D25: =IFERROR(C25/C$14,0) -> 0.25 | F25: ='LW Budget'!$AB$25 -> 948 | G25: =IFERROR(F25/F$14,0) -> 0.12972085 | I25: =C25+F25 -> 12706.622 | J25: =IFERROR(I25/I$14,0) -> 0.23382481
A26: Beer Cost | C26: ='Vessel Budget'!$AB$26 -> 433.50221 | D26: =IFERROR(C26/C$15,0) -> 0.25 | F26: ='LW Budget'!$AB$26 -> 2064 | G26: =IFERROR(F26/F$15,0) -> 0.2796748 | I26: =C26+F26 -> 2497.5022 | J26: =IFERROR(I26/I$15,0) -> 0.27402894
A27: Wine/Sake Cost | C27: ='Vessel Budget'!$AB$27 -> 1649.5212 | D27: =IFERROR(C27/C$16,0) -> 0.25 | F27: ='LW Budget'!$AB$27 -> 4476 | G27: =IFERROR(F27/F$16,0) -> 0.3569378 | I27: =C27+F27 -> 6125.5212 | J27: =IFERROR(I27/I$16,0) -> 0.32006971
A28: Retail Cost | C28: ='Vessel Budget'!$AB$28 -> 0 | D28: =IFERROR(C28/C$17,0) -> 0 | F28: ='LW Budget'!$AB$28 -> 21000.11 | G28: =IFERROR(F28/F$17,0) -> 0.4674586 | I28: =C28+F28 -> 21000.11 | J28: =IFERROR(I28/I$17,0) -> 0.4674586
A29: Total COGS | C29: ='Vessel Budget'!$AB$29 -> 170033.8 | D29: =IFERROR(C29/C$20,0) -> 0.40972 | F29: ='LW Budget'!$AB$29 -> 134412.11 | G29: =IFERROR(F29/F$20,0) -> 0.37118839 | I29: =C29+F29 -> 304445.91 | J29: =IFERROR(I29/I$20,0) -> 0.39176534
A30: Gross Profit | C30: ='Vessel Budget'!$AB$30 -> 244966.2 | D30: =IFERROR(C30/C$20,0) -> 0.59028 | F30: ='LW Budget'!$AB$30 -> 227700.81 | G30: =IFERROR(F30/F$20,0) -> 0.62881161 | I30: =C30+F30 -> 472667.01 | J30: =IFERROR(I30/I$20,0) -> 0.60823466
A32: Labor Cost
A33: Management Labor | C33: ='Vessel Budget'!$AB$33 -> 17230 | D33: =IFERROR(C33/C$20,0) -> 0.041518072 | F33: ='LW Budget'!$AB$33 -> 19884 | G33: =IFERROR(F33/F$20,0) -> 0.054911048 | I33: =C33+F33 -> 37114 | J33: =IFERROR(I33/I$20,0) -> 0.047758825
A34: Back of House Hourly Labor | C34: ='Vessel Budget'!$AB$34 -> 0 | D34: =IFERROR(C34/C$20,0) -> 0 | F34: ='LW Budget'!$AB$34 -> 15392 | G34: =IFERROR(F34/F$20,0) -> 0.042506078 | I34: =C34+F34 -> 15392 | J34: =IFERROR(I34/I$20,0) -> 0.019806645
A35: Front of House Hourly Labor | C35: ='Vessel Budget'!$AB$35 -> 43575 | D35: =IFERROR(C35/C$20,0) -> 0.105 | F35: ='LW Budget'!$AB$35 -> 81120 | G35: =IFERROR(F35/F$20,0) -> 0.22401852 | I35: =C35+F35 -> 124695 | J35: =IFERROR(I35/I$20,0) -> 0.16045931
A36: Payroll Taxes & Benefits | C36: ='Vessel Budget'!$AB$36 -> 9789.605 | D36: =IFERROR(C36/C$20,0) -> 0.02358941 | F36: ='LW Budget'!$AB$36 -> 18623.36 | G36: =IFERROR(F36/F$20,0) -> 0.051429703 | I36: =C36+F36 -> 28412.965 | J36: =IFERROR(I36/I$20,0) -> 0.036562209
A37: Bonus | C37: ='Vessel Budget'!$AB$37 -> 0 | D37: =IFERROR(C37/C$20,0) -> 0 | F37: ='LW Budget'!$AB$37 -> 0 | G37: =IFERROR(F37/F$20,0) -> 0 | I37: =C37+F37 -> 0 | J37: =IFERROR(I37/I$20,0) -> 0
A38: Total Labor Cost | C38: ='Vessel Budget'!$AB$38 -> 70594.605 | D38: =IFERROR(C38/C$20,0) -> 0.17010748 | F38: ='LW Budget'!$AB$38 -> 135019.36 | G38: =IFERROR(F38/F$20,0) -> 0.37286535 | I38: =C38+F38 -> 205613.96 | J38: =IFERROR(I38/I$20,0) -> 0.26458699
A40: Prime Costs | C40: ='Vessel Budget'!$AB$40 -> 240628.4 | D40: =IFERROR(C40/C$20,0) -> 0.57982748 | F40: ='LW Budget'!$AB$40 -> 269431.47 | G40: =IFERROR(F40/F$20,0) -> 0.74405373 | I40: =C40+F40 -> 510059.88 | J40: =IFERROR(I40/I$20,0) -> 0.65635233
A41: Operating Profit | C41: ='Vessel Budget'!$AB$41 -> 174371.6 | D41: =IFERROR(C41/C$20,0) -> 0.42017252 | F41: ='LW Budget'!$AB$41 -> 92681.45 | G41: =IFERROR(F41/F$20,0) -> 0.25594627 | I41: =C41+F41 -> 267053.04 | J41: =IFERROR(I41/I$20,0) -> 0.34364767
A43: Controllable Expenses
A44: Operating Expenses | C44: ='Vessel Budget'!$AB$44 -> 16227 | D44: =IFERROR(C44/C$20,0) -> 0.039101205 | F44: ='LW Budget'!$AB$44 -> 49136.123 | G44: =IFERROR(F44/F$20,0) -> 0.13569282 | I44: =C44+F44 -> 65363.123 | J44: =IFERROR(I44/I$20,0) -> 0.0841102
A45: Music & Entertainment | C45: ='Vessel Budget'!$AB$45 -> 11483 | D45: =IFERROR(C45/C$20,0) -> 0.02766988 | F45: ='LW Budget'!$AB$45 -> 0 | G45: =IFERROR(F45/F$20,0) -> 0 | I45: =C45+F45 -> 11483 | J45: =IFERROR(I45/I$20,0) -> 0.014776488
A46: Marketing & Advertising | C46: ='Vessel Budget'!$AB$46 -> 10539 | D46: =IFERROR(C46/C$20,0) -> 0.025395181 | F46: ='LW Budget'!$AB$46 -> 7536 | G46: =IFERROR(F46/F$20,0) -> 0.020811188 | I46: =C46+F46 -> 18075 | J46: =IFERROR(I46/I$20,0) -> 0.023259168
A47: General & Administrative - Controllable | C47: ='Vessel Budget'!$AB$47 -> 39980 | D47: =IFERROR(C47/C$20,0) -> 0.096337349 | F47: ='LW Budget'!$AB$47 -> 40704 | G47: =IFERROR(F47/F$20,0) -> 0.11240693 | I47: =C47+F47 -> 80684 | J47: =IFERROR(I47/I$20,0) -> 0.10382532
A48: Repairs & Maintenance | C48: ='Vessel Budget'!$AB$48 -> 2395 | D48: =IFERROR(C48/C$20,0) -> 0.0057710843 | F48: ='LW Budget'!$AB$48 -> 876 | G48: =IFERROR(F48/F$20,0) -> 0.0024191349 | I48: =C48+F48 -> 3271 | J48: =IFERROR(I48/I$20,0) -> 0.0042091695
...

Sheet Combined 12-Mo P&L
A1: Method Terrapin — Combined
A2: Profit & Loss Budget — Vessel + Little Wing
A3: 2027
C5: January | E5: February | G5: March | I5: April | K5: May | M5: June | O5: July | Q5: August | S5: September | U5: October | W5: November | Y5: December | AB5: 2027
C6: Budget | E6: Budget | G6: Budget | I6: Budget | K6: Budget | M6: Budget | O6: Budget | Q6: Budget | S6: Budget | U6: Budget | W6: Budget | Y6: Budget | AB6: FY 2027
C7: Amount $ | D7: % | E7: Amount $ | F7: % | G7: Amount $ | H7: % | I7: Amount $ | J7: % | K7: Amount $ | L7: % | M7: Amount $ | N7: % | O7: Amount $ | P7: % | Q7: Amount $ | R7: % | S7: Amount $ | T7: % | U7: Amount $ | V7: % | W7: Amount $ | X7: % | Y7: Amount $ | Z7: % | AB7: Amount $ | AC7: %
A8: Events (Vessel, budgeted) | C8: ='Vessel Budget'!C9 -> 10 | E8: ='Vessel Budget'!E9 -> 3 | G8: ='Vessel Budget'!G9 -> 10 | I8: ='Vessel Budget'!I9 -> 3 | K8: ='Vessel Budget'!K9 -> 8 | M8: ='Vessel Budget'!M9 -> 7 | O8: ='Vessel Budget'!O9 -> 7 | Q8: ='Vessel Budget'!Q9 -> 7 | S8: ='Vessel Budget'!S9 -> 7 | U8: ='Vessel Budget'!U9 -> 7 | W8: ='Vessel Budget'!W9 -> 7 | Y8: ='Vessel Budget'!Y9 -> 7
A11: Income
A12: Food Sales | C12: ='Vessel Budget'!C12+'LW Budget'!C12 -> 41240.525 | D12: =IFERROR(C12/C$20,0) -> 0.51437445 | E12: ='Vessel Budget'!E12+'LW Budget'!E12 -> 20268.525 | F12: =IFERROR(E12/E$20,0) -> 0.44865616 | G12: ='Vessel Budget'!G12+'LW Budget'!G12 -> 41240.525 | H12: =IFERROR(G12/G$20,0) -> 0.51437445 | I12: ='Vessel Budget'!I12+'LW Budget'!I12 -> 20268.525 | J12: =IFERROR(I12/I$20,0) -> 0.44865616 | K12: ='Vessel Budget'!K12+'LW Budget'!K12 -> 35248.525 | L12: =IFERROR(K12/K$20,0) -> 0.50228691 | M12: ='Vessel Budget'!M12+'LW Budget'!M12 -> 32252.525 | N12: =IFERROR(M12/M$20,0) -> 0.4948522 | O12: ='Vessel Budget'!O12+'LW Budget'!O12 -> 32252.525 | P12: =IFERROR(O12/O$20,0) -> 0.4948522 | Q12: ='Vessel Budget'!Q12+'LW Budget'!Q12 -> 32252.525 | R12: =IFERROR(Q12/Q$20,0) -> 0.4948522 | S12: ='Vessel Budget'!S12+'LW Budget'!S12 -> 32252.525 | T12: =IFERROR(S12/S$20,0) -> 0.4948522 | U12: ='Vessel Budget'!U12+'LW Budget'!U12 -> 32252.525 | V12: =IFERROR(U12/U$20,0) -> 0.4948522 | W12: ='Vessel Budget'!W12+'LW Budget'!W12 -> 32252.525 | X12: =IFERROR(W12/W$20,0) -> 0.4948522 | Y12: ='Vessel Budget'!Y12+'LW Budget'!Y12 -> 32252.525 | Z12: =IFERROR(Y12/Y$20,0) -> 0.4948522 | AB12: =SUM(C12,E12,G12,I12,K12,M12,O12,Q12,S12,U12,W12,Y12) -> 384034.3 | AC12: =IFERROR(AB12/AB$20,0) -> 0.49418082
A13: Non-Alcoholic Beverage Sales | C13: ='Vessel Budget'!C13+'LW Budget'!C13 -> 17433.213 | D13: =IFERROR(C13/C$20,0) -> 0.21743659 | E13: ='Vessel Budget'!E13+'LW Budget'!E13 -> 15074.683 | F13: =IFERROR(E13/E$20,0) -> 0.33368731 | G13: ='Vessel Budget'!G13+'LW Budget'!G13 -> 17433.213 | H13: =IFERROR(G13/G$20,0) -> 0.21743659 | I13: ='Vessel Budget'!I13+'LW Budget'!I13 -> 15074.683 | J13: =IFERROR(I13/I$20,0) -> 0.33368731 | K13: ='Vessel Budget'!K13+'LW Budget'!K13 -> 16759.347 | L13: =IFERROR(K13/K$20,0) -> 0.23881852 | M13: ='Vessel Budget'!M13+'LW Budget'!M13 -> 16422.414 | N13: =IFERROR(M13/M$20,0) -> 0.25196997 | O13: ='Vessel Budget'!O13+'LW Budget'!O13 -> 16422.414 | P13: =IFERROR(O13/O$20,0) -> 0.25196997 | Q13: ='Vessel Budget'!Q13+'LW Budget'!Q13 -> 16422.414 | R13: =IFERROR(Q13/Q$20,0) -> 0.25196997 | S13: ='Vessel Budget'!S13+'LW Budget'!S13 -> 16422.414 | T13: =IFERROR(S13/S$20,0) -> 0.25196997 | U13: ='Vessel Budget'!U13+'LW Budget'!U13 -> 16422.414 | V13: =IFERROR(U13/U$20,0) -> 0.25196997 | W13: ='Vessel Budget'!W13+'LW Budget'!W13 -> 16422.414 | X13: =IFERROR(W13/W$20,0) -> 0.25196997 | Y13: ='Vessel Budget'!Y13+'LW Budget'!Y13 -> 16422.414 | Z13: =IFERROR(Y13/Y$20,0) -> 0.25196997 | AB13: =SUM(C13,E13,G13,I13,K13,M13,O13,Q13,S13,U13,W13,Y13) -> 196732.04 | AC13: =IFERROR(AB13/AB$20,0) -> 0.2531576
A14: Liquor Sales | C14: ='Vessel Budget'!C14+'LW Budget'!C14 -> 6275.8057 | D14: =IFERROR(C14/C$20,0) -> 0.078275291 | E14: ='Vessel Budget'!E14+'LW Budget'!E14 -> 2309.0417 | F14: =IFERROR(E14/E$20,0) -> 0.051112046 | G14: ='Vessel Budget'!G14+'LW Budget'!G14 -> 6275.8057 | H14: =IFERROR(G14/G$20,0) -> 0.078275291 | I14: ='Vessel Budget'!I14+'LW Budget'!I14 -> 2309.0417 | J14: =IFERROR(I14/I$20,0) -> 0.051112046 | K14: ='Vessel Budget'!K14+'LW Budget'!K14 -> 5142.4446 | L14: =IFERROR(K14/K$20,0) -> 0.073279169 | M14: ='Vessel Budget'!M14+'LW Budget'!M14 -> 4575.764 | N14: =IFERROR(M14/M$20,0) -> 0.07020619 | O14: ='Vessel Budget'!O14+'LW Budget'!O14 -> 4575.764 | P14: =IFERROR(O14/O$20,0) -> 0.07020619 | Q14: ='Vessel Budget'!Q14+'LW Budget'!Q14 -> 4575.764 | R14: =IFERROR(Q14/Q$20,0) -> 0.07020619 | S14: ='Vessel Budget'!S14+'LW Budget'!S14 -> 4575.764 | T14: =IFERROR(S14/S$20,0) -> 0.07020619 | U14: ='Vessel Budget'!U14+'LW Budget'!U14 -> 4575.764 | V14: =IFERROR(U14/U$20,0) -> 0.07020619 | W14: ='Vessel Budget'!W14+'LW Budget'!W14 -> 4575.764 | X14: =IFERROR(W14/W$20,0) -> 0.07020619 | Y14: ='Vessel Budget'!Y14+'LW Budget'!Y14 -> 4575.764 | Z14: =IFERROR(Y14/Y$20,0) -> 0.07020619 | AB14: =SUM(C14,E14,G14,I14,K14,M14,O14,Q14,S14,U14,W14,Y14) -> 54342.487 | AC14: =IFERROR(AB14/AB$20,0) -> 0.069928689
A15: Beer Sales | C15: ='Vessel Budget'!C15+'LW Budget'!C15 -> 823.91673 | D15: =IFERROR(C15/C$20,0) -> 0.010276341 | E15: ='Vessel Budget'!E15+'LW Budget'!E15 -> 677.67502 | F15: =IFERROR(E15/E$20,0) -> 0.01500075 | G15: ='Vessel Budget'!G15+'LW Budget'!G15 -> 823.91673 | H15: =IFERROR(G15/G$20,0) -> 0.010276341 | I15: ='Vessel Budget'!I15+'LW Budget'!I15 -> 677.67502 | J15: =IFERROR(I15/I$20,0) -> 0.01500075 | K15: ='Vessel Budget'!K15+'LW Budget'!K15 -> 782.13338 | L15: =IFERROR(K15/K$20,0) -> 0.011145299 | M15: ='Vessel Budget'!M15+'LW Budget'!M15 -> 761.24171 | N15: =IFERROR(M15/M$20,0) -> 0.011679772 | O15: ='Vessel Budget'!O15+'LW Budget'!O15 -> 761.24171 | P15: =IFERROR(O15/O$20,0) -> 0.011679772 | Q15: ='Vessel Budget'!Q15+'LW Budget'!Q15 -> 761.24171 | R15: =IFERROR(Q15/Q$20,0) -> 0.011679772 | S15: ='Vessel Budget'!S15+'LW Budget'!S15 -> 761.24171 | T15: =IFERROR(S15/S$20,0) -> 0.011679772 | U15: ='Vessel Budget'!U15+'LW Budget'!U15 -> 761.24171 | V15: =IFERROR(U15/U$20,0) -> 0.011679772 | W15: ='Vessel Budget'!W15+'LW Budget'!W15 -> 761.24171 | X15: =IFERROR(W15/W$20,0) -> 0.011679772 | Y15: ='Vessel Budget'!Y15+'LW Budget'!Y15 -> 761.24171 | Z15: =IFERROR(Y15/Y$20,0) -> 0.011679772 | AB15: =SUM(C15,E15,G15,I15,K15,M15,O15,Q15,S15,U15,W15,Y15) -> 9114.0089 | AC15: =IFERROR(AB15/AB$20,0) -> 0.011728037
A16: Wine Sales | C16: ='Vessel Budget'!C16+'LW Budget'!C16 -> 1839.95 | D16: =IFERROR(C16/C$20,0) -> 0.022948865 | E16: ='Vessel Budget'!E16+'LW Budget'!E16 -> 1283.485 | F16: =IFERROR(E16/E$20,0) -> 0.028410723 | G16: ='Vessel Budget'!G16+'LW Budget'!G16 -> 1839.95 | H16: =IFERROR(G16/G$20,0) -> 0.022948865 | I16: ='Vessel Budget'!I16+'LW Budget'!I16 -> 1283.485 | J16: =IFERROR(I16/I$20,0) -> 0.028410723 | K16: ='Vessel Budget'!K16+'LW Budget'!K16 -> 1680.96 | L16: =IFERROR(K16/K$20,0) -> 0.023953462 | M16: ='Vessel Budget'!M16+'LW Budget'!M16 -> 1601.465 | N16: =IFERROR(M16/M$20,0) -> 0.024571362 | O16: ='Vessel Budget'!O16+'LW Budget'!O16 -> 1601.465 | P16: =IFERROR(O16/O$20,0) -> 0.024571362 | Q16: ='Vessel Budget'!Q16+'LW Budget'!Q16 -> 1601.465 | R16: =IFERROR(Q16/Q$20,0) -> 0.024571362 | S16: ='Vessel Budget'!S16+'LW Budget'!S16 -> 1601.465 | T16: =IFERROR(S16/S$20,0) -> 0.024571362 | U16: ='Vessel Budget'!U16+'LW Budget'!U16 -> 1601.465 | V16: =IFERROR(U16/U$20,0) -> 0.024571362 | W16: ='Vessel Budget'!W16+'LW Budget'!W16 -> 1601.465 | X16: =IFERROR(W16/W$20,0) -> 0.024571362 | Y16: ='Vessel Budget'!Y16+'LW Budget'!Y16 -> 1601.465 | Z16: =IFERROR(Y16/Y$20,0) -> 0.024571362 | AB16: =SUM(C16,E16,G16,I16,K16,M16,O16,Q16,S16,U16,W16,Y16) -> 19138.085 | AC16: =IFERROR(AB16/AB$20,0) -> 0.024627161
A17: Retail / Merch Sales | C17: ='Vessel Budget'!C17+'LW Budget'!C17 -> 3743.6667 | D17: =IFERROR(C17/C$20,0) -> 0.046693064 | E17: ='Vessel Budget'!E17+'LW Budget'!E17 -> 3743.6667 | F17: =IFERROR(E17/E$20,0) -> 0.082868344 | G17: ='Vessel Budget'!G17+'LW Budget'!G17 -> 3743.6667 | H17: =IFERROR(G17/G$20,0) -> 0.046693064 | I17: ='Vessel Budget'!I17+'LW Budget'!I17 -> 3743.6667 | J17: =IFERROR(I17/I$20,0) -> 0.082868344 | K17: ='Vessel Budget'!K17+'LW Budget'!K17 -> 3743.6667 | L17: =IFERROR(K17/K$20,0) -> 0.053346765 | M17: ='Vessel Budget'!M17+'LW Budget'!M17 -> 3743.6667 | N17: =IFERROR(M17/M$20,0) -> 0.057439276 | O17: ='Vessel Budget'!O17+'LW Budget'!O17 -> 3743.6667 | P17: =IFERROR(O17/O$20,0) -> 0.057439276 | Q17: ='Vessel Budget'!Q17+'LW Budget'!Q17 -> 3743.6667 | R17: =IFERROR(Q17/Q$20,0) -> 0.057439276 | S17: ='Vessel Budget'!S17+'LW Budget'!S17 -> 3743.6667 | T17: =IFERROR(S17/S$20,0) -> 0.057439276 | U17: ='Vessel Budget'!U17+'LW Budget'!U17 -> 3743.6667 | V17: =IFERROR(U17/U$20,0) -> 0.057439276 | W17: ='Vessel Budget'!W17+'LW Budget'!W17 -> 3743.6667 | X17: =IFERROR(W17/W$20,0) -> 0.057439276 | Y17: ='Vessel Budget'!Y17+'LW Budget'!Y17 -> 3743.6667 | Z17: =IFERROR(Y17/Y$20,0) -> 0.057439276 | AB17: =SUM(C17,E17,G17,I17,K17,M17,O17,Q17,S17,U17,W17,Y17) -> 44924 | AC17: =IFERROR(AB17/AB$20,0) -> 0.057808845
A18: Other Operating Income | C18: ='Vessel Budget'!C18+'LW Budget'!C18 -> 10340 | D18: =IFERROR(C18/C$20,0) -> 0.12896615 | E18: ='Vessel Budget'!E18+'LW Budget'!E18 -> 3340 | F18: =IFERROR(E18/E$20,0) -> 0.073932936 | G18: ='Vessel Budget'!G18+'LW Budget'!G18 -> 10340 | H18: =IFERROR(G18/G$20,0) -> 0.12896615 | I18: ='Vessel Budget'!I18+'LW Budget'!I18 -> 3340 | J18: =IFERROR(I18/I$20,0) -> 0.073932936 | K18: ='Vessel Budget'!K18+'LW Budget'!K18 -> 8340 | L18: =IFERROR(K18/K$20,0) -> 0.11884392 | M18: ='Vessel Budget'!M18+'LW Budget'!M18 -> 7340 | N18: =IFERROR(M18/M$20,0) -> 0.11261801 | O18: ='Vessel Budget'!O18+'LW Budget'!O18 -> 7340 | P18: =IFERROR(O18/O$20,0) -> 0.11261801 | Q18: ='Vessel Budget'!Q18+'LW Budget'!Q18 -> 7340 | R18: =IFERROR(Q18/Q$20,0) -> 0.11261801 | S18: ='Vessel Budget'!S18+'LW Budget'!S18 -> 7340 | T18: =IFERROR(S18/S$20,0) -> 0.11261801 | U18: ='Vessel Budget'!U18+'LW Budget'!U18 -> 7340 | V18: =IFERROR(U18/U$20,0) -> 0.11261801 | W18: ='Vessel Budget'!W18+'LW Budget'!W18 -> 7340 | X18: =IFERROR(W18/W$20,0) -> 0.11261801 | Y18: ='Vessel Budget'!Y18+'LW Budget'!Y18 -> 7340 | Z18: =IFERROR(Y18/Y$20,0) -> 0.11261801 | AB18: =SUM(C18,E18,G18,I18,K18,M18,O18,Q18,S18,U18,W18,Y18) -> 87080 | AC18: =IFERROR(AB18/AB$20,0) -> 0.11205579
A19: Discounts & Comps | C19: ='Vessel Budget'!C19+'LW Budget'!C19 -> -1521 | D19: =IFERROR(C19/C$20,0) -> -0.018970746 | E19: ='Vessel Budget'!E19+'LW Budget'!E19 -> -1521 | F19: =IFERROR(E19/E$20,0) -> -0.033668262 | G19: ='Vessel Budget'!G19+'LW Budget'!G19 -> -1521 | H19: =IFERROR(G19/G$20,0) -> -0.018970746 | I19: ='Vessel Budget'!I19+'LW Budget'!I19 -> -1521 | J19: =IFERROR(I19/I$20,0) -> -0.033668262 | K19: ='Vessel Budget'!K19+'LW Budget'!K19 -> -1521 | L19: =IFERROR(K19/K$20,0) -> -0.021674053 | M19: ='Vessel Budget'!M19+'LW Budget'!M19 -> -1521 | N19: =IFERROR(M19/M$20,0) -> -0.023336784 | O19: ='Vessel Budget'!O19+'LW Budget'!O19 -> -1521 | P19: =IFERROR(O19/O$20,0) -> -0.023336784 | Q19: ='Vessel Budget'!Q19+'LW Budget'!Q19 -> -1521 | R19: =IFERROR(Q19/Q$20,0) -> -0.023336784 | S19: ='Vessel Budget'!S19+'LW Budget'!S19 -> -1521 | T19: =IFERROR(S19/S$20,0) -> -0.023336784 | U19: ='Vessel Budget'!U19+'LW Budget'!U19 -> -1521 | V19: =IFERROR(U19/U$20,0) -> -0.023336784 | W19: ='Vessel Budget'!W19+'LW Budget'!W19 -> -1521 | X19: =IFERROR(W19/W$20,0) -> -0.023336784 | Y19: ='Vessel Budget'!Y19+'LW Budget'!Y19 -> -1521 | Z19: =IFERROR(Y19/Y$20,0) -> -0.023336784 | AB19: =SUM(C19,E19,G19,I19,K19,M19,O19,Q19,S19,U19,W19,Y19) -> -18252 | AC19: =IFERROR(AB19/AB$20,0) -> -0.023486934
A20: Total Income | C20: =SUM(C12:C19) -> 80176.077 | D20: =IFERROR(C20/C$20,0) -> 1 | E20: =SUM(E12:E19) -> 45176.077 | F20: =IFERROR(E20/E$20,0) -> 1 | G20: =SUM(G12:G19) -> 80176.077 | H20: =IFERROR(G20/G$20,0) -> 1 | I20: =SUM(I12:I19) -> 45176.077 | J20: =IFERROR(I20/I$20,0) -> 1 | K20: =SUM(K12:K19) -> 70176.077 | L20: =IFERROR(K20/K$20,0) -> 1 | M20: =SUM(M12:M19) -> 65176.077 | N20: =IFERROR(M20/M$20,0) -> 1 | O20: =SUM(O12:O19) -> 65176.077 | P20: =IFERROR(O20/O$20,0) -> 1 | Q20: =SUM(Q12:Q19) -> 65176.077 | R20: =IFERROR(Q20/Q$20,0) -> 1 | S20: =SUM(S12:S19) -> 65176.077 | T20: =IFERROR(S20/S$20,0) -> 1 | U20: =SUM(U12:U19) -> 65176.077 | V20: =IFERROR(U20/U$20,0) -> 1 | W20: =SUM(W12:W19) -> 65176.077 | X20: =IFERROR(W20/W$20,0) -> 1 | Y20: =SUM(Y12:Y19) -> 65176.077 | Z20: =IFERROR(Y20/Y$20,0) -> 1 | AB20: =SUM(AB12:AB19) -> 777112.92 | AC20: =IFERROR(AB20/AB$20,0) -> 1
A22: Cost of Goods Sold
A23: Food Cost | C23: ='Vessel Budget'!C23+'LW Budget'!C23 -> 23970 | D23: =IFERROR(C23/C$12,0) -> 0.58122441 | E23: ='Vessel Budget'!E23+'LW Budget'!E23 -> 11386.8 | F23: =IFERROR(E23/E$12,0) -> 0.56179717 | G23: ='Vessel Budget'!G23+'LW Budget'!G23 -> 23970 | H23: =IFERROR(G23/G$12,0) -> 0.58122441 | I23: ='Vessel Budget'!I23+'LW Budget'!I23 -> 11386.8 | J23: =IFERROR(I23/I$12,0) -> 0.56179717 | K23: ='Vessel Budget'!K23+'LW Budget'!K23 -> 20374.8 | L23: =IFERROR(K23/K$12,0) -> 0.5780327 | M23: ='Vessel Budget'!M23+'LW Budget'!M23 -> 18577.2 | N23: =IFERROR(M23/M$12,0) -> 0.57599211 | O23: ='Vessel Budget'!O23+'LW Budget'!O23 -> 18577.2 | P23: =IFERROR(O23/O$12,0) -> 0.57599211 | Q23: ='Vessel Budget'!Q23+'LW Budget'!Q23 -> 18577.2 | R23: =IFERROR(Q23/Q$12,0) -> 0.57599211 | S23: ='Vessel Budget'!S23+'LW Budget'!S23 -> 18577.2 | T23: =IFERROR(S23/S$12,0) -> 0.57599211 | U23: ='Vessel Budget'!U23+'LW Budget'!U23 -> 18577.2 | V23: =IFERROR(U23/U$12,0) -> 0.57599211 | W23: ='Vessel Budget'!W23+'LW Budget'!W23 -> 18577.2 | X23: =IFERROR(W23/W$12,0) -> 0.57599211 | Y23: ='Vessel Budget'!Y23+'LW Budget'!Y23 -> 18577.2 | Z23: =IFERROR(Y23/Y$12,0) -> 0.57599211 | AB23: =SUM(C23,E23,G23,I23,K23,M23,O23,Q23,S23,U23,W23,Y23) -> 221128.8 | AC23: =IFERROR(AB23/AB$12,0) -> 0.57580482
A24: Non-Alcoholic Beverage Cost | C24: ='Vessel Budget'!C24+'LW Budget'!C24 -> 3675.3319 | D24: =IFERROR(C24/C$13,0) -> 0.21082356 | E24: ='Vessel Budget'!E24+'LW Budget'!E24 -> 3085.6996 | F24: =IFERROR(E24/E$13,0) -> 0.20469416 | G24: ='Vessel Budget'!G24+'LW Budget'!G24 -> 3675.3319 | H24: =IFERROR(G24/G$13,0) -> 0.21082356 | I24: ='Vessel Budget'!I24+'LW Budget'!I24 -> 3085.6996 | J24: =IFERROR(I24/I$13,0) -> 0.20469416 | K24: ='Vessel Budget'!K24+'LW Budget'!K24 -> 3506.8655 | L24: =IFERROR(K24/K$13,0) -> 0.20924834 | M24: ='Vessel Budget'!M24+'LW Budget'!M24 -> 3422.6323 | N24: =IFERROR(M24/M$13,0) -> 0.20841225 | O24: ='Vessel Budget'!O24+'LW Budget'!O24 -> 3422.6323 | P24: =IFERROR(O24/O$13,0) -> 0.20841225 | Q24: ='Vessel Budget'!Q24+'LW Budget'!Q24 -> 3422.6323 | R24: =IFERROR(Q24/Q$13,0) -> 0.20841225 | S24: ='Vessel Budget'!S24+'LW Budget'!S24 -> 3422.6323 | T24: =IFERROR(S24/S$13,0) -> 0.20841225 | U24: ='Vessel Budget'!U24+'LW Budget'!U24 -> 3422.6323 | V24: =IFERROR(U24/U$13,0) -> 0.20841225 | W24: ='Vessel Budget'!W24+'LW Budget'!W24 -> 3422.6323 | X24: =IFERROR(W24/W$13,0) -> 0.20841225 | Y24: ='Vessel Budget'!Y24+'LW Budget'!Y24 -> 3422.6323 | Z24: =IFERROR(Y24/Y$13,0) -> 0.20841225 | AB24: =SUM(C24,E24,G24,I24,K24,M24,O24,Q24,S24,U24,W24,Y24) -> 40987.355 | AC24: =IFERROR(AB24/AB$13,0) -> 0.20834103
A25: Liquor Cost | C25: ='Vessel Budget'!C25+'LW Budget'!C25 -> 1495.7014 | D25: =IFERROR(C25/C$14,0) -> 0.23832819 | E25: ='Vessel Budget'!E25+'LW Budget'!E25 -> 504.01043 | F25: =IFERROR(E25/E$14,0) -> 0.21827688 | G25: ='Vessel Budget'!G25+'LW Budget'!G25 -> 1495.7014 | H25: =IFERROR(G25/G$14,0) -> 0.23832819 | I25: ='Vessel Budget'!I25+'LW Budget'!I25 -> 504.01043 | J25: =IFERROR(I25/I$14,0) -> 0.21827688 | K25: ='Vessel Budget'!K25+'LW Budget'!K25 -> 1212.3611 | L25: =IFERROR(K25/K$14,0) -> 0.2357558 | M25: ='Vessel Budget'!M25+'LW Budget'!M25 -> 1070.691 | N25: =IFERROR(M25/M$14,0) -> 0.23399174 | O25: ='Vessel Budget'!O25+'LW Budget'!O25 -> 1070.691 | P25: =IFERROR(O25/O$14,0) -> 0.23399174 | Q25: ='Vessel Budget'!Q25+'LW Budget'!Q25 -> 1070.691 | R25: =IFERROR(Q25/Q$14,0) -> 0.23399174 | S25: ='Vessel Budget'!S25+'LW Budget'!S25 -> 1070.691 | T25: =IFERROR(S25/S$14,0) -> 0.23399174 | U25: ='Vessel Budget'!U25+'LW Budget'!U25 -> 1070.691 | V25: =IFERROR(U25/U$14,0) -> 0.23399174 | W25: ='Vessel Budget'!W25+'LW Budget'!W25 -> 1070.691 | X25: =IFERROR(W25/W$14,0) -> 0.23399174 | Y25: ='Vessel Budget'!Y25+'LW Budget'!Y25 -> 1070.691 | Z25: =IFERROR(Y25/Y$14,0) -> 0.23399174 | AB25: =SUM(C25,E25,G25,I25,K25,M25,O25,Q25,S25,U25,W25,Y25) -> 12706.622 | AC25: =IFERROR(AB25/AB$14,0) -> 0.23382481
A26: Beer Cost | C26: ='Vessel Budget'!C26+'LW Budget'!C26 -> 224.22918 | D26: =IFERROR(C26/C$15,0) -> 0.2721503 | E26: ='Vessel Budget'!E26+'LW Budget'!E26 -> 187.66875 | F26: =IFERROR(E26/E$15,0) -> 0.27693031 | G26: ='Vessel Budget'!G26+'LW Budget'!G26 -> 224.22918 | H26: =IFERROR(G26/G$15,0) -> 0.2721503 | I26: ='Vessel Budget'!I26+'LW Budget'!I26 -> 187.66875 | J26: =IFERROR(I26/I$15,0) -> 0.27693031 | K26: ='Vessel Budget'!K26+'LW Budget'!K26 -> 213.78335 | L26: =IFERROR(K26/K$15,0) -> 0.27333362 | M26: ='Vessel Budget'!M26+'LW Budget'!M26 -> 208.56043 | N26: =IFERROR(M26/M$15,0) -> 0.27397399 | O26: ='Vessel Budget'!O26+'LW Budget'!O26 -> 208.56043 | P26: =IFERROR(O26/O$15,0) -> 0.27397399 | Q26: ='Vessel Budget'!Q26+'LW Budget'!Q26 -> 208.56043 | R26: =IFERROR(Q26/Q$15,0) -> 0.27397399 | S26: ='Vessel Budget'!S26+'LW Budget'!S26 -> 208.56043 | T26: =IFERROR(S26/S$15,0) -> 0.27397399 | U26: ='Vessel Budget'!U26+'LW Budget'!U26 -> 208.56043 | V26: =IFERROR(U26/U$15,0) -> 0.27397399 | W26: ='Vessel Budget'!W26+'LW Budget'!W26 -> 208.56043 | X26: =IFERROR(W26/W$15,0) -> 0.27397399 | Y26: ='Vessel Budget'!Y26+'LW Budget'!Y26 -> 208.56043 | Z26: =IFERROR(Y26/Y$15,0) -> 0.27397399 | AB26: =SUM(C26,E26,G26,I26,K26,M26,O26,Q26,S26,U26,W26,Y26) -> 2497.5022 | AC26: =IFERROR(AB26/AB$15,0) -> 0.27402894
A27: Wine/Sake Cost | C27: ='Vessel Budget'!C27+'LW Budget'!C27 -> 571.73749 | D27: =IFERROR(C27/C$16,0) -> 0.31073535 | E27: ='Vessel Budget'!E27+'LW Budget'!E27 -> 432.62125 | F27: =IFERROR(E27/E$16,0) -> 0.33706763 | G27: ='Vessel Budget'!G27+'LW Budget'!G27 -> 571.73749 | H27: =IFERROR(G27/G$16,0) -> 0.31073535 | I27: ='Vessel Budget'!I27+'LW Budget'!I27 -> 432.62125 | J27: =IFERROR(I27/I$16,0) -> 0.33706763 | K27: ='Vessel Budget'!K27+'LW Budget'!K27 -> 531.98999 | L27: =IFERROR(K27/K$16,0) -> 0.31647987 | M27: ='Vessel Budget'!M27+'LW Budget'!M27 -> 512.11624 | N27: =IFERROR(M27/M$16,0) -> 0.31977986 | O27: ='Vessel Budget'!O27+'LW Budget'!O27 -> 512.11624 | P27: =IFERROR(O27/O$16,0) -> 0.31977986 | Q27: ='Vessel Budget'!Q27+'LW Budget'!Q27 -> 512.11624 | R27: =IFERROR(Q27/Q$16,0) -> 0.31977986 | S27: ='Vessel Budget'!S27+'LW Budget'!S27 -> 512.11624 | T27: =IFERROR(S27/S$16,0) -> 0.31977986 | U27: ='Vessel Budget'!U27+'LW Budget'!U27 -> 512.11624 | V27: =IFERROR(U27/U$16,0) -> 0.31977986 | W27: ='Vessel Budget'!W27+'LW Budget'!W27 -> 512.11624 | X27: =IFERROR(W27/W$16,0) -> 0.31977986 | Y27: ='Vessel Budget'!Y27+'LW Budget'!Y27 -> 512.11624 | Z27: =IFERROR(Y27/Y$16,0) -> 0.31977986 | AB27: =SUM(C27,E27,G27,I27,K27,M27,O27,Q27,S27,U27,W27,Y27) -> 6125.5212 | AC27: =IFERROR(AB27/AB$16,0) -> 0.32006971
A28: Retail Cost | C28: ='Vessel Budget'!C28+'LW Budget'!C28 -> 1750.0092 | D28: =IFERROR(C28/C$17,0) -> 0.4674586 | E28: ='Vessel Budget'!E28+'LW Budget'!E28 -> 1750.0092 | F28: =IFERROR(E28/E$17,0) -> 0.4674586 | G28: ='Vessel Budget'!G28+'LW Budget'!G28 -> 1750.0092 | H28: =IFERROR(G28/G$17,0) -> 0.4674586 | I28: ='Vessel Budget'!I28+'LW Budget'!I28 -> 1750.0092 | J28: =IFERROR(I28/I$17,0) -> 0.4674586 | K28: ='Vessel Budget'!K28+'LW Budget'!K28 -> 1750.0092 | L28: =IFERROR(K28/K$17,0) -> 0.4674586 | M28: ='Vessel Budget'!M28+'LW Budget'!M28 -> 1750.0092 | N28: =IFERROR(M28/M$17,0) -> 0.4674586 | O28: ='Vessel Budget'!O28+'LW Budget'!O28 -> 1750.0092 | P28: =IFERROR(O28/O$17,0) -> 0.4674586 | Q28: ='Vessel Budget'!Q28+'LW Budget'!Q28 -> 1750.0092 | R28: =IFERROR(Q28/Q$17,0) -> 0.4674586 | S28: ='Vessel Budget'!S28+'LW Budget'!S28 -> 1750.0092 | T28: =IFERROR(S28/S$17,0) -> 0.4674586 | U28: ='Vessel Budget'!U28+'LW Budget'!U28 -> 1750.0092 | V28: =IFERROR(U28/U$17,0) -> 0.4674586 | W28: ='Vessel Budget'!W28+'LW Budget'!W28 -> 1750.0092 | X28: =IFERROR(W28/W$17,0) -> 0.4674586 | Y28: ='Vessel Budget'!Y28+'LW Budget'!Y28 -> 1750.0092 | Z28: =IFERROR(Y28/Y$17,0) -> 0.4674586 | AB28: =SUM(C28,E28,G28,I28,K28,M28,O28,Q28,S28,U28,W28,Y28) -> 21000.11 | AC28: =IFERROR(AB28/AB$17,0) -> 0.4674586
A29: Total COGS | C29: =SUM(C23:C28) -> 31687.009 | D29: =IFERROR(C29/C$20,0) -> 0.39521776 | E29: =SUM(E23:E28) -> 17346.809 | F29: =IFERROR(E29/E$20,0) -> 0.3839822 | G29: =SUM(G23:G28) -> 31687.009 | H29: =IFERROR(G29/G$20,0) -> 0.39521776 | I29: =SUM(I23:I28) -> 17346.809 | J29: =IFERROR(I29/I$20,0) -> 0.3839822 | K29: =SUM(K23:K28) -> 27589.809 | L29: =IFERROR(K29/K$20,0) -> 0.39315121 | M29: =SUM(M23:M28) -> 25541.209 | N29: =IFERROR(M29/M$20,0) -> 0.39188013 | O29: =SUM(O23:O28) -> 25541.209 | P29: =IFERROR(O29/O$20,0) -> 0.39188013 | Q29: =SUM(Q23:Q28) -> 25541.209 | R29: =IFERROR(Q29/Q$20,0) -> 0.39188013 | S29: =SUM(S23:S28) -> 25541.209 | T29: =IFERROR(S29/S$20,0) -> 0.39188013 | U29: =SUM(U23:U28) -> 25541.209 | V29: =IFERROR(U29/U$20,0) -> 0.39188013 | W29: =SUM(W23:W28) -> 25541.209 | X29: =IFERROR(W29/W$20,0) -> 0.39188013 | Y29: =SUM(Y23:Y28) -> 25541.209 | Z29: =IFERROR(Y29/Y$20,0) -> 0.39188013 | AB29: =SUM(AB23:AB28) -> 304445.91 | AC29: =IFERROR(AB29/AB$20,0) -> 0.39176534
A30: Gross Profit | C30: =C20-C29 -> 48489.067 | D30: =IFERROR(C30/C$20,0) -> 0.60478224 | E30: =E20-E29 -> 27829.268 | F30: =IFERROR(E30/E$20,0) -> 0.6160178 | G30: =G20-G29 -> 48489.067 | H30: =IFERROR(G30/G$20,0) -> 0.60478224 | I30: =I20-I29 -> 27829.268 | J30: =IFERROR(I30/I$20,0) -> 0.6160178 | K30: =K20-K29 -> 42586.268 | L30: =IFERROR(K30/K$20,0) -> 0.60684879 | M30: =M20-M29 -> 39634.868 | N30: =IFERROR(M30/M$20,0) -> 0.60811987 | O30: =O20-O29 -> 39634.868 | P30: =IFERROR(O30/O$20,0) -> 0.60811987 | Q30: =Q20-Q29 -> 39634.868 | R30: =IFERROR(Q30/Q$20,0) -> 0.60811987 | S30: =S20-S29 -> 39634.868 | T30: =IFERROR(S30/S$20,0) -> 0.60811987 | U30: =U20-U29 -> 39634.868 | V30: =IFERROR(U30/U$20,0) -> 0.60811987 | W30: =W20-W29 -> 39634.868 | X30: =IFERROR(W30/W$20,0) -> 0.60811987 | Y30: =Y20-Y29 -> 39634.868 | Z30: =IFERROR(Y30/Y$20,0) -> 0.60811987 | AB30: =AB20-AB29 -> 472667.01 | AC30: =IFERROR(AB30/AB$20,0) -> 0.60823466
A32: Labor Cost
A33: Management Labor | C33: ='Vessel Budget'!C33+'LW Budget'!C33 -> 3092.8333 | D33: =IFERROR(C33/C$20,0) -> 0.038575514 | E33: ='Vessel Budget'!E33+'LW Budget'!E33 -> 3092.8333 | F33: =IFERROR(E33/E$20,0) -> 0.068461751 | G33: ='Vessel Budget'!G33+'LW Budget'!G33 -> 3092.8333 | H33: =IFERROR(G33/G$20,0) -> 0.038575514 | I33: ='Vessel Budget'!I33+'LW Budget'!I33 -> 3092.8333 | J33: =IFERROR(I33/I$20,0) -> 0.068461751 | K33: ='Vessel Budget'!K33+'LW Budget'!K33 -> 3092.8333 | L33: =IFERROR(K33/K$20,0) -> 0.044072474 | M33: ='Vessel Budget'!M33+'LW Budget'!M33 -> 3092.8333 | N33: =IFERROR(M33/M$20,0) -> 0.047453506 | O33: ='Vessel Budget'!O33+'LW Budget'!O33 -> 3092.8333 | P33: =IFERROR(O33/O$20,0) -> 0.047453506 | Q33: ='Vessel Budget'!Q33+'LW Budget'!Q33 -> 3092.8333 | R33: =IFERROR(Q33/Q$20,0) -> 0.047453506 | S33: ='Vessel Budget'!S33+'LW Budget'!S33 -> 3092.8333 | T33: =IFERROR(S33/S$20,0) -> 0.047453506 | U33: ='Vessel Budget'!U33+'LW Budget'!U33 -> 3092.8333 | V33: =IFERROR(U33/U$20,0) -> 0.047453506 | W33: ='Vessel Budget'!W33+'LW Budget'!W33 -> 3092.8333 | X33: =IFERROR(W33/W$20,0) -> 0.047453506 | Y33: ='Vessel Budget'!Y33+'LW Budget'!Y33 -> 3092.8333 | Z33: =IFERROR(Y33/Y$20,0) -> 0.047453506 | AB33: =SUM(C33,E33,G33,I33,K33,M33,O33,Q33,S33,U33,W33,Y33) -> 37114 | AC33: =IFERROR(AB33/AB$20,0) -> 0.047758825
A34: Back of House Hourly Labor | C34: ='Vessel Budget'!C34+'LW Budget'!C34 -> 1282.6667 | D34: =IFERROR(C34/C$20,0) -> 0.015998122 | E34: ='Vessel Budget'!E34+'LW Budget'!E34 -> 1282.6667 | F34: =IFERROR(E34/E$20,0) -> 0.028392609 | G34: ='Vessel Budget'!G34+'LW Budget'!G34 -> 1282.6667 | H34: =IFERROR(G34/G$20,0) -> 0.015998122 | I34: ='Vessel Budget'!I34+'LW Budget'!I34 -> 1282.6667 | J34: =IFERROR(I34/I$20,0) -> 0.028392609 | K34: ='Vessel Budget'!K34+'LW Budget'!K34 -> 1282.6667 | L34: =IFERROR(K34/K$20,0) -> 0.018277834 | M34: ='Vessel Budget'!M34+'LW Budget'!M34 -> 1282.6667 | N34: =IFERROR(M34/M$20,0) -> 0.019680023 | O34: ='Vessel Budget'!O34+'LW Budget'!O34 -> 1282.6667 | P34: =IFERROR(O34/O$20,0) -> 0.019680023 | Q34: ='Vessel Budget'!Q34+'LW Budget'!Q34 -> 1282.6667 | R34: =IFERROR(Q34/Q$20,0) -> 0.019680023 | S34: ='Vessel Budget'!S34+'LW Budget'!S34 -> 1282.6667 | T34: =IFERROR(S34/S$20,0) -> 0.019680023 | U34: ='Vessel Budget'!U34+'LW Budget'!U34 -> 1282.6667 | V34: =IFERROR(U34/U$20,0) -> 0.019680023 | W34: ='Vessel Budget'!W34+'LW Budget'!W34 -> 1282.6667 | X34: =IFERROR(W34/W$20,0) -> 0.019680023 | Y34: ='Vessel Budget'!Y34+'LW Budget'!Y34 -> 1282.6667 | Z34: =IFERROR(Y34/Y$20,0) -> 0.019680023 | AB34: =SUM(C34,E34,G34,I34,K34,M34,O34,Q34,S34,U34,W34,Y34) -> 15392 | AC34: =IFERROR(AB34/AB$20,0) -> 0.019806645
A35: Front of House Hourly Labor | C35: ='Vessel Budget'!C35+'LW Budget'!C35 -> 12010 | D35: =IFERROR(C35/C$20,0) -> 0.14979531 | E35: ='Vessel Budget'!E35+'LW Budget'!E35 -> 8335 | F35: =IFERROR(E35/E$20,0) -> 0.18450031 | G35: ='Vessel Budget'!G35+'LW Budget'!G35 -> 12010 | H35: =IFERROR(G35/G$20,0) -> 0.14979531 | I35: ='Vessel Budget'!I35+'LW Budget'!I35 -> 8335 | J35: =IFERROR(I35/I$20,0) -> 0.18450031 | K35: ='Vessel Budget'!K35+'LW Budget'!K35 -> 10960 | L35: =IFERROR(K35/K$20,0) -> 0.15617858 | M35: ='Vessel Budget'!M35+'LW Budget'!M35 -> 10435 | N35: =IFERROR(M35/M$20,0) -> 0.16010476 | O35: ='Vessel Budget'!O35+'LW Budget'!O35 -> 10435 | P35: =IFERROR(O35/O$20,0) -> 0.16010476 | Q35: ='Vessel Budget'!Q35+'LW Budget'!Q35 -> 10435 | R35: =IFERROR(Q35/Q$20,0) -> 0.16010476 | S35: ='Vessel Budget'!S35+'LW Budget'!S35 -> 10435 | T35: =IFERROR(S35/S$20,0) -> 0.16010476 | U35: ='Vessel Budget'!U35+'LW Budget'!U35 -> 10435 | V35: =IFERROR(U35/U$20,0) -> 0.16010476 | W35: ='Vessel Budget'!W35+'LW Budget'!W35 -> 10435 | X35: =IFERROR(W35/W$20,0) -> 0.16010476 | Y35: ='Vessel Budget'!Y35+'LW Budget'!Y35 -> 10435 | Z35: =IFERROR(Y35/Y$20,0) -> 0.16010476 | AB35: =SUM(C35,E35,G35,I35,K35,M35,O35,Q35,S35,U35,W35,Y35) -> 124695 | AC35: =IFERROR(AB35/AB$20,0) -> 0.16045931
A36: Payroll Taxes & Benefits | C36: ='Vessel Budget'!C36+'LW Budget'!C36 -> 2628.3658 | D36: =IFERROR(C36/C$20,0) -> 0.03278242 | E36: ='Vessel Budget'!E36+'LW Budget'!E36 -> 2036.6908 | F36: =IFERROR(E36/E$20,0) -> 0.045083393 | G36: ='Vessel Budget'!G36+'LW Budget'!G36 -> 2628.3658 | H36: =IFERROR(G36/G$20,0) -> 0.03278242 | I36: ='Vessel Budget'!I36+'LW Budget'!I36 -> 2036.6908 | J36: =IFERROR(I36/I$20,0) -> 0.045083393 | K36: ='Vessel Budget'!K36+'LW Budget'!K36 -> 2459.3158 | L36: =IFERROR(K36/K$20,0) -> 0.035044932 | M36: ='Vessel Budget'!M36+'LW Budget'!M36 -> 2374.7908 | N36: =IFERROR(M36/M$20,0) -> 0.036436542 | O36: ='Vessel Budget'!O36+'LW Budget'!O36 -> 2374.7908 | P36: =IFERROR(O36/O$20,0) -> 0.036436542 | Q36: ='Vessel Budget'!Q36+'LW Budget'!Q36 -> 2374.7908 | R36: =IFERROR(Q36/Q$20,0) -> 0.036436542 | S36: ='Vessel Budget'!S36+'LW Budget'!S36 -> 2374.7908 | T36: =IFERROR(S36/S$20,0) -> 0.036436542 | U36: ='Vessel Budget'!U36+'LW Budget'!U36 -> 2374.7908 | V36: =IFERROR(U36/U$20,0) -> 0.036436542 | W36: ='Vessel Budget'!W36+'LW Budget'!W36 -> 2374.7908 | X36: =IFERROR(W36/W$20,0) -> 0.036436542 | Y36: ='Vessel Budget'!Y36+'LW Budget'!Y36 -> 2374.7908 | Z36: =IFERROR(Y36/Y$20,0) -> 0.036436542 | AB36: =SUM(C36,E36,G36,I36,K36,M36,O36,Q36,S36,U36,W36,Y36) -> 28412.965 | AC36: =IFERROR(AB36/AB$20,0) -> 0.036562209
A37: Bonus | C37: ='Vessel Budget'!C37+'LW Budget'!C37 -> 0 | D37: =IFERROR(C37/C$20,0) -> 0 | E37: ='Vessel Budget'!E37+'LW Budget'!E37 -> 0 | F37: =IFERROR(E37/E$20,0) -> 0 | G37: ='Vessel Budget'!G37+'LW Budget'!G37 -> 0 | H37: =IFERROR(G37/G$20,0) -> 0 | I37: ='Vessel Budget'!I37+'LW Budget'!I37 -> 0 | J37: =IFERROR(I37/I$20,0) -> 0 | K37: ='Vessel Budget'!K37+'LW Budget'!K37 -> 0 | L37: =IFERROR(K37/K$20,0) -> 0 | M37: ='Vessel Budget'!M37+'LW Budget'!M37 -> 0 | N37: =IFERROR(M37/M$20,0) -> 0 | O37: ='Vessel Budget'!O37+'LW Budget'!O37 -> 0 | P37: =IFERROR(O37/O$20,0) -> 0 | Q37: ='Vessel Budget'!Q37+'LW Budget'!Q37 -> 0 | R37: =IFERROR(Q37/Q$20,0) -> 0 | S37: ='Vessel Budget'!S37+'LW Budget'!S37 -> 0 | T37: =IFERROR(S37/S$20,0) -> 0 | U37: ='Vessel Budget'!U37+'LW Budget'!U37 -> 0 | V37: =IFERROR(U37/U$20,0) -> 0 | W37: ='Vessel Budget'!W37+'LW Budget'!W37 -> 0 | X37: =IFERROR(W37/W$20,0) -> 0 | Y37: ='Vessel Budget'!Y37+'LW Budget'!Y37 -> 0 | Z37: =IFERROR(Y37/Y$20,0) -> 0 | AB37: =SUM(C37,E37,G37,I37,K37,M37,O37,Q37,S37,U37,W37,Y37) -> 0 | AC37: =IFERROR(AB37/AB$20,0) -> 0
A38: Total Labor Cost | C38: =SUM(C33:C37) -> 19013.866 | D38: =IFERROR(C38/C$20,0) -> 0.23715136 | E38: =SUM(E33:E37) -> 14747.191 | F38: =IFERROR(E38/E$20,0) -> 0.32643806 | G38: =SUM(G33:G37) -> 19013.866 | H38: =IFERROR(G38/G$20,0) -> 0.23715136 | I38: =SUM(I33:I37) -> 14747.191 | J38: =IFERROR(I38/I$20,0) -> 0.32643806 | K38: =SUM(K33:K37) -> 17794.816 | L38: =IFERROR(K38/K$20,0) -> 0.25357382 | M38: =SUM(M33:M37) -> 17185.291 | N38: =IFERROR(M38/M$20,0) -> 0.26367483 | O38: =SUM(O33:O37) -> 17185.291 | P38: =IFERROR(O38/O$20,0) -> 0.26367483 | Q38: =SUM(Q33:Q37) -> 17185.291 | R38: =IFERROR(Q38/Q$20,0) -> 0.26367483 | S38: =SUM(S33:S37) -> 17185.291 | T38: =IFERROR(S38/S$20,0) -> 0.26367483 | U38: =SUM(U33:U37) -> 17185.291 | V38: =IFERROR(U38/U$20,0) -> 0.26367483 | W38: =SUM(W33:W37) -> 17185.291 | X38: =IFERROR(W38/W$20,0) -> 0.26367483 | Y38: =SUM(Y33:Y37) -> 17185.291 | Z38: =IFERROR(Y38/Y$20,0) -> 0.26367483 | AB38: =SUM(AB33:AB37) -> 205613.96 | AC38: =IFERROR(AB38/AB$20,0) -> 0.26458699
A40: Prime Costs | C40: =C29+C38 -> 50700.875 | D40: =IFERROR(C40/C$20,0) -> 0.63236912 | E40: =E29+E38 -> 32094 | F40: =IFERROR(E40/E$20,0) -> 0.71042026 | G40: =G29+G38 -> 50700.875 | H40: =IFERROR(G40/G$20,0) -> 0.63236912 | I40: =I29+I38 -> 32094 | J40: =IFERROR(I40/I$20,0) -> 0.71042026 | K40: =K29+K38 -> 45384.625 | L40: =IFERROR(K40/K$20,0) -> 0.64672503 | M40: =M29+M38 -> 42726.5 | N40: =IFERROR(M40/M$20,0) -> 0.65555495 | O40: =O29+O38 -> 42726.5 | P40: =IFERROR(O40/O$20,0) -> 0.65555495 | Q40: =Q29+Q38 -> 42726.5 | R40: =IFERROR(Q40/Q$20,0) -> 0.65555495 | S40: =S29+S38 -> 42726.5 | T40: =IFERROR(S40/S$20,0) -> 0.65555495 | U40: =U29+U38 -> 42726.5 | V40: =IFERROR(U40/U$20,0) -> 0.65555495 | W40: =W29+W38 -> 42726.5 | X40: =IFERROR(W40/W$20,0) -> 0.65555495 | Y40: =Y29+Y38 -> 42726.5 | Z40: =IFERROR(Y40/Y$20,0) -> 0.65555495 | AB40: =AB29+AB38 -> 510059.88 | AC40: =IFERROR(AB40/AB$20,0) -> 0.65635233
A41: Operating Profit | C41: =C30-C38 -> 29475.202 | D41: =IFERROR(C41/C$20,0) -> 0.36763088 | E41: =E30-E38 -> 13082.077 | F41: =IFERROR(E41/E$20,0) -> 0.28957974 | G41: =G30-G38 -> 29475.202 | H41: =IFERROR(G41/G$20,0) -> 0.36763088 | I41: =I30-I38 -> 13082.077 | J41: =IFERROR(I41/I$20,0) -> 0.28957974 | K41: =K30-K38 -> 24791.452 | L41: =IFERROR(K41/K$20,0) -> 0.35327497 | M41: =M30-M38 -> 22449.577 | N41: =IFERROR(M41/M$20,0) -> 0.34444505 | O41: =O30-O38 -> 22449.577 | P41: =IFERROR(O41/O$20,0) -> 0.34444505 | Q41: =Q30-Q38 -> 22449.577 | R41: =IFERROR(Q41/Q$20,0) -> 0.34444505 | S41: =S30-S38 -> 22449.577 | T41: =IFERROR(S41/S$20,0) -> 0.34444505 | U41: =U30-U38 -> 22449.577 | V41: =IFERROR(U41/U$20,0) -> 0.34444505 | W41: =W30-W38 -> 22449.577 | X41: =IFERROR(W41/W$20,0) -> 0.34444505 | Y41: =Y30-Y38 -> 22449.577 | Z41: =IFERROR(Y41/Y$20,0) -> 0.34444505 | AB41: =AB30-AB38 -> 267053.04 | AC41: =IFERROR(AB41/AB$20,0) -> 0.34364767
A43: Controllable Expenses
A44: Operating Expenses | C44: ='Vessel Budget'!C44+'LW Budget'!C44 -> 5446.9269 | D44: =IFERROR(C44/C$20,0) -> 0.06793706 | E44: ='Vessel Budget'!E44+'LW Budget'!E44 -> 5446.9269 | F44: =IFERROR(E44/E$20,0) -> 0.12057105 | G44: ='Vessel Budget'!G44+'LW Budget'!G44 -> 5446.9269 | H44: =IFERROR(G44/G$20,0) -> 0.06793706 | I44: ='Vessel Budget'!I44+'LW Budget'!I44 -> 5446.9269 | J44: =IFERROR(I44/I$20,0) -> 0.12057105 | K44: ='Vessel Budget'!K44+'LW Budget'!K44 -> 5446.9269 | L44: =IFERROR(K44/K$20,0) -> 0.077618003 | M44: ='Vessel Budget'!M44+'LW Budget'!M44 -> 5446.9269 | N44: =IFERROR(M44/M$20,0) -> 0.083572488 | O44: ='Vessel Budget'!O44+'LW Budget'!O44 -> 5446.9269 | P44: =IFERROR(O44/O$20,0) -> 0.083572488 | Q44: ='Vessel Budget'!Q44+'LW Budget'!Q44 -> 5446.9269 | R44: =IFERROR(Q44/Q$20,0) -> 0.083572488 | S44: ='Vessel Budget'!S44+'LW Budget'!S44 -> 5446.9269 | T44: =IFERROR(S44/S$20,0) -> 0.083572488 | U44: ='Vessel Budget'!U44+'LW Budget'!U44 -> 5446.9269 | V44: =IFERROR(U44/U$20,0) -> 0.083572488 | W44: ='Vessel Budget'!W44+'LW Budget'!W44 -> 5446.9269 | X44: =IFERROR(W44/W$20,0) -> 0.083572488 | Y44: ='Vessel Budget'!Y44+'LW Budget'!Y44 -> 5446.9269 | Z44: =IFERROR(Y44/Y$20,0) -> 0.083572488 | AB44: =SUM(C44,E44,G44,I44,K44,M44,O44,Q44,S44,U44,W44,Y44) -> 65363.123 | AC44: =IFERROR(AB44/AB$20,0) -> 0.0841102
A45: Music & Entertainment | C45: ='Vessel Budget'!C45+'LW Budget'!C45 -> 956.91667 | D45: =IFERROR(C45/C$20,0) -> 0.011935189 | E45: ='Vessel Budget'!E45+'LW Budget'!E45 -> 956.91667 | F45: =IFERROR(E45/E$20,0) -> 0.021181934 | G45: ='Vessel Budget'!G45+'LW Budget'!G45 -> 956.91667 | H45: =IFERROR(G45/G$20,0) -> 0.011935189 | I45: ='Vessel Budget'!I45+'LW Budget'!I45 -> 956.91667 | J45: =IFERROR(I45/I$20,0) -> 0.021181934 | K45: ='Vessel Budget'!K45+'LW Budget'!K45 -> 956.91667 | L45: =IFERROR(K45/K$20,0) -> 0.013635939 | M45: ='Vessel Budget'!M45+'LW Budget'!M45 -> 956.91667 | N45: =IFERROR(M45/M$20,0) -> 0.014682023 | O45: ='Vessel Budget'!O45+'LW Budget'!O45 -> 956.91667 | P45: =IFERROR(O45/O$20,0) -> 0.014682023 | Q45: ='Vessel Budget'!Q45+'LW Budget'!Q45 -> 956.91667 | R45: =IFERROR(Q45/Q$20,0) -> 0.014682023 | S45: ='Vessel Budget'!S45+'LW Budget'!S45 -> 956.91667 | T45: =IFERROR(S45/S$20,0) -> 0.014682023 | U45: ='Vessel Budget'!U45+'LW Budget'!U45 -> 956.91667 | V45: =IFERROR(U45/U$20,0) -> 0.014682023 | W45: ='Vessel Budget'!W45+'LW Budget'!W45 -> 956.91667 | X45: =IFERROR(W45/W$20,0) -> 0.014682023 | Y45: ='Vessel Budget'!Y45+'LW Budget'!Y45 -> 956.91667 | Z45: =IFERROR(Y45/Y$20,0) -> 0.014682023 | AB45: =SUM(C45,E45,G45,I45,K45,M45,O45,Q45,S45,U45,W45,Y45) -> 11483 | AC45: =IFERROR(AB45/AB$20,0) -> 0.014776488
A46: Marketing & Advertising | C46: ='Vessel Budget'!C46+'LW Budget'!C46 -> 1506.25 | D46: =IFERROR(C46/C$20,0) -> 0.018786776 | E46: ='Vessel Budget'!E46+'LW Budget'!E46 -> 1506.25 | F46: =IFERROR(E46/E$20,0) -> 0.033341762 | G46: ='Vessel Budget'!G46+'LW Budget'!G46 -> 1506.25 | H46: =IFERROR(G46/G$20,0) -> 0.018786776 | I46: ='Vessel Budget'!I46+'LW Budget'!I46 -> 1506.25 | J46: =IFERROR(I46/I$20,0) -> 0.033341762 | K46: ='Vessel Budget'!K46+'LW Budget'!K46 -> 1506.25 | L46: =IFERROR(K46/K$20,0) -> 0.021463867 | M46: ='Vessel Budget'!M46+'LW Budget'!M46 -> 1506.25 | N46: =IFERROR(M46/M$20,0) -> 0.023110474 | O46: ='Vessel Budget'!O46+'LW Budget'!O46 -> 1506.25 | P46: =IFERROR(O46/O$20,0) -> 0.023110474 | Q46: ='Vessel Budget'!Q46+'LW Budget'!Q46 -> 1506.25 | R46: =IFERROR(Q46/Q$20,0) -> 0.023110474 | S46: ='Vessel Budget'!S46+'LW Budget'!S46 -> 1506.25 | T46: =IFERROR(S46/S$20,0) -> 0.023110474 | U46: ='Vessel Budget'!U46+'LW Budget'!U46 -> 1506.25 | V46: =IFERROR(U46/U$20,0) -> 0.023110474 | W46: ='Vessel Budget'!W46+'LW Budget'!W46 -> 1506.25 | X46: =IFERROR(W46/W$20,0) -> 0.023110474 | Y46: ='Vessel Budget'!Y46+'LW Budget'!Y46 -> 1506.25 | Z46: =IFERROR(Y46/Y$20,0) -> 0.023110474 | AB46: =SUM(C46,E46,G46,I46,K46,M46,O46,Q46,S46,U46,W46,Y46) -> 18075 | AC46: =IFERROR(AB46/AB$20,0) -> 0.023259168
A47: General & Administrative - Controllable | C47: ='Vessel Budget'!C47+'LW Budget'!C47 -> 6723.6667 | D47: =IFERROR(C47/C$20,0) -> 0.083861258 | E47: ='Vessel Budget'!E47+'LW Budget'!E47 -> 6723.6667 | F47: =IFERROR(E47/E$20,0) -> 0.14883246 | G47: ='Vessel Budget'!G47+'LW Budget'!G47 -> 6723.6667 | H47: =IFERROR(G47/G$20,0) -> 0.083861258 | I47: ='Vessel Budget'!I47+'LW Budget'!I47 -> 6723.6667 | J47: =IFERROR(I47/I$20,0) -> 0.14883246 | K47: ='Vessel Budget'!K47+'LW Budget'!K47 -> 6723.6667 | L47: =IFERROR(K47/K$20,0) -> 0.095811379 | M47: ='Vessel Budget'!M47+'LW Budget'!M47 -> 6723.6667 | N47: =IFERROR(M47/M$20,0) -> 0.10316157 | O47: ='Vessel Budget'!O47+'LW Budget'!O47 -> 6723.6667 | P47: =IFERROR(O47/O$20,0) -> 0.10316157 | Q47: ='Vessel Budget'!Q47+'LW Budget'!Q47 -> 6723.6667 | R47: =IFERROR(Q47/Q$20,0) -> 0.10316157 | S47: ='Vessel Budget'!S47+'LW Budget'!S47 -> 6723.6667 | T47: =IFERROR(S47/S$20,0) -> 0.10316157 | U47: ='Vessel Budget'!U47+'LW Budget'!U47 -> 6723.6667 | V47: =IFERROR(U47/U$20,0) -> 0.10316157 | W47: ='Vessel Budget'!W47+'LW Budget'!W47 -> 6723.6667 | X47: =IFERROR(W47/W$20,0) -> 0.10316157 | Y47: ='Vessel Budget'!Y47+'LW Budget'!Y47 -> 6723.6667 | Z47: =IFERROR(Y47/Y$20,0) -> 0.10316157 | AB47: =SUM(C47,E47,G47,I47,K47,M47,O47,Q47,S47,U47,W47,Y47) -> 80684 | AC47: =IFERROR(AB47/AB$20,0) -> 0.10382532
...

Sheet Vessel Summary
B2: VESSEL EVENTS — 2027 OPERATING SUMMARY
B3: ="$"&TEXT('Vessel Assumptions'!$C$6,"#,##0")&" F&B min · "&TEXT('Vessel Assumptions'!$C$7,"0%")&" volume · "&TEXT('Vessel Assumptions'!$C$30,"0%")&" mgmt fee" -> $4,000 F&B min · 80% volume · 4% mgmt fee
B5: ANNUAL P&L | C5: $ | D5: % rev | F5: KEY METRICS
B6: Total revenue | C6: ='Vessel Budget'!$AB$20 -> 415000 | D6: =C6/C6 -> 1 | F6: Net operating margin | G6: ='Vessel Budget'!$AB$62/'Vessel Budget'!$AB$20 -> 0.1306689
B7: Total COGS | C7: ='Vessel Budget'!$AB$29 -> 170033.8 | D7: =C7/C6 -> 0.40972 | F7: Prime cost % | G7: ='Vessel Budget'!$AB$40/'Vessel Budget'!$AB$20 -> 0.57982748
B8: Gross profit | C8: ='Vessel Budget'!$AB$30 -> 244966.2 | D8: =C8/C6 -> 0.59028 | F8: COGS % | G8: ='Vessel Budget'!$AB$29/'Vessel Budget'!$AB$20 -> 0.40972
B9: Total labor (incl. mgmt) | C9: ='Vessel Budget'!$AB$38 -> 70594.605 | D9: =C9/C6 -> 0.17010748 | F9: Total events / year | G9: ='Vessel Budget'!$AB$9 -> 83
B10: Prime cost | C10: ='Vessel Budget'!$AB$40 -> 240628.4 | D10: =C10/C6 -> 0.57982748 | F10: Avg F&B / event | G10: =SUM('Vessel Budget'!$AB$12:$AB$16)/'Vessel Budget'!$AB$9 -> 4000
B11: Controllable (excl CC) | C11: ='Vessel Budget'!$AB$50-'Vessel Budget'!$AB$49 -> 80624 | D11: =C11/C6 -> 0.1942747 | F11: Revenue / event | G11: ='Vessel Budget'!$AB$20/'Vessel Budget'!$AB$9 -> 5000
B12: Credit card fees (2.5%) | C12: ='Vessel Budget'!$AB$49 -> 10375 | D12: =C12/C6 -> 0.025
