Workbook

Sheet Deck Tie-Out (LW)
A1: LITTLE WING — DECK TIE-OUT
A2: Every financial claim in LW_Vessel_Plan_of_Action → its live model source. Model values recalculate; if a Status turns ⚠, deck and model have diverged.
A4: Slide | B4: Claim in deck | C4: Deck value | D4: Model source | E4: Model value (live) | F4: Status / note
A5: 2 | B5: 2026 revenue (Act/For) | C5: $288.7K | D5: LW 2026 P&L AB16 | E5: ='LW 2026 P&L'!$AB$16 | F5: ✓
A6: 2 | B6: 2026 net operating loss | C6: ($164.0K) | D6: LW 2026 P&L AB55 | E6: ='LW 2026 P&L'!$AB$55 | F6: ✓
A7: 2 | B7: Labor as % of revenue | C7: 59% | D7: AB33 / AB16 | E7: ='LW 2026 P&L'!$AB$33/'LW 2026 P&L'!$AB$16 | F7: ✓
A8: 2 | B8: Prime cost % | C8: 95.2% | D8: (AB24+AB33)/AB16 | E8: =('LW 2026 P&L'!$AB$24+'LW 2026 P&L'!$AB$33)/'LW 2026 P&L'!$AB$16 | F8: ✓
A9: 2 | B9: Flat mgmt fee + rent today | C9: $65.4K | D9: AB50 + AB48 | E9: ='LW 2026 P&L'!$AB$50+'LW 2026 P&L'!$AB$48 | F9: ✓
A10: 2 | B10: Discounts & comps | C10: ($18.6K) | D10: LW 2026 P&L AB15 | E10: ='LW 2026 P&L'!$AB$15 | F10: ✓
A11: 4 | B11: Product mix by group (8 categories) | C11: $250.5K total | D11: TTM PMIX export (external workbook) | F11: ≈ ties within mapping of $10.6K uncategorized rings — rebuild from TTM export for exact figures
A12: 5 | B12: Self-serve window share of sales | C12: 17% | D12: Daypart Analysis — TTM post-4pm % | E12: ='LW Daypart Analysis'!$D$59 | F12: ✓ (17.3%)
A13: 5 | B13: "Three biggest hours ~39% of the day" | C13: ~39% | D13: TTM: 8–10am = $87.2K of $254.9K | E13: =87226/254946 | F13: ⚠ TTM says 34.2% — fix deck copy
A14: 6 | B14: Labor lever (chip) | C14: +$39K/yr | D14: Weekly Compare D29 (annualized savings) | E14: =-'LW Weekly Compare'!$D$29 | F14: ✓ · plan-year P&L now ties exactly: December true-up in LW Budget Y37 reconciles to the Weekly Compare basis
A15: 6 | B15: Pricing lever (chip) | C15: +$9K/yr | D15: Menu Pricing C53 (net @90% capture) | E15: ='LW Menu Pricing'!$C$53 | F15: ✓
A16: 6 | B16: Retail lever (chip) | C16: +$24K GP/yr | D16: base uplift + programming × margin | E16: ='LW Assumptions'!$C$47+'LW Assumptions'!$C$36*(1-'LW Assumptions'!$C$37) | F16: ✓ ($23.9K)
A17: 6 | B17: Owner charges today → plan | C17: $65.4K → $14.8K | D17: LW 2026 P&L AB50+AB48 → LW Budget AB56 | E17: ='LW Budget'!$AB$56 | F17: ✓ (plan side; today side row above)
A18: 6 | B18: Owner charges saving (chip) | C18: −$51K/yr | D18: difference of the two | E18: =('LW 2026 P&L'!$AB$50+'LW 2026 P&L'!$AB$48)-'LW Budget'!$AB$56 | F18: ✓ ($50.9K)
A19: 6 | B19: Owner charges % of revenue | C19: 22.6% → 4.0% | D19: fee+rent ÷ revenue, both years | E19: ='LW Budget'!$AB$56/'LW Budget'!$AB$20 | F19: ✓ (plan side 4.0%)
A20: 6 | B20: Programming lever | C20: +$500/wk | D20: assumption — baked into the revenue base | F20: ✓ by convention: 2x/month activations assumed to sustain ~$500/wk of traffic already counted in the Act/For-based revenue; no separate lever, no double-count
A21: 7 | B21: Post-4pm share of sales (TTM) | C21: 17.3% | D21: Daypart Analysis TTM block | E21: ='LW Daypart Analysis'!$D$59 | F21: ✓
A22: 7 | B22: Barista-required share of post-4pm | C22: 21.5% | D22: Daypart Analysis TTM block | E22: ='LW Daypart Analysis'!$D$60 | F22: ✓
A23: 7 | B23: Net sales at risk | C23: ~3.7% | D23: barista-required ÷ TTM total | E23: ='LW Daypart Analysis'!$C$60/244323 | F23: ✓
A24: 8 | B24: Proposed loaded labor / week | C24: $2,441 | D24: Weekly Compare C20 | E24: ='LW Weekly Compare'!$C$20 | F24: ✓ whole table = Weekly Compare tab, cols B (current) & C (proposed)
A25: 8 | B25: Weekly savings → annualized | C25: −$750 / ~$39.0K | D25: Weekly Compare C29 / D29 | E25: ='LW Weekly Compare'!$C$29 | F25: ✓
A26: 9 | B26: Item prices, units & bumps (10 rows) | C26: per deck | D26: LW Menu Pricing rows 6–15 | F26: ✓ tab rebuilt FROM the deck (TTM units, list prices) — deck is source of truth
A27: 11 | B27: Today shelf run-rate | C27: $1,346/wk | D27: Retail Plan B15 ÷ 52 | E27: ='LW Retail Plan'!$B$15/52 | F27: ✓
A28: 11 | B28: Plan-year shelf revenue | C28: $114.9K | D28: Retail Plan E15 | E28: ='LW Retail Plan'!$E$15 | F28: ✓
A29: 11 | B29: Shelf % of go-forward top line | C29: 31.7% | D29: Retail Plan E15 ÷ LW Budget AB20 | E29: ='LW Retail Plan'!$E$15/'LW Budget'!$AB$20 | F29: ✓
A30: 11 | B30: Incremental gross profit | C30: $23.9K/yr | D30: base uplift (0% COGS) + programming margin | E30: ='LW Assumptions'!$C$47+'LW Assumptions'!$C$36*(1-'LW Assumptions'!$C$37) | F30: ✓ note: Retail Plan F15 shows $22.5K because it applies blended COGS to the base uplift too — model is the truth
A31: 14 | B31: Total income (Act/For → Mod → 2027) | C31: $288.7/311.2/362.1K | D31: Scenario Summary row 6 (C/D/E) | E31: ='Scenario Summary'!$E$6 | F31: ✓ (2027 shown; whole table = Scenario Summary LW block)
A32: 14 | B32: NOP (Act/For → Mod → 2027) | C32: (164.0)/(97.4)/+1.0K | D32: Scenario Summary row 14 | E32: ='Scenario Summary'!$E$14 | F32: ✓
A33: 14 | B33: Loss cut vs Act/For | C33: loss eliminated | D33: 1 − E14/C14 | E33: =1-'Scenario Summary'!$E$14/'Scenario Summary'!$C$14 | F33: ✓
A34: 14 | B34: Combined 2027 (with Vessel) | C34: +$97.1K | D34: Scenario Summary E40 | E34: ='Scenario Summary'!$E$40 | F34: ✓
A35: 14 | B35: Immediate impact note: Aug–Dec with vs without changes | C35: +$66.6K | D35: 2026 Bridge D19 | E35: ='2026 Bridge'!$D$19 | F35: ✓
A36: 18 | B36: Vessel go-forward: Aug–Dec immediate impact | C36: +$37.2K | D36: 2026 Bridge D20 | E36: ='2026 Bridge'!$D$20 | F36: ✓ (Vessel slide)
A37: 7 | B37: Point 3: 4pm-close trade — labor saved vs worst-case margin lost | C37: +$27.5K worst case | D37: Daypart Analysis C68–C70 | E37: ='LW Daypart Analysis'!$C$70 | F37: ✓

Sheet Scenario Summary
A1: Method Terrapin
A2: Scenario Summary — T12 · 2026 Forecast · 2026 Modified (changes from effective dates) · 2027 Plan
A4: LITTLE WING
B5: T12 (GL actual) | C5: 2026 Act/For (unmodified) | D5: 2026 Act/For MODIFIED | E5: 2027 Plan
A6: Total Income | B6: 258287 | C6: ='LW 2026 P&L'!$AB$16 | D6: ='LW 2026 Modified'!$AB$20 | E6: ='LW Budget'!$AB$20
A7: Total COGS | B7: 81599 | C7: ='LW 2026 P&L'!$AB$24 | D7: ='LW 2026 Modified'!$AB$29 | E7: ='LW Budget'!$AB$29
A8: Gross Profit | B8: =B6-B7 | C8: =C6-C7 | D8: =D6-D7 | E8: =E6-E7
A9: Total Labor Cost | B9: 164857 | C9: ='LW 2026 P&L'!$AB$33 | D9: ='LW 2026 Modified'!$AB$38 | E9: ='LW Budget'!$AB$38
A10: Operating Expenses (excl fees & occupancy) | B10: 105344 | C10: ='LW 2026 P&L'!$AB$44+'LW 2026 P&L'!$AB$53-'LW 2026 P&L'!$AB$50-'LW 2026 P&L'!$AB$48 | D10: ='LW 2026 Modified'!$AB$50+'LW 2026 Modified'!$AB$60-'LW 2026 Modified'!$AB$54-'LW 2026 Modified'!$AB$56-'LW 2026 Modified'!$AB$57 | E10: ='LW Budget'!$AB$50+'LW Budget'!$AB$60-'LW Budget'!$AB$54-'LW Budget'!$AB$56-'LW Budget'!$AB$57
A11: Management Fee | B11: 48000 | C11: ='LW 2026 P&L'!$AB$50 | D11: ='LW 2026 Modified'!$AB$56 | E11: ='LW Budget'!$AB$56
A12: Admin Fee (Vessel — billed to clients, in income) | B12: 0 | C12: 0 | D12: ='LW 2026 Modified'!$AB$57 | E12: =0
A13: Occupancy / Rent | B13: 15642 | C13: ='LW 2026 P&L'!$AB$48 | D13: ='LW 2026 Modified'!$AB$54 | E13: ='LW Budget'!$AB$54
A14: Net Operating Profit | B14: =B6-B7-B9-B10-B11-B12-B13 | C14: =C6-C7-C9-C10-C11-C12-C13 | D14: =D6-D7-D9-D10-D11-D12-D13 | E14: =E6-E7-E9-E10-E11-E12-E13
A15: NOP margin | B15: =B14/B6 | C15: =C14/C6 | D15: =D14/D6 | E15: =E14/E6
A17: VESSEL
B18: T12 (GL actual) | C18: 2026 Act/For (unmodified) | D18: 2026 Act/For MODIFIED | E18: 2027 Plan
A19: Total Income | B19: ='Vessel 2026 P&L'!$AB$16 | C19: ='Vessel 2026 P&L'!$AB$16 | D19: ='Vessel 2026 Modified'!$AB$20 | E19: ='Vessel Budget'!$AB$20
A20: Total COGS | B20: ='Vessel 2026 P&L'!$AB$24 | C20: ='Vessel 2026 P&L'!$AB$24 | D20: ='Vessel 2026 Modified'!$AB$29 | E20: ='Vessel Budget'!$AB$29
A21: Gross Profit | B21: =B19-B20 | C21: =C19-C20 | D21: =D19-D20 | E21: =E19-E20
A22: Total Labor Cost | B22: ='Vessel 2026 P&L'!$AB$33 | C22: ='Vessel 2026 P&L'!$AB$33 | D22: ='Vessel 2026 Modified'!$AB$38 | E22: ='Vessel Budget'!$AB$38
A23: Operating Expenses (excl fees & occupancy) | B23: ='Vessel 2026 P&L'!$AB$44+'Vessel 2026 P&L'!$AB$53-'Vessel 2026 P&L'!$AB$50-'Vessel 2026 P&L'!$AB$48 | C23: ='Vessel 2026 P&L'!$AB$44+'Vessel 2026 P&L'!$AB$53-'Vessel 2026 P&L'!$AB$50-'Vessel 2026 P&L'!$AB$48 | D23: ='Vessel 2026 Modified'!$AB$50+'Vessel 2026 Modified'!$AB$60-'Vessel 2026 Modified'!$AB$54-'Vessel 2026 Modified'!$AB$56-'Vessel 2026 Modified'!$AB$57 | E23: ='Vessel Budget'!$AB$50+'Vessel Budget'!$AB$60-'Vessel Budget'!$AB$54-'Vessel Budget'!$AB$56-'Vessel Budget'!$AB$57
A24: Management Fee | B24: ='Vessel 2026 P&L'!$AB$50 | C24: ='Vessel 2026 P&L'!$AB$50 | D24: ='Vessel 2026 Modified'!$AB$56 | E24: ='Vessel Budget'!$AB$56
A25: Admin Fee (Vessel — billed to clients, in income) | B25: 0 | C25: 0 | D25: ='Vessel 2026 Modified'!$AB$57 | E25: ='Vessel Budget'!$AB$57
A26: Occupancy / Rent | B26: ='Vessel 2026 P&L'!$AB$48 | C26: ='Vessel 2026 P&L'!$AB$48 | D26: ='Vessel 2026 Modified'!$AB$54 | E26: ='Vessel Budget'!$AB$54
A27: Net Operating Profit | B27: =B19-B20-B22-B23-B24-B25-B26 | C27: =C19-C20-C22-C23-C24-C25-C26 | D27: =D19-D20-D22-D23-D24-D25-D26 | E27: =E19-E20-E22-E23-E24-E25-E26
A28: NOP margin | B28: =B27/B19 | C28: =C27/C19 | D28: =D27/D19 | E28: =E27/E19
A30: COMBINED
B31: T12 (GL actual) | C31: 2026 Act/For (unmodified) | D31: 2026 Act/For MODIFIED | E31: 2027 Plan
A32: Total Income | B32: =B6+B19 | C32: =C6+C19 | D32: =D6+D19 | E32: =E6+E19
A33: Total COGS | B33: =B7+B20 | C33: =C7+C20 | D33: =D7+D20 | E33: =E7+E20
A34: Gross Profit | B34: =B32-B33 | C34: =C32-C33 | D34: =D32-D33 | E34: =E32-E33
A35: Total Labor Cost | B35: =B9+B22 | C35: =C9+C22 | D35: =D9+D22 | E35: =E9+E22
A36: Operating Expenses (excl fees & occupancy) | B36: =B10+B23 | C36: =C10+C23 | D36: =D10+D23 | E36: =E10+E23
A37: Management Fee | B37: =B11+B24 | C37: =C11+C24 | D37: =D11+D24 | E37: =E11+E24
A38: Admin Fee (Vessel — billed to clients, in income) | B38: =B12+B25 | C38: =C12+C25 | D38: =D12+D25 | E38: =E12+E25
A39: Occupancy / Rent | B39: =B13+B26 | C39: =C13+C26 | D39: =D13+D26 | E39: =E13+E26
A40: Net Operating Profit | B40: =B32-B33-B35-B36-B37-B38-B39 | C40: =C32-C33-C35-C36-C37-C38-C39 | D40: =D32-D33-D35-D36-D37-D38-D39 | E40: =E32-E33-E35-E36-E37-E38-E39
A41: NOP margin | B41: =B40/B32 | C41: =C40/C32 | D41: =D40/D32 | E41: =E40/E32
A43: Vessel T12 seeded with 2026 Act/For. Unmodified = accountant Act/For statements (Jan–Jun actual). MODIFIED = monthly build on the 2026 Modified tabs — levers live from the go-live date input (default 2026-08-01, editable on each Modified tab). 2027 Plan: LW = annualized modified run-rate; Vessel = event-driven plan ($4K F&B min × 80% volume).

Sheet 2026 Bridge
A1: 2026 CHANGE RECONCILIATION
A2: Unmodified Act/For → Modified 2026 · driven by the monthly Modified tabs (levers gated by each tab's go-live date input)
B4: Unmodified 2026 NOP | C4: Δ from changes | D4: MODIFIED 2026 NOP | E4: Go-live
A5: Little Wing | B5: ='LW 2026 P&L'!$AB$55 | C5: ='LW 2026 Modified'!$AB$62-'LW 2026 P&L'!$AB$55 | D5: ='LW 2026 Modified'!$AB$62 | E5: ='LW 2026 Modified'!$C$4
A6: Vessel | B6: ='Vessel 2026 P&L'!$AB$55 | C6: ='Vessel 2026 Modified'!$AB$62-'Vessel 2026 P&L'!$AB$55 | D6: ='Vessel 2026 Modified'!$AB$62 | E6: ='Vessel 2026 Modified'!$C$4
A7: COMBINED | B7: =B5+B6 | C7: =C5+C6 | D7: =D5+D6
A9: LEVERS IN THE MODIFIED MONTHS (edit on LW Assumptions / LW Menu Pricing / Vessel Assumptions):
A10: LW — Single-shift staffing: FOH 6:30am–4pm (C20) + wknd 2nd barista (C21) @ $20/hr (C23) + BOH cook $296/wk (C26) + GL mgmt labor kept
A11: LW — Menu pricing uplift (item-level, LW Menu Pricing) × capture % → Food/NA lines, pure margin
A12: LW — Retail: existing-base uplift (C46) + new programming $ (C36) with programming COGS % (C37)
A13: LW — Management fee: $4,000/mo → 4% of revenue (C40) · rent WAIVED (C41=0%) · CC 2.5% on added revenue (C31)
A14: Vessel — Management fee: $4,000/mo → 4% of revenue (C30) · rent waived (C31=0%) · NEW 5% admin fee on F&B billed to clients → Other Operating Income (C32)
A15: LW — Programming: 2x/month activations assumed to sustain ~$500/wk of traffic ALREADY included in the revenue base (no incremental revenue modeled)
A16: LW — Cleanup levers (v23): food COGS → 40% of food sales · G&A-unc → 4.5% of revenue · discounts & comps → 2.5% of gross · retail COGS → 42% (LW Assumptions C51–C53, Retail Plan col D)
A18: AUG–DEC 2026 — IMMEDIATE IMPACT OF THE CHANGES (8/1 go-live → year-end) | B18: Without changes | C18: With changes | D18: Impact
A19: Little Wing | B19: ='LW 2026 P&L'!Q55+'LW 2026 P&L'!S55+'LW 2026 P&L'!U55+'LW 2026 P&L'!W55+'LW 2026 P&L'!Y55 | C19: ='LW 2026 Modified'!Q62+'LW 2026 Modified'!S62+'LW 2026 Modified'!U62+'LW 2026 Modified'!W62+'LW 2026 Modified'!Y62 | D19: =C19-B19
A20: Vessel | B20: ='Vessel 2026 P&L'!Q55+'Vessel 2026 P&L'!S55+'Vessel 2026 P&L'!U55+'Vessel 2026 P&L'!W55+'Vessel 2026 P&L'!Y55 | C20: ='Vessel 2026 Modified'!Q62+'Vessel 2026 Modified'!S62+'Vessel 2026 Modified'!U62+'Vessel 2026 Modified'!W62+'Vessel 2026 Modified'!Y62 | D20: =C20-B20
A21: COMBINED | B21: =B19+B20 | C21: =C19+C20 | D21: =C21-B21

Sheet Consolidated P&L
A1: Method Terrapin
A2: Consolidated Profit & Loss — FY 2027
A3: 2027
C5: Vessel | F5: Little Wing | I5: Consolidated
C6: FY 2027 | F6: FY 2027 | I6: FY 2027
C7: Amount $ | D7: % | F7: Amount $ | G7: % | I7: Amount $ | J7: %
A11: Income
A12: Food Sales | C12: ='Vessel Budget'!$AB$12 | D12: =IFERROR(C12/C$20,0) | F12: ='LW Budget'!$AB$12 | G12: =IFERROR(F12/F$20,0) | I12: =C12+F12 | J12: =IFERROR(I12/I$20,0)
A13: Non-Alcoholic Beverage Sales | C13: ='Vessel Budget'!$AB$13 | D13: =IFERROR(C13/C$20,0) | F13: ='LW Budget'!$AB$13 | G13: =IFERROR(F13/F$20,0) | I13: =C13+F13 | J13: =IFERROR(I13/I$20,0)
A14: Liquor Sales | C14: ='Vessel Budget'!$AB$14 | D14: =IFERROR(C14/C$20,0) | F14: ='LW Budget'!$AB$14 | G14: =IFERROR(F14/F$20,0) | I14: =C14+F14 | J14: =IFERROR(I14/I$20,0)
A15: Beer Sales | C15: ='Vessel Budget'!$AB$15 | D15: =IFERROR(C15/C$20,0) | F15: ='LW Budget'!$AB$15 | G15: =IFERROR(F15/F$20,0) | I15: =C15+F15 | J15: =IFERROR(I15/I$20,0)
A16: Wine Sales | C16: ='Vessel Budget'!$AB$16 | D16: =IFERROR(C16/C$20,0) | F16: ='LW Budget'!$AB$16 | G16: =IFERROR(F16/F$20,0) | I16: =C16+F16 | J16: =IFERROR(I16/I$20,0)
A17: Retail / Merch Sales | C17: ='Vessel Budget'!$AB$17 | D17: =IFERROR(C17/C$20,0) | F17: ='LW Budget'!$AB$17 | G17: =IFERROR(F17/F$20,0) | I17: =C17+F17 | J17: =IFERROR(I17/I$20,0)
A18: Other Operating Income | C18: ='Vessel Budget'!$AB$18 | D18: =IFERROR(C18/C$20,0) | F18: ='LW Budget'!$AB$18 | G18: =IFERROR(F18/F$20,0) | I18: =C18+F18 | J18: =IFERROR(I18/I$20,0)
A19: Discounts & Comps | C19: ='Vessel Budget'!$AB$19 | D19: =IFERROR(C19/C$20,0) | F19: ='LW Budget'!$AB$19 | G19: =IFERROR(F19/F$20,0) | I19: =C19+F19 | J19: =IFERROR(I19/I$20,0)
A20: Total Income | C20: ='Vessel Budget'!$AB$20 | D20: =IFERROR(C20/C$20,0) | F20: ='LW Budget'!$AB$20 | G20: =IFERROR(F20/F$20,0) | I20: =C20+F20 | J20: =IFERROR(I20/I$20,0)
A22: Cost of Goods Sold
A23: Food Cost | C23: ='Vessel Budget'!$AB$23 | D23: =IFERROR(C23/C$12,0) | F23: ='LW Budget'!$AB$23 | G23: =IFERROR(F23/F$12,0) | I23: =C23+F23 | J23: =IFERROR(I23/I$12,0)
A24: Non-Alcoholic Beverage Cost | C24: ='Vessel Budget'!$AB$24 | D24: =IFERROR(C24/C$13,0) | F24: ='LW Budget'!$AB$24 | G24: =IFERROR(F24/F$13,0) | I24: =C24+F24 | J24: =IFERROR(I24/I$13,0)
A25: Liquor Cost | C25: ='Vessel Budget'!$AB$25 | D25: =IFERROR(C25/C$14,0) | F25: ='LW Budget'!$AB$25 | G25: =IFERROR(F25/F$14,0) | I25: =C25+F25 | J25: =IFERROR(I25/I$14,0)
A26: Beer Cost | C26: ='Vessel Budget'!$AB$26 | D26: =IFERROR(C26/C$15,0) | F26: ='LW Budget'!$AB$26 | G26: =IFERROR(F26/F$15,0) | I26: =C26+F26 | J26: =IFERROR(I26/I$15,0)
A27: Wine/Sake Cost | C27: ='Vessel Budget'!$AB$27 | D27: =IFERROR(C27/C$16,0) | F27: ='LW Budget'!$AB$27 | G27: =IFERROR(F27/F$16,0) | I27: =C27+F27 | J27: =IFERROR(I27/I$16,0)
A28: Retail Cost | C28: ='Vessel Budget'!$AB$28 | D28: =IFERROR(C28/C$17,0) | F28: ='LW Budget'!$AB$28 | G28: =IFERROR(F28/F$17,0) | I28: =C28+F28 | J28: =IFERROR(I28/I$17,0)
A29: Total COGS | C29: ='Vessel Budget'!$AB$29 | D29: =IFERROR(C29/C$20,0) | F29: ='LW Budget'!$AB$29 | G29: =IFERROR(F29/F$20,0) | I29: =C29+F29 | J29: =IFERROR(I29/I$20,0)
A30: Gross Profit | C30: ='Vessel Budget'!$AB$30 | D30: =IFERROR(C30/C$20,0) | F30: ='LW Budget'!$AB$30 | G30: =IFERROR(F30/F$20,0) | I30: =C30+F30 | J30: =IFERROR(I30/I$20,0)
A32: Labor Cost
A33: Management Labor | C33: ='Vessel Budget'!$AB$33 | D33: =IFERROR(C33/C$20,0) | F33: ='LW Budget'!$AB$33 | G33: =IFERROR(F33/F$20,0) | I33: =C33+F33 | J33: =IFERROR(I33/I$20,0)
A34: Back of House Hourly Labor | C34: ='Vessel Budget'!$AB$34 | D34: =IFERROR(C34/C$20,0) | F34: ='LW Budget'!$AB$34 | G34: =IFERROR(F34/F$20,0) | I34: =C34+F34 | J34: =IFERROR(I34/I$20,0)
A35: Front of House Hourly Labor | C35: ='Vessel Budget'!$AB$35 | D35: =IFERROR(C35/C$20,0) | F35: ='LW Budget'!$AB$35 | G35: =IFERROR(F35/F$20,0) | I35: =C35+F35 | J35: =IFERROR(I35/I$20,0)
A36: Payroll Taxes & Benefits | C36: ='Vessel Budget'!$AB$36 | D36: =IFERROR(C36/C$20,0) | F36: ='LW Budget'!$AB$36 | G36: =IFERROR(F36/F$20,0) | I36: =C36+F36 | J36: =IFERROR(I36/I$20,0)
A37: Bonus | C37: ='Vessel Budget'!$AB$37 | D37: =IFERROR(C37/C$20,0) | F37: ='LW Budget'!$AB$37 | G37: =IFERROR(F37/F$20,0) | I37: =C37+F37 | J37: =IFERROR(I37/I$20,0)
A38: Total Labor Cost | C38: ='Vessel Budget'!$AB$38 | D38: =IFERROR(C38/C$20,0) | F38: ='LW Budget'!$AB$38 | G38: =IFERROR(F38/F$20,0) | I38: =C38+F38 | J38: =IFERROR(I38/I$20,0)
A40: Prime Costs | C40: ='Vessel Budget'!$AB$40 | D40: =IFERROR(C40/C$20,0) | F40: ='LW Budget'!$AB$40 | G40: =IFERROR(F40/F$20,0) | I40: =C40+F40 | J40: =IFERROR(I40/I$20,0)
A41: Operating Profit | C41: ='Vessel Budget'!$AB$41 | D41: =IFERROR(C41/C$20,0) | F41: ='LW Budget'!$AB$41 | G41: =IFERROR(F41/F$20,0) | I41: =C41+F41 | J41: =IFERROR(I41/I$20,0)
A43: Controllable Expenses
A44: Operating Expenses | C44: ='Vessel Budget'!$AB$44 | D44: =IFERROR(C44/C$20,0) | F44: ='LW Budget'!$AB$44 | G44: =IFERROR(F44/F$20,0) | I44: =C44+F44 | J44: =IFERROR(I44/I$20,0)
A45: Music & Entertainment | C45: ='Vessel Budget'!$AB$45 | D45: =IFERROR(C45/C$20,0) | F45: ='LW Budget'!$AB$45 | G45: =IFERROR(F45/F$20,0) | I45: =C45+F45 | J45: =IFERROR(I45/I$20,0)
A46: Marketing & Advertising | C46: ='Vessel Budget'!$AB$46 | D46: =IFERROR(C46/C$20,0) | F46: ='LW Budget'!$AB$46 | G46: =IFERROR(F46/F$20,0) | I46: =C46+F46 | J46: =IFERROR(I46/I$20,0)
A47: General & Administrative - Controllable | C47: ='Vessel Budget'!$AB$47 | D47: =IFERROR(C47/C$20,0) | F47: ='LW Budget'!$AB$47 | G47: =IFERROR(F47/F$20,0) | I47: =C47+F47 | J47: =IFERROR(I47/I$20,0)
A48: Repairs & Maintenance | C48: ='Vessel Budget'!$AB$48 | D48: =IFERROR(C48/C$20,0) | F48: ='LW Budget'!$AB$48 | G48: =IFERROR(F48/F$20,0) | I48: =C48+F48 | J48: =IFERROR(I48/I$20,0)
...

Sheet Combined 12-Mo P&L
A1: Method Terrapin — Combined
A2: Profit & Loss Budget — Vessel + Little Wing
A3: 2027
C5: January | E5: February | G5: March | I5: April | K5: May | M5: June | O5: July | Q5: August | S5: September | U5: October | W5: November | Y5: December | AB5: 2027
C6: Budget | E6: Budget | G6: Budget | I6: Budget | K6: Budget | M6: Budget | O6: Budget | Q6: Budget | S6: Budget | U6: Budget | W6: Budget | Y6: Budget | AB6: FY 2027
C7: Amount $ | D7: % | E7: Amount $ | F7: % | G7: Amount $ | H7: % | I7: Amount $ | J7: % | K7: Amount $ | L7: % | M7: Amount $ | N7: % | O7: Amount $ | P7: % | Q7: Amount $ | R7: % | S7: Amount $ | T7: % | U7: Amount $ | V7: % | W7: Amount $ | X7: % | Y7: Amount $ | Z7: % | AB7: Amount $ | AC7: %
A8: Events (Vessel, budgeted) | C8: ='Vessel Budget'!C9 | E8: ='Vessel Budget'!E9 | G8: ='Vessel Budget'!G9 | I8: ='Vessel Budget'!I9 | K8: ='Vessel Budget'!K9 | M8: ='Vessel Budget'!M9 | O8: ='Vessel Budget'!O9 | Q8: ='Vessel Budget'!Q9 | S8: ='Vessel Budget'!S9 | U8: ='Vessel Budget'!U9 | W8: ='Vessel Budget'!W9 | Y8: ='Vessel Budget'!Y9
A11: Income
A12: Food Sales | C12: ='Vessel Budget'!C12+'LW Budget'!C12 | D12: =IFERROR(C12/C$20,0) | E12: ='Vessel Budget'!E12+'LW Budget'!E12 | F12: =IFERROR(E12/E$20,0) | G12: ='Vessel Budget'!G12+'LW Budget'!G12 | H12: =IFERROR(G12/G$20,0) | I12: ='Vessel Budget'!I12+'LW Budget'!I12 | J12: =IFERROR(I12/I$20,0) | K12: ='Vessel Budget'!K12+'LW Budget'!K12 | L12: =IFERROR(K12/K$20,0) | M12: ='Vessel Budget'!M12+'LW Budget'!M12 | N12: =IFERROR(M12/M$20,0) | O12: ='Vessel Budget'!O12+'LW Budget'!O12 | P12: =IFERROR(O12/O$20,0) | Q12: ='Vessel Budget'!Q12+'LW Budget'!Q12 | R12: =IFERROR(Q12/Q$20,0) | S12: ='Vessel Budget'!S12+'LW Budget'!S12 | T12: =IFERROR(S12/S$20,0) | U12: ='Vessel Budget'!U12+'LW Budget'!U12 | V12: =IFERROR(U12/U$20,0) | W12: ='Vessel Budget'!W12+'LW Budget'!W12 | X12: =IFERROR(W12/W$20,0) | Y12: ='Vessel Budget'!Y12+'LW Budget'!Y12 | Z12: =IFERROR(Y12/Y$20,0) | AB12: =SUM(C12,E12,G12,I12,K12,M12,O12,Q12,S12,U12,W12,Y12) | AC12: =IFERROR(AB12/AB$20,0)
A13: Non-Alcoholic Beverage Sales | C13: ='Vessel Budget'!C13+'LW Budget'!C13 | D13: =IFERROR(C13/C$20,0) | E13: ='Vessel Budget'!E13+'LW Budget'!E13 | F13: =IFERROR(E13/E$20,0) | G13: ='Vessel Budget'!G13+'LW Budget'!G13 | H13: =IFERROR(G13/G$20,0) | I13: ='Vessel Budget'!I13+'LW Budget'!I13 | J13: =IFERROR(I13/I$20,0) | K13: ='Vessel Budget'!K13+'LW Budget'!K13 | L13: =IFERROR(K13/K$20,0) | M13: ='Vessel Budget'!M13+'LW Budget'!M13 | N13: =IFERROR(M13/M$20,0) | O13: ='Vessel Budget'!O13+'LW Budget'!O13 | P13: =IFERROR(O13/O$20,0) | Q13: ='Vessel Budget'!Q13+'LW Budget'!Q13 | R13: =IFERROR(Q13/Q$20,0) | S13: ='Vessel Budget'!S13+'LW Budget'!S13 | T13: =IFERROR(S13/S$20,0) | U13: ='Vessel Budget'!U13+'LW Budget'!U13 | V13: =IFERROR(U13/U$20,0) | W13: ='Vessel Budget'!W13+'LW Budget'!W13 | X13: =IFERROR(W13/W$20,0) | Y13: ='Vessel Budget'!Y13+'LW Budget'!Y13 | Z13: =IFERROR(Y13/Y$20,0) | AB13: =SUM(C13,E13,G13,I13,K13,M13,O13,Q13,S13,U13,W13,Y13) | AC13: =IFERROR(AB13/AB$20,0)
A14: Liquor Sales | C14: ='Vessel Budget'!C14+'LW Budget'!C14 | D14: =IFERROR(C14/C$20,0) | E14: ='Vessel Budget'!E14+'LW Budget'!E14 | F14: =IFERROR(E14/E$20,0) | G14: ='Vessel Budget'!G14+'LW Budget'!G14 | H14: =IFERROR(G14/G$20,0) | I14: ='Vessel Budget'!I14+'LW Budget'!I14 | J14: =IFERROR(I14/I$20,0) | K14: ='Vessel Budget'!K14+'LW Budget'!K14 | L14: =IFERROR(K14/K$20,0) | M14: ='Vessel Budget'!M14+'LW Budget'!M14 | N14: =IFERROR(M14/M$20,0) | O14: ='Vessel Budget'!O14+'LW Budget'!O14 | P14: =IFERROR(O14/O$20,0) | Q14: ='Vessel Budget'!Q14+'LW Budget'!Q14 | R14: =IFERROR(Q14/Q$20,0) | S14: ='Vessel Budget'!S14+'LW Budget'!S14 | T14: =IFERROR(S14/S$20,0) | U14: ='Vessel Budget'!U14+'LW Budget'!U14 | V14: =IFERROR(U14/U$20,0) | W14: ='Vessel Budget'!W14+'LW Budget'!W14 | X14: =IFERROR(W14/W$20,0) | Y14: ='Vessel Budget'!Y14+'LW Budget'!Y14 | Z14: =IFERROR(Y14/Y$20,0) | AB14: =SUM(C14,E14,G14,I14,K14,M14,O14,Q14,S14,U14,W14,Y14) | AC14: =IFERROR(AB14/AB$20,0)
A15: Beer Sales | C15: ='Vessel Budget'!C15+'LW Budget'!C15 | D15: =IFERROR(C15/C$20,0) | E15: ='Vessel Budget'!E15+'LW Budget'!E15 | F15: =IFERROR(E15/E$20,0) | G15: ='Vessel Budget'!G15+'LW Budget'!G15 | H15: =IFERROR(G15/G$20,0) | I15: ='Vessel Budget'!I15+'LW Budget'!I15 | J15: =IFERROR(I15/I$20,0) | K15: ='Vessel Budget'!K15+'LW Budget'!K15 | L15: =IFERROR(K15/K$20,0) | M15: ='Vessel Budget'!M15+'LW Budget'!M15 | N15: =IFERROR(M15/M$20,0) | O15: ='Vessel Budget'!O15+'LW Budget'!O15 | P15: =IFERROR(O15/O$20,0) | Q15: ='Vessel Budget'!Q15+'LW Budget'!Q15 | R15: =IFERROR(Q15/Q$20,0) | S15: ='Vessel Budget'!S15+'LW Budget'!S15 | T15: =IFERROR(S15/S$20,0) | U15: ='Vessel Budget'!U15+'LW Budget'!U15 | V15: =IFERROR(U15/U$20,0) | W15: ='Vessel Budget'!W15+'LW Budget'!W15 | X15: =IFERROR(W15/W$20,0) | Y15: ='Vessel Budget'!Y15+'LW Budget'!Y15 | Z15: =IFERROR(Y15/Y$20,0) | AB15: =SUM(C15,E15,G15,I15,K15,M15,O15,Q15,S15,U15,W15,Y15) | AC15: =IFERROR(AB15/AB$20,0)
A16: Wine Sales | C16: ='Vessel Budget'!C16+'LW Budget'!C16 | D16: =IFERROR(C16/C$20,0) | E16: ='Vessel Budget'!E16+'LW Budget'!E16 | F16: =IFERROR(E16/E$20,0) | G16: ='Vessel Budget'!G16+'LW Budget'!G16 | H16: =IFERROR(G16/G$20,0) | I16: ='Vessel Budget'!I16+'LW Budget'!I16 | J16: =IFERROR(I16/I$20,0) | K16: ='Vessel Budget'!K16+'LW Budget'!K16 | L16: =IFERROR(K16/K$20,0) | M16: ='Vessel Budget'!M16+'LW Budget'!M16 | N16: =IFERROR(M16/M$20,0) | O16: ='Vessel Budget'!O16+'LW Budget'!O16 | P16: =IFERROR(O16/O$20,0) | Q16: ='Vessel Budget'!Q16+'LW Budget'!Q16 | R16: =IFERROR(Q16/Q$20,0) | S16: ='Vessel Budget'!S16+'LW Budget'!S16 | T16: =IFERROR(S16/S$20,0) | U16: ='Vessel Budget'!U16+'LW Budget'!U16 | V16: =IFERROR(U16/U$20,0) | W16: ='Vessel Budget'!W16+'LW Budget'!W16 | X16: =IFERROR(W16/W$20,0) | Y16: ='Vessel Budget'!Y16+'LW Budget'!Y16 | Z16: =IFERROR(Y16/Y$20,0) | AB16: =SUM(C16,E16,G16,I16,K16,M16,O16,Q16,S16,U16,W16,Y16) | AC16: =IFERROR(AB16/AB$20,0)
A17: Retail / Merch Sales | C17: ='Vessel Budget'!C17+'LW Budget'!C17 | D17: =IFERROR(C17/C$20,0) | E17: ='Vessel Budget'!E17+'LW Budget'!E17 | F17: =IFERROR(E17/E$20,0) | G17: ='Vessel Budget'!G17+'LW Budget'!G17 | H17: =IFERROR(G17/G$20,0) | I17: ='Vessel Budget'!I17+'LW Budget'!I17 | J17: =IFERROR(I17/I$20,0) | K17: ='Vessel Budget'!K17+'LW Budget'!K17 | L17: =IFERROR(K17/K$20,0) | M17: ='Vessel Budget'!M17+'LW Budget'!M17 | N17: =IFERROR(M17/M$20,0) | O17: ='Vessel Budget'!O17+'LW Budget'!O17 | P17: =IFERROR(O17/O$20,0) | Q17: ='Vessel Budget'!Q17+'LW Budget'!Q17 | R17: =IFERROR(Q17/Q$20,0) | S17: ='Vessel Budget'!S17+'LW Budget'!S17 | T17: =IFERROR(S17/S$20,0) | U17: ='Vessel Budget'!U17+'LW Budget'!U17 | V17: =IFERROR(U17/U$20,0) | W17: ='Vessel Budget'!W17+'LW Budget'!W17 | X17: =IFERROR(W17/W$20,0) | Y17: ='Vessel Budget'!Y17+'LW Budget'!Y17 | Z17: =IFERROR(Y17/Y$20,0) | AB17: =SUM(C17,E17,G17,I17,K17,M17,O17,Q17,S17,U17,W17,Y17) | AC17: =IFERROR(AB17/AB$20,0)
A18: Other Operating Income | C18: ='Vessel Budget'!C18+'LW Budget'!C18 | D18: =IFERROR(C18/C$20,0) | E18: ='Vessel Budget'!E18+'LW Budget'!E18 | F18: =IFERROR(E18/E$20,0) | G18: ='Vessel Budget'!G18+'LW Budget'!G18 | H18: =IFERROR(G18/G$20,0) | I18: ='Vessel Budget'!I18+'LW Budget'!I18 | J18: =IFERROR(I18/I$20,0) | K18: ='Vessel Budget'!K18+'LW Budget'!K18 | L18: =IFERROR(K18/K$20,0) | M18: ='Vessel Budget'!M18+'LW Budget'!M18 | N18: =IFERROR(M18/M$20,0) | O18: ='Vessel Budget'!O18+'LW Budget'!O18 | P18: =IFERROR(O18/O$20,0) | Q18: ='Vessel Budget'!Q18+'LW Budget'!Q18 | R18: =IFERROR(Q18/Q$20,0) | S18: ='Vessel Budget'!S18+'LW Budget'!S18 | T18: =IFERROR(S18/S$20,0) | U18: ='Vessel Budget'!U18+'LW Budget'!U18 | V18: =IFERROR(U18/U$20,0) | W18: ='Vessel Budget'!W18+'LW Budget'!W18 | X18: =IFERROR(W18/W$20,0) | Y18: ='Vessel Budget'!Y18+'LW Budget'!Y18 | Z18: =IFERROR(Y18/Y$20,0) | AB18: =SUM(C18,E18,G18,I18,K18,M18,O18,Q18,S18,U18,W18,Y18) | AC18: =IFERROR(AB18/AB$20,0)
A19: Discounts & Comps | C19: ='Vessel Budget'!C19+'LW Budget'!C19 | D19: =IFERROR(C19/C$20,0) | E19: ='Vessel Budget'!E19+'LW Budget'!E19 | F19: =IFERROR(E19/E$20,0) | G19: ='Vessel Budget'!G19+'LW Budget'!G19 | H19: =IFERROR(G19/G$20,0) | I19: ='Vessel Budget'!I19+'LW Budget'!I19 | J19: =IFERROR(I19/I$20,0) | K19: ='Vessel Budget'!K19+'LW Budget'!K19 | L19: =IFERROR(K19/K$20,0) | M19: ='Vessel Budget'!M19+'LW Budget'!M19 | N19: =IFERROR(M19/M$20,0) | O19: ='Vessel Budget'!O19+'LW Budget'!O19 | P19: =IFERROR(O19/O$20,0) | Q19: ='Vessel Budget'!Q19+'LW Budget'!Q19 | R19: =IFERROR(Q19/Q$20,0) | S19: ='Vessel Budget'!S19+'LW Budget'!S19 | T19: =IFERROR(S19/S$20,0) | U19: ='Vessel Budget'!U19+'LW Budget'!U19 | V19: =IFERROR(U19/U$20,0) | W19: ='Vessel Budget'!W19+'LW Budget'!W19 | X19: =IFERROR(W19/W$20,0) | Y19: ='Vessel Budget'!Y19+'LW Budget'!Y19 | Z19: =IFERROR(Y19/Y$20,0) | AB19: =SUM(C19,E19,G19,I19,K19,M19,O19,Q19,S19,U19,W19,Y19) | AC19: =IFERROR(AB19/AB$20,0)
A20: Total Income | C20: =SUM(C12:C19) | D20: =IFERROR(C20/C$20,0) | E20: =SUM(E12:E19) | F20: =IFERROR(E20/E$20,0) | G20: =SUM(G12:G19) | H20: =IFERROR(G20/G$20,0) | I20: =SUM(I12:I19) | J20: =IFERROR(I20/I$20,0) | K20: =SUM(K12:K19) | L20: =IFERROR(K20/K$20,0) | M20: =SUM(M12:M19) | N20: =IFERROR(M20/M$20,0) | O20: =SUM(O12:O19) | P20: =IFERROR(O20/O$20,0) | Q20: =SUM(Q12:Q19) | R20: =IFERROR(Q20/Q$20,0) | S20: =SUM(S12:S19) | T20: =IFERROR(S20/S$20,0) | U20: =SUM(U12:U19) | V20: =IFERROR(U20/U$20,0) | W20: =SUM(W12:W19) | X20: =IFERROR(W20/W$20,0) | Y20: =SUM(Y12:Y19) | Z20: =IFERROR(Y20/Y$20,0) | AB20: =SUM(AB12:AB19) | AC20: =IFERROR(AB20/AB$20,0)
A22: Cost of Goods Sold
A23: Food Cost | C23: ='Vessel Budget'!C23+'LW Budget'!C23 | D23: =IFERROR(C23/C$12,0) | E23: ='Vessel Budget'!E23+'LW Budget'!E23 | F23: =IFERROR(E23/E$12,0) | G23: ='Vessel Budget'!G23+'LW Budget'!G23 | H23: =IFERROR(G23/G$12,0) | I23: ='Vessel Budget'!I23+'LW Budget'!I23 | J23: =IFERROR(I23/I$12,0) | K23: ='Vessel Budget'!K23+'LW Budget'!K23 | L23: =IFERROR(K23/K$12,0) | M23: ='Vessel Budget'!M23+'LW Budget'!M23 | N23: =IFERROR(M23/M$12,0) | O23: ='Vessel Budget'!O23+'LW Budget'!O23 | P23: =IFERROR(O23/O$12,0) | Q23: ='Vessel Budget'!Q23+'LW Budget'!Q23 | R23: =IFERROR(Q23/Q$12,0) | S23: ='Vessel Budget'!S23+'LW Budget'!S23 | T23: =IFERROR(S23/S$12,0) | U23: ='Vessel Budget'!U23+'LW Budget'!U23 | V23: =IFERROR(U23/U$12,0) | W23: ='Vessel Budget'!W23+'LW Budget'!W23 | X23: =IFERROR(W23/W$12,0) | Y23: ='Vessel Budget'!Y23+'LW Budget'!Y23 | Z23: =IFERROR(Y23/Y$12,0) | AB23: =SUM(C23,E23,G23,I23,K23,M23,O23,Q23,S23,U23,W23,Y23) | AC23: =IFERROR(AB23/AB$12,0)
A24: Non-Alcoholic Beverage Cost | C24: ='Vessel Budget'!C24+'LW Budget'!C24 | D24: =IFERROR(C24/C$13,0) | E24: ='Vessel Budget'!E24+'LW Budget'!E24 | F24: =IFERROR(E24/E$13,0) | G24: ='Vessel Budget'!G24+'LW Budget'!G24 | H24: =IFERROR(G24/G$13,0) | I24: ='Vessel Budget'!I24+'LW Budget'!I24 | J24: =IFERROR(I24/I$13,0) | K24: ='Vessel Budget'!K24+'LW Budget'!K24 | L24: =IFERROR(K24/K$13,0) | M24: ='Vessel Budget'!M24+'LW Budget'!M24 | N24: =IFERROR(M24/M$13,0) | O24: ='Vessel Budget'!O24+'LW Budget'!O24 | P24: =IFERROR(O24/O$13,0) | Q24: ='Vessel Budget'!Q24+'LW Budget'!Q24 | R24: =IFERROR(Q24/Q$13,0) | S24: ='Vessel Budget'!S24+'LW Budget'!S24 | T24: =IFERROR(S24/S$13,0) | U24: ='Vessel Budget'!U24+'LW Budget'!U24 | V24: =IFERROR(U24/U$13,0) | W24: ='Vessel Budget'!W24+'LW Budget'!W24 | X24: =IFERROR(W24/W$13,0) | Y24: ='Vessel Budget'!Y24+'LW Budget'!Y24 | Z24: =IFERROR(Y24/Y$13,0) | AB24: =SUM(C24,E24,G24,I24,K24,M24,O24,Q24,S24,U24,W24,Y24) | AC24: =IFERROR(AB24/AB$13,0)
A25: Liquor Cost | C25: ='Vessel Budget'!C25+'LW Budget'!C25 | D25: =IFERROR(C25/C$14,0) | E25: ='Vessel Budget'!E25+'LW Budget'!E25 | F25: =IFERROR(E25/E$14,0) | G25: ='Vessel Budget'!G25+'LW Budget'!G25 | H25: =IFERROR(G25/G$14,0) | I25: ='Vessel Budget'!I25+'LW Budget'!I25 | J25: =IFERROR(I25/I$14,0) | K25: ='Vessel Budget'!K25+'LW Budget'!K25 | L25: =IFERROR(K25/K$14,0) | M25: ='Vessel Budget'!M25+'LW Budget'!M25 | N25: =IFERROR(M25/M$14,0) | O25: ='Vessel Budget'!O25+'LW Budget'!O25 | P25: =IFERROR(O25/O$14,0) | Q25: ='Vessel Budget'!Q25+'LW Budget'!Q25 | R25: =IFERROR(Q25/Q$14,0) | S25: ='Vessel Budget'!S25+'LW Budget'!S25 | T25: =IFERROR(S25/S$14,0) | U25: ='Vessel Budget'!U25+'LW Budget'!U25 | V25: =IFERROR(U25/U$14,0) | W25: ='Vessel Budget'!W25+'LW Budget'!W25 | X25: =IFERROR(W25/W$14,0) | Y25: ='Vessel Budget'!Y25+'LW Budget'!Y25 | Z25: =IFERROR(Y25/Y$14,0) | AB25: =SUM(C25,E25,G25,I25,K25,M25,O25,Q25,S25,U25,W25,Y25) | AC25: =IFERROR(AB25/AB$14,0)
A26: Beer Cost | C26: ='Vessel Budget'!C26+'LW Budget'!C26 | D26: =IFERROR(C26/C$15,0) | E26: ='Vessel Budget'!E26+'LW Budget'!E26 | F26: =IFERROR(E26/E$15,0) | G26: ='Vessel Budget'!G26+'LW Budget'!G26 | H26: =IFERROR(G26/G$15,0) | I26: ='Vessel Budget'!I26+'LW Budget'!I26 | J26: =IFERROR(I26/I$15,0) | K26: ='Vessel Budget'!K26+'LW Budget'!K26 | L26: =IFERROR(K26/K$15,0) | M26: ='Vessel Budget'!M26+'LW Budget'!M26 | N26: =IFERROR(M26/M$15,0) | O26: ='Vessel Budget'!O26+'LW Budget'!O26 | P26: =IFERROR(O26/O$15,0) | Q26: ='Vessel Budget'!Q26+'LW Budget'!Q26 | R26: =IFERROR(Q26/Q$15,0) | S26: ='Vessel Budget'!S26+'LW Budget'!S26 | T26: =IFERROR(S26/S$15,0) | U26: ='Vessel Budget'!U26+'LW Budget'!U26 | V26: =IFERROR(U26/U$15,0) | W26: ='Vessel Budget'!W26+'LW Budget'!W26 | X26: =IFERROR(W26/W$15,0) | Y26: ='Vessel Budget'!Y26+'LW Budget'!Y26 | Z26: =IFERROR(Y26/Y$15,0) | AB26: =SUM(C26,E26,G26,I26,K26,M26,O26,Q26,S26,U26,W26,Y26) | AC26: =IFERROR(AB26/AB$15,0)
A27: Wine/Sake Cost | C27: ='Vessel Budget'!C27+'LW Budget'!C27 | D27: =IFERROR(C27/C$16,0) | E27: ='Vessel Budget'!E27+'LW Budget'!E27 | F27: =IFERROR(E27/E$16,0) | G27: ='Vessel Budget'!G27+'LW Budget'!G27 | H27: =IFERROR(G27/G$16,0) | I27: ='Vessel Budget'!I27+'LW Budget'!I27 | J27: =IFERROR(I27/I$16,0) | K27: ='Vessel Budget'!K27+'LW Budget'!K27 | L27: =IFERROR(K27/K$16,0) | M27: ='Vessel Budget'!M27+'LW Budget'!M27 | N27: =IFERROR(M27/M$16,0) | O27: ='Vessel Budget'!O27+'LW Budget'!O27 | P27: =IFERROR(O27/O$16,0) | Q27: ='Vessel Budget'!Q27+'LW Budget'!Q27 | R27: =IFERROR(Q27/Q$16,0) | S27: ='Vessel Budget'!S27+'LW Budget'!S27 | T27: =IFERROR(S27/S$16,0) | U27: ='Vessel Budget'!U27+'LW Budget'!U27 | V27: =IFERROR(U27/U$16,0) | W27: ='Vessel Budget'!W27+'LW Budget'!W27 | X27: =IFERROR(W27/W$16,0) | Y27: ='Vessel Budget'!Y27+'LW Budget'!Y27 | Z27: =IFERROR(Y27/Y$16,0) | AB27: =SUM(C27,E27,G27,I27,K27,M27,O27,Q27,S27,U27,W27,Y27) | AC27: =IFERROR(AB27/AB$16,0)
A28: Retail Cost | C28: ='Vessel Budget'!C28+'LW Budget'!C28 | D28: =IFERROR(C28/C$17,0) | E28: ='Vessel Budget'!E28+'LW Budget'!E28 | F28: =IFERROR(E28/E$17,0) | G28: ='Vessel Budget'!G28+'LW Budget'!G28 | H28: =IFERROR(G28/G$17,0) | I28: ='Vessel Budget'!I28+'LW Budget'!I28 | J28: =IFERROR(I28/I$17,0) | K28: ='Vessel Budget'!K28+'LW Budget'!K28 | L28: =IFERROR(K28/K$17,0) | M28: ='Vessel Budget'!M28+'LW Budget'!M28 | N28: =IFERROR(M28/M$17,0) | O28: ='Vessel Budget'!O28+'LW Budget'!O28 | P28: =IFERROR(O28/O$17,0) | Q28: ='Vessel Budget'!Q28+'LW Budget'!Q28 | R28: =IFERROR(Q28/Q$17,0) | S28: ='Vessel Budget'!S28+'LW Budget'!S28 | T28: =IFERROR(S28/S$17,0) | U28: ='Vessel Budget'!U28+'LW Budget'!U28 | V28: =IFERROR(U28/U$17,0) | W28: ='Vessel Budget'!W28+'LW Budget'!W28 | X28: =IFERROR(W28/W$17,0) | Y28: ='Vessel Budget'!Y28+'LW Budget'!Y28 | Z28: =IFERROR(Y28/Y$17,0) | AB28: =SUM(C28,E28,G28,I28,K28,M28,O28,Q28,S28,U28,W28,Y28) | AC28: =IFERROR(AB28/AB$17,0)
A29: Total COGS | C29: =SUM(C23:C28) | D29: =IFERROR(C29/C$20,0) | E29: =SUM(E23:E28) | F29: =IFERROR(E29/E$20,0) | G29: =SUM(G23:G28) | H29: =IFERROR(G29/G$20,0) | I29: =SUM(I23:I28) | J29: =IFERROR(I29/I$20,0) | K29: =SUM(K23:K28) | L29: =IFERROR(K29/K$20,0) | M29: =SUM(M23:M28) | N29: =IFERROR(M29/M$20,0) | O29: =SUM(O23:O28) | P29: =IFERROR(O29/O$20,0) | Q29: =SUM(Q23:Q28) | R29: =IFERROR(Q29/Q$20,0) | S29: =SUM(S23:S28) | T29: =IFERROR(S29/S$20,0) | U29: =SUM(U23:U28) | V29: =IFERROR(U29/U$20,0) | W29: =SUM(W23:W28) | X29: =IFERROR(W29/W$20,0) | Y29: =SUM(Y23:Y28) | Z29: =IFERROR(Y29/Y$20,0) | AB29: =SUM(AB23:AB28) | AC29: =IFERROR(AB29/AB$20,0)
A30: Gross Profit | C30: =C20-C29 | D30: =IFERROR(C30/C$20,0) | E30: =E20-E29 | F30: =IFERROR(E30/E$20,0) | G30: =G20-G29 | H30: =IFERROR(G30/G$20,0) | I30: =I20-I29 | J30: =IFERROR(I30/I$20,0) | K30: =K20-K29 | L30: =IFERROR(K30/K$20,0) | M30: =M20-M29 | N30: =IFERROR(M30/M$20,0) | O30: =O20-O29 | P30: =IFERROR(O30/O$20,0) | Q30: =Q20-Q29 | R30: =IFERROR(Q30/Q$20,0) | S30: =S20-S29 | T30: =IFERROR(S30/S$20,0) | U30: =U20-U29 | V30: =IFERROR(U30/U$20,0) | W30: =W20-W29 | X30: =IFERROR(W30/W$20,0) | Y30: =Y20-Y29 | Z30: =IFERROR(Y30/Y$20,0) | AB30: =AB20-AB29 | AC30: =IFERROR(AB30/AB$20,0)
A32: Labor Cost
A33: Management Labor | C33: ='Vessel Budget'!C33+'LW Budget'!C33 | D33: =IFERROR(C33/C$20,0) | E33: ='Vessel Budget'!E33+'LW Budget'!E33 | F33: =IFERROR(E33/E$20,0) | G33: ='Vessel Budget'!G33+'LW Budget'!G33 | H33: =IFERROR(G33/G$20,0) | I33: ='Vessel Budget'!I33+'LW Budget'!I33 | J33: =IFERROR(I33/I$20,0) | K33: ='Vessel Budget'!K33+'LW Budget'!K33 | L33: =IFERROR(K33/K$20,0) | M33: ='Vessel Budget'!M33+'LW Budget'!M33 | N33: =IFERROR(M33/M$20,0) | O33: ='Vessel Budget'!O33+'LW Budget'!O33 | P33: =IFERROR(O33/O$20,0) | Q33: ='Vessel Budget'!Q33+'LW Budget'!Q33 | R33: =IFERROR(Q33/Q$20,0) | S33: ='Vessel Budget'!S33+'LW Budget'!S33 | T33: =IFERROR(S33/S$20,0) | U33: ='Vessel Budget'!U33+'LW Budget'!U33 | V33: =IFERROR(U33/U$20,0) | W33: ='Vessel Budget'!W33+'LW Budget'!W33 | X33: =IFERROR(W33/W$20,0) | Y33: ='Vessel Budget'!Y33+'LW Budget'!Y33 | Z33: =IFERROR(Y33/Y$20,0) | AB33: =SUM(C33,E33,G33,I33,K33,M33,O33,Q33,S33,U33,W33,Y33) | AC33: =IFERROR(AB33/AB$20,0)
A34: Back of House Hourly Labor | C34: ='Vessel Budget'!C34+'LW Budget'!C34 | D34: =IFERROR(C34/C$20,0) | E34: ='Vessel Budget'!E34+'LW Budget'!E34 | F34: =IFERROR(E34/E$20,0) | G34: ='Vessel Budget'!G34+'LW Budget'!G34 | H34: =IFERROR(G34/G$20,0) | I34: ='Vessel Budget'!I34+'LW Budget'!I34 | J34: =IFERROR(I34/I$20,0) | K34: ='Vessel Budget'!K34+'LW Budget'!K34 | L34: =IFERROR(K34/K$20,0) | M34: ='Vessel Budget'!M34+'LW Budget'!M34 | N34: =IFERROR(M34/M$20,0) | O34: ='Vessel Budget'!O34+'LW Budget'!O34 | P34: =IFERROR(O34/O$20,0) | Q34: ='Vessel Budget'!Q34+'LW Budget'!Q34 | R34: =IFERROR(Q34/Q$20,0) | S34: ='Vessel Budget'!S34+'LW Budget'!S34 | T34: =IFERROR(S34/S$20,0) | U34: ='Vessel Budget'!U34+'LW Budget'!U34 | V34: =IFERROR(U34/U$20,0) | W34: ='Vessel Budget'!W34+'LW Budget'!W34 | X34: =IFERROR(W34/W$20,0) | Y34: ='Vessel Budget'!Y34+'LW Budget'!Y34 | Z34: =IFERROR(Y34/Y$20,0) | AB34: =SUM(C34,E34,G34,I34,K34,M34,O34,Q34,S34,U34,W34,Y34) | AC34: =IFERROR(AB34/AB$20,0)
A35: Front of House Hourly Labor | C35: ='Vessel Budget'!C35+'LW Budget'!C35 | D35: =IFERROR(C35/C$20,0) | E35: ='Vessel Budget'!E35+'LW Budget'!E35 | F35: =IFERROR(E35/E$20,0) | G35: ='Vessel Budget'!G35+'LW Budget'!G35 | H35: =IFERROR(G35/G$20,0) | I35: ='Vessel Budget'!I35+'LW Budget'!I35 | J35: =IFERROR(I35/I$20,0) | K35: ='Vessel Budget'!K35+'LW Budget'!K35 | L35: =IFERROR(K35/K$20,0) | M35: ='Vessel Budget'!M35+'LW Budget'!M35 | N35: =IFERROR(M35/M$20,0) | O35: ='Vessel Budget'!O35+'LW Budget'!O35 | P35: =IFERROR(O35/O$20,0) | Q35: ='Vessel Budget'!Q35+'LW Budget'!Q35 | R35: =IFERROR(Q35/Q$20,0) | S35: ='Vessel Budget'!S35+'LW Budget'!S35 | T35: =IFERROR(S35/S$20,0) | U35: ='Vessel Budget'!U35+'LW Budget'!U35 | V35: =IFERROR(U35/U$20,0) | W35: ='Vessel Budget'!W35+'LW Budget'!W35 | X35: =IFERROR(W35/W$20,0) | Y35: ='Vessel Budget'!Y35+'LW Budget'!Y35 | Z35: =IFERROR(Y35/Y$20,0) | AB35: =SUM(C35,E35,G35,I35,K35,M35,O35,Q35,S35,U35,W35,Y35) | AC35: =IFERROR(AB35/AB$20,0)
A36: Payroll Taxes & Benefits | C36: ='Vessel Budget'!C36+'LW Budget'!C36 | D36: =IFERROR(C36/C$20,0) | E36: ='Vessel Budget'!E36+'LW Budget'!E36 | F36: =IFERROR(E36/E$20,0) | G36: ='Vessel Budget'!G36+'LW Budget'!G36 | H36: =IFERROR(G36/G$20,0) | I36: ='Vessel Budget'!I36+'LW Budget'!I36 | J36: =IFERROR(I36/I$20,0) | K36: ='Vessel Budget'!K36+'LW Budget'!K36 | L36: =IFERROR(K36/K$20,0) | M36: ='Vessel Budget'!M36+'LW Budget'!M36 | N36: =IFERROR(M36/M$20,0) | O36: ='Vessel Budget'!O36+'LW Budget'!O36 | P36: =IFERROR(O36/O$20,0) | Q36: ='Vessel Budget'!Q36+'LW Budget'!Q36 | R36: =IFERROR(Q36/Q$20,0) | S36: ='Vessel Budget'!S36+'LW Budget'!S36 | T36: =IFERROR(S36/S$20,0) | U36: ='Vessel Budget'!U36+'LW Budget'!U36 | V36: =IFERROR(U36/U$20,0) | W36: ='Vessel Budget'!W36+'LW Budget'!W36 | X36: =IFERROR(W36/W$20,0) | Y36: ='Vessel Budget'!Y36+'LW Budget'!Y36 | Z36: =IFERROR(Y36/Y$20,0) | AB36: =SUM(C36,E36,G36,I36,K36,M36,O36,Q36,S36,U36,W36,Y36) | AC36: =IFERROR(AB36/AB$20,0)
A37: Bonus | C37: ='Vessel Budget'!C37+'LW Budget'!C37 | D37: =IFERROR(C37/C$20,0) | E37: ='Vessel Budget'!E37+'LW Budget'!E37 | F37: =IFERROR(E37/E$20,0) | G37: ='Vessel Budget'!G37+'LW Budget'!G37 | H37: =IFERROR(G37/G$20,0) | I37: ='Vessel Budget'!I37+'LW Budget'!I37 | J37: =IFERROR(I37/I$20,0) | K37: ='Vessel Budget'!K37+'LW Budget'!K37 | L37: =IFERROR(K37/K$20,0) | M37: ='Vessel Budget'!M37+'LW Budget'!M37 | N37: =IFERROR(M37/M$20,0) | O37: ='Vessel Budget'!O37+'LW Budget'!O37 | P37: =IFERROR(O37/O$20,0) | Q37: ='Vessel Budget'!Q37+'LW Budget'!Q37 | R37: =IFERROR(Q37/Q$20,0) | S37: ='Vessel Budget'!S37+'LW Budget'!S37 | T37: =IFERROR(S37/S$20,0) | U37: ='Vessel Budget'!U37+'LW Budget'!U37 | V37: =IFERROR(U37/U$20,0) | W37: ='Vessel Budget'!W37+'LW Budget'!W37 | X37: =IFERROR(W37/W$20,0) | Y37: ='Vessel Budget'!Y37+'LW Budget'!Y37 | Z37: =IFERROR(Y37/Y$20,0) | AB37: =SUM(C37,E37,G37,I37,K37,M37,O37,Q37,S37,U37,W37,Y37) | AC37: =IFERROR(AB37/AB$20,0)
A38: Total Labor Cost | C38: =SUM(C33:C37) | D38: =IFERROR(C38/C$20,0) | E38: =SUM(E33:E37) | F38: =IFERROR(E38/E$20,0) | G38: =SUM(G33:G37) | H38: =IFERROR(G38/G$20,0) | I38: =SUM(I33:I37) | J38: =IFERROR(I38/I$20,0) | K38: =SUM(K33:K37) | L38: =IFERROR(K38/K$20,0) | M38: =SUM(M33:M37) | N38: =IFERROR(M38/M$20,0) | O38: =SUM(O33:O37) | P38: =IFERROR(O38/O$20,0) | Q38: =SUM(Q33:Q37) | R38: =IFERROR(Q38/Q$20,0) | S38: =SUM(S33:S37) | T38: =IFERROR(S38/S$20,0) | U38: =SUM(U33:U37) | V38: =IFERROR(U38/U$20,0) | W38: =SUM(W33:W37) | X38: =IFERROR(W38/W$20,0) | Y38: =SUM(Y33:Y37) | Z38: =IFERROR(Y38/Y$20,0) | AB38: =SUM(AB33:AB37) | AC38: =IFERROR(AB38/AB$20,0)
A40: Prime Costs | C40: =C29+C38 | D40: =IFERROR(C40/C$20,0) | E40: =E29+E38 | F40: =IFERROR(E40/E$20,0) | G40: =G29+G38 | H40: =IFERROR(G40/G$20,0) | I40: =I29+I38 | J40: =IFERROR(I40/I$20,0) | K40: =K29+K38 | L40: =IFERROR(K40/K$20,0) | M40: =M29+M38 | N40: =IFERROR(M40/M$20,0) | O40: =O29+O38 | P40: =IFERROR(O40/O$20,0) | Q40: =Q29+Q38 | R40: =IFERROR(Q40/Q$20,0) | S40: =S29+S38 | T40: =IFERROR(S40/S$20,0) | U40: =U29+U38 | V40: =IFERROR(U40/U$20,0) | W40: =W29+W38 | X40: =IFERROR(W40/W$20,0) | Y40: =Y29+Y38 | Z40: =IFERROR(Y40/Y$20,0) | AB40: =AB29+AB38 | AC40: =IFERROR(AB40/AB$20,0)
A41: Operating Profit | C41: =C30-C38 | D41: =IFERROR(C41/C$20,0) | E41: =E30-E38 | F41: =IFERROR(E41/E$20,0) | G41: =G30-G38 | H41: =IFERROR(G41/G$20,0) | I41: =I30-I38 | J41: =IFERROR(I41/I$20,0) | K41: =K30-K38 | L41: =IFERROR(K41/K$20,0) | M41: =M30-M38 | N41: =IFERROR(M41/M$20,0) | O41: =O30-O38 | P41: =IFERROR(O41/O$20,0) | Q41: =Q30-Q38 | R41: =IFERROR(Q41/Q$20,0) | S41: =S30-S38 | T41: =IFERROR(S41/S$20,0) | U41: =U30-U38 | V41: =IFERROR(U41/U$20,0) | W41: =W30-W38 | X41: =IFERROR(W41/W$20,0) | Y41: =Y30-Y38 | Z41: =IFERROR(Y41/Y$20,0) | AB41: =AB30-AB38 | AC41: =IFERROR(AB41/AB$20,0)
A43: Controllable Expenses
A44: Operating Expenses | C44: ='Vessel Budget'!C44+'LW Budget'!C44 | D44: =IFERROR(C44/C$20,0) | E44: ='Vessel Budget'!E44+'LW Budget'!E44 | F44: =IFERROR(E44/E$20,0) | G44: ='Vessel Budget'!G44+'LW Budget'!G44 | H44: =IFERROR(G44/G$20,0) | I44: ='Vessel Budget'!I44+'LW Budget'!I44 | J44: =IFERROR(I44/I$20,0) | K44: ='Vessel Budget'!K44+'LW Budget'!K44 | L44: =IFERROR(K44/K$20,0) | M44: ='Vessel Budget'!M44+'LW Budget'!M44 | N44: =IFERROR(M44/M$20,0) | O44: ='Vessel Budget'!O44+'LW Budget'!O44 | P44: =IFERROR(O44/O$20,0) | Q44: ='Vessel Budget'!Q44+'LW Budget'!Q44 | R44: =IFERROR(Q44/Q$20,0) | S44: ='Vessel Budget'!S44+'LW Budget'!S44 | T44: =IFERROR(S44/S$20,0) | U44: ='Vessel Budget'!U44+'LW Budget'!U44 | V44: =IFERROR(U44/U$20,0) | W44: ='Vessel Budget'!W44+'LW Budget'!W44 | X44: =IFERROR(W44/W$20,0) | Y44: ='Vessel Budget'!Y44+'LW Budget'!Y44 | Z44: =IFERROR(Y44/Y$20,0) | AB44: =SUM(C44,E44,G44,I44,K44,M44,O44,Q44,S44,U44,W44,Y44) | AC44: =IFERROR(AB44/AB$20,0)
A45: Music & Entertainment | C45: ='Vessel Budget'!C45+'LW Budget'!C45 | D45: =IFERROR(C45/C$20,0) | E45: ='Vessel Budget'!E45+'LW Budget'!E45 | F45: =IFERROR(E45/E$20,0) | G45: ='Vessel Budget'!G45+'LW Budget'!G45 | H45: =IFERROR(G45/G$20,0) | I45: ='Vessel Budget'!I45+'LW Budget'!I45 | J45: =IFERROR(I45/I$20,0) | K45: ='Vessel Budget'!K45+'LW Budget'!K45 | L45: =IFERROR(K45/K$20,0) | M45: ='Vessel Budget'!M45+'LW Budget'!M45 | N45: =IFERROR(M45/M$20,0) | O45: ='Vessel Budget'!O45+'LW Budget'!O45 | P45: =IFERROR(O45/O$20,0) | Q45: ='Vessel Budget'!Q45+'LW Budget'!Q45 | R45: =IFERROR(Q45/Q$20,0) | S45: ='Vessel Budget'!S45+'LW Budget'!S45 | T45: =IFERROR(S45/S$20,0) | U45: ='Vessel Budget'!U45+'LW Budget'!U45 | V45: =IFERROR(U45/U$20,0) | W45: ='Vessel Budget'!W45+'LW Budget'!W45 | X45: =IFERROR(W45/W$20,0) | Y45: ='Vessel Budget'!Y45+'LW Budget'!Y45 | Z45: =IFERROR(Y45/Y$20,0) | AB45: =SUM(C45,E45,G45,I45,K45,M45,O45,Q45,S45,U45,W45,Y45) | AC45: =IFERROR(AB45/AB$20,0)
A46: Marketing & Advertising | C46: ='Vessel Budget'!C46+'LW Budget'!C46 | D46: =IFERROR(C46/C$20,0) | E46: ='Vessel Budget'!E46+'LW Budget'!E46 | F46: =IFERROR(E46/E$20,0) | G46: ='Vessel Budget'!G46+'LW Budget'!G46 | H46: =IFERROR(G46/G$20,0) | I46: ='Vessel Budget'!I46+'LW Budget'!I46 | J46: =IFERROR(I46/I$20,0) | K46: ='Vessel Budget'!K46+'LW Budget'!K46 | L46: =IFERROR(K46/K$20,0) | M46: ='Vessel Budget'!M46+'LW Budget'!M46 | N46: =IFERROR(M46/M$20,0) | O46: ='Vessel Budget'!O46+'LW Budget'!O46 | P46: =IFERROR(O46/O$20,0) | Q46: ='Vessel Budget'!Q46+'LW Budget'!Q46 | R46: =IFERROR(Q46/Q$20,0) | S46: ='Vessel Budget'!S46+'LW Budget'!S46 | T46: =IFERROR(S46/S$20,0) | U46: ='Vessel Budget'!U46+'LW Budget'!U46 | V46: =IFERROR(U46/U$20,0) | W46: ='Vessel Budget'!W46+'LW Budget'!W46 | X46: =IFERROR(W46/W$20,0) | Y46: ='Vessel Budget'!Y46+'LW Budget'!Y46 | Z46: =IFERROR(Y46/Y$20,0) | AB46: =SUM(C46,E46,G46,I46,K46,M46,O46,Q46,S46,U46,W46,Y46) | AC46: =IFERROR(AB46/AB$20,0)
A47: General & Administrative - Controllable | C47: ='Vessel Budget'!C47+'LW Budget'!C47 | D47: =IFERROR(C47/C$20,0) | E47: ='Vessel Budget'!E47+'LW Budget'!E47 | F47: =IFERROR(E47/E$20,0) | G47: ='Vessel Budget'!G47+'LW Budget'!G47 | H47: =IFERROR(G47/G$20,0) | I47: ='Vessel Budget'!I47+'LW Budget'!I47 | J47: =IFERROR(I47/I$20,0) | K47: ='Vessel Budget'!K47+'LW Budget'!K47 | L47: =IFERROR(K47/K$20,0) | M47: ='Vessel Budget'!M47+'LW Budget'!M47 | N47: =IFERROR(M47/M$20,0) | O47: ='Vessel Budget'!O47+'LW Budget'!O47 | P47: =IFERROR(O47/O$20,0) | Q47: ='Vessel Budget'!Q47+'LW Budget'!Q47 | R47: =IFERROR(Q47/Q$20,0) | S47: ='Vessel Budget'!S47+'LW Budget'!S47 | T47: =IFERROR(S47/S$20,0) | U47: ='Vessel Budget'!U47+'LW Budget'!U47 | V47: =IFERROR(U47/U$20,0) | W47: ='Vessel Budget'!W47+'LW Budget'!W47 | X47: =IFERROR(W47/W$20,0) | Y47: ='Vessel Budget'!Y47+'LW Budget'!Y47 | Z47: =IFERROR(Y47/Y$20,0) | AB47: =SUM(C47,E47,G47,I47,K47,M47,O47,Q47,S47,U47,W47,Y47) | AC47: =IFERROR(AB47/AB$20,0)
...

Sheet Vessel Summary
B2: VESSEL EVENTS — 2027 OPERATING SUMMARY
B3: ="$"&TEXT('Vessel Assumptions'!$C$6,"#,##0")&" F&B min · "&TEXT('Vessel Assumptions'!$C$7,"0%")&" volume · "&TEXT('Vessel Assumptions'!$C$30,"0%")&" mgmt fee"
B5: ANNUAL P&L | C5: $ | D5: % rev | F5: KEY METRICS
B6: Total revenue | C6: ='Vessel Budget'!$AB$20 | D6: =C6/C6 | F6: Net operating margin | G6: ='Vessel Budget'!$AB$62/'Vessel Budget'!$AB$20
B7: Total COGS | C7: ='Vessel Budget'!$AB$29 | D7: =C7/C6 | F7: Prime cost % | G7: ='Vessel Budget'!$AB$40/'Vessel Budget'!$AB$20
B8: Gross profit | C8: ='Vessel Budget'!$AB$30 | D8: =C8/C6 | F8: COGS % | G8: ='Vessel Budget'!$AB$29/'Vessel Budget'!$AB$20
B9: Total labor (incl. mgmt) | C9: ='Vessel Budget'!$AB$38 | D9: =C9/C6 | F9: Total events / year | G9: ='Vessel Budget'!$AB$9
B10: Prime cost | C10: ='Vessel Budget'!$AB$40 | D10: =C10/C6 | F10: Avg F&B / event | G10: =SUM('Vessel Budget'!$AB$12:$AB$16)/'Vessel Budget'!$AB$9
B11: Controllable (excl CC) | C11: ='Vessel Budget'!$AB$50-'Vessel Budget'!$AB$49 | D11: =C11/C6 | F11: Revenue / event | G11: ='Vessel Budget'!$AB$20/'Vessel Budget'!$AB$9
B12: Credit card fees (2.5%) | C12: ='Vessel Budget'!$AB$49 | D12: =C12/C6
B13: Non-controllable | C13: ='Vessel Budget'!$AB$60-'Vessel Budget'!$AB$54-'Vessel Budget'!$AB$56-'Vessel Budget'!$AB$57 | D13: =C13/C6
B14: Management fee (4% of revenue) | C14: ='Vessel Budget'!$AB$56 | D14: =C14/C6
B15: Admin fee income (5% of F&B, billed to clients) | C15: =SUM('Vessel Budget'!$AB$12:$AB$16)*'Vessel Assumptions'!$C$32 | D15: =C15/C6
B16: Rent / occupancy (none) | C16: ='Vessel Budget'!$AB$54 | D16: =C16/C6
B17: NET OPERATING PROFIT | C17: ='Vessel Budget'!$AB$62 | D17: =C17/C6
B20: Adjust inputs on the Vessel Assumptions tab — every figure recalculates. Management fee = 4% of revenue; no separate rent.

Sheet Vessel Assumptions
B2: VESSEL · EVENT OPERATING MODEL
B3: Model drivers — adjust any input and the 2027 budget recalculates
B5: REVENUE DRIVERS
B6: F&B minimum per event | C6: 3720 | D6: per-event F&B realized (card: food $2,880 + bev $840; $4,000 contract minimum)
B7: Event volume (% of run-rate) | C7: 0.8 | D7: =TEXT($C$7,"0%")&" of Jan–May run-rate"
B8: Food share of F&B | C8: =2880/3720 | D8: food share per the 2027 unit-economics card
B9: Service charge (% of F&B) | C9: 0.2 | D9: revenue, not billed labor
B11: COST OF SALES (% of that category's sales)
B12: Food cost % (of food sales) | C12: =1600/2880 | D12: food cost per card: $1,600 on $2,880 (55.6%)
B13: Beverage cost % (of bev sales) | C13: 0.25 | D13: =TEXT(1-$C$13,"0%")&" margin"
B15: LABOR
B16: Bartenders per event | C16: 1
B17: Servers per event | C17: 2
B18: Hourly rate | C18: 35
B19: Shift hours | C19: 5
B20: Hourly labor per event (calc) | C20: =(C16+C17)*C18*C19
B21: Management labor / month | C21: ='Vessel GL Basis'!D8 | D21: linked ← Vessel GL Basis
B22: Payroll taxes & benefits % | C22: =114/692 | D22: PT&B per card: $114 on $692 of wages (hourly+manager+bonus)
B24: OVERHEAD & VARIABLE
B25: Controllable exp / month (excl CC) | C25: ='Vessel GL Basis'!D18 | D25: linked ← Vessel GL Basis
B26: Non-controllable / month | C26: ='Vessel GL Basis'!D24 | D26: linked ← Vessel GL Basis
B27: Credit card fee (% of revenue) | C27: 0.025 | D27: variable — own line
B29: OWNER CHARGES (above NOI) & ADMIN FEE INCOME
B30: Management fee (% of revenue) — EXPENSE | C30: 0.04 | D30: 4% of gross revenue → Method (replaces profit split)
B31: Rent (% of revenue) — EXPENSE (waived) | C31: 0 | D31: Vessel carries no separate rent (owner)
B32: Admin fee (% of F&B) — INCOME, billed to clients | C32: 0.05 | D32: 5% added to event client invoices → Vessel Other Operating Income (NOT an expense); 4% mgmt fee applies to it as revenue
B34: Operating expenses (% of revenue — modified/plan) | C34: 0.03 | D34: target ratio, replaces GL run-rate in modified months & 2027
B35: G&A controllable (% of revenue — modified/plan) | C35: 0.04 | D35: target ratio (GL runs ~11%) — the accounting/bank cleanup
B36: Manager labor $/event | C36: 55 | D36: 2027 unit-economics card
B37: Bonus $/event | C37: 112 | D37: 2027 unit-economics card
B38: Controllable expenses (% of revenue — 2027 card) | C38: =575/4650 | D38: $575/event incl CC fees
B39: Uncontrollable (% of revenue — 2027 card) | C39: =116/4650 | D39: $116/event

Sheet Vessel Budget
A1: Vessel
A2: Profit & Loss Budget
A3: 2027
C5: January | E5: February | G5: March | I5: April | K5: May | M5: June | O5: July | Q5: August | S5: September | U5: October | W5: November | Y5: December | AB5: 2027
C6: Budget | E6: Budget | G6: Budget | I6: Budget | K6: Budget | M6: Budget | O6: Budget | Q6: Budget | S6: Budget | U6: Budget | W6: Budget | Y6: Budget | AB6: FY 2027
C7: Amount $ | D7: % | E7: Amount $ | F7: % | G7: Amount $ | H7: % | I7: Amount $ | J7: % | K7: Amount $ | L7: % | M7: Amount $ | N7: % | O7: Amount $ | P7: % | Q7: Amount $ | R7: % | S7: Amount $ | T7: % | U7: Amount $ | V7: % | W7: Amount $ | X7: % | Y7: Amount $ | Z7: % | AB7: Amount $ | AC7: %
A8: Events (2026 run-rate) | C8: 13 | E8: 4 | G8: 13 | I8: 4 | K8: 10 | M8: =AVERAGE($C$8,$E$8,$G$8,$I$8,$K$8) | O8: =AVERAGE($C$8,$E$8,$G$8,$I$8,$K$8) | Q8: =AVERAGE($C$8,$E$8,$G$8,$I$8,$K$8) | S8: =AVERAGE($C$8,$E$8,$G$8,$I$8,$K$8) | U8: =AVERAGE($C$8,$E$8,$G$8,$I$8,$K$8) | W8: =AVERAGE($C$8,$E$8,$G$8,$I$8,$K$8) | Y8: =AVERAGE($C$8,$E$8,$G$8,$I$8,$K$8) | AB8: =SUM(C8,E8,G8,I8,K8,M8,O8,Q8,S8,U8,W8,Y8)
A9: Events (budgeted, whole) | C9: =ROUND(C8*'Vessel Assumptions'!$C$7,0) | E9: =ROUND(E8*'Vessel Assumptions'!$C$7,0) | G9: =ROUND(G8*'Vessel Assumptions'!$C$7,0) | I9: =ROUND(I8*'Vessel Assumptions'!$C$7,0) | K9: =ROUND(K8*'Vessel Assumptions'!$C$7,0) | M9: =ROUND(M8*'Vessel Assumptions'!$C$7,0) | O9: =ROUND(O8*'Vessel Assumptions'!$C$7,0) | Q9: =ROUND(Q8*'Vessel Assumptions'!$C$7,0) | S9: =ROUND(S8*'Vessel Assumptions'!$C$7,0) | U9: =ROUND(U8*'Vessel Assumptions'!$C$7,0) | W9: =ROUND(W8*'Vessel Assumptions'!$C$7,0) | Y9: =ROUND(Y8*'Vessel Assumptions'!$C$7,0) | AB9: =SUM(C9,E9,G9,I9,K9,M9,O9,Q9,S9,U9,W9,Y9)
A11: Income
A12: Food Sales | C12: =C9*'Vessel Assumptions'!$C$6*'Vessel Assumptions'!$C$8 | D12: =IFERROR(C12/C$20,0) | E12: =E9*'Vessel Assumptions'!$C$6*'Vessel Assumptions'!$C$8 | F12: =IFERROR(E12/E$20,0) | G12: =G9*'Vessel Assumptions'!$C$6*'Vessel Assumptions'!$C$8 | H12: =IFERROR(G12/G$20,0) | I12: =I9*'Vessel Assumptions'!$C$6*'Vessel Assumptions'!$C$8 | J12: =IFERROR(I12/I$20,0) | K12: =K9*'Vessel Assumptions'!$C$6*'Vessel Assumptions'!$C$8 | L12: =IFERROR(K12/K$20,0) | M12: =M9*'Vessel Assumptions'!$C$6*'Vessel Assumptions'!$C$8 | N12: =IFERROR(M12/M$20,0) | O12: =O9*'Vessel Assumptions'!$C$6*'Vessel Assumptions'!$C$8 | P12: =IFERROR(O12/O$20,0) | Q12: =Q9*'Vessel Assumptions'!$C$6*'Vessel Assumptions'!$C$8 | R12: =IFERROR(Q12/Q$20,0) | S12: =S9*'Vessel Assumptions'!$C$6*'Vessel Assumptions'!$C$8 | T12: =IFERROR(S12/S$20,0) | U12: =U9*'Vessel Assumptions'!$C$6*'Vessel Assumptions'!$C$8 | V12: =IFERROR(U12/U$20,0) | W12: =W9*'Vessel Assumptions'!$C$6*'Vessel Assumptions'!$C$8 | X12: =IFERROR(W12/W$20,0) | Y12: =Y9*'Vessel Assumptions'!$C$6*'Vessel Assumptions'!$C$8 | Z12: =IFERROR(Y12/Y$20,0) | AB12: =SUM(C12,E12,G12,I12,K12,M12,O12,Q12,S12,U12,W12,Y12) | AC12: =IFERROR(AB12/AB$20,0)
A13: Non-Alcoholic Beverage Sales | C13: =(C9*'Vessel Assumptions'!$C$6*(1-'Vessel Assumptions'!$C$8))*'Vessel 2026 P&L'!$AB$10/SUM('Vessel 2026 P&L'!$AB$10:$AB$13) | D13: =IFERROR(C13/C$20,0) | E13: =(E9*'Vessel Assumptions'!$C$6*(1-'Vessel Assumptions'!$C$8))*'Vessel 2026 P&L'!$AB$10/SUM('Vessel 2026 P&L'!$AB$10:$AB$13) | F13: =IFERROR(E13/E$20,0) | G13: =(G9*'Vessel Assumptions'!$C$6*(1-'Vessel Assumptions'!$C$8))*'Vessel 2026 P&L'!$AB$10/SUM('Vessel 2026 P&L'!$AB$10:$AB$13) | H13: =IFERROR(G13/G$20,0) | I13: =(I9*'Vessel Assumptions'!$C$6*(1-'Vessel Assumptions'!$C$8))*'Vessel 2026 P&L'!$AB$10/SUM('Vessel 2026 P&L'!$AB$10:$AB$13) | J13: =IFERROR(I13/I$20,0) | K13: =(K9*'Vessel Assumptions'!$C$6*(1-'Vessel Assumptions'!$C$8))*'Vessel 2026 P&L'!$AB$10/SUM('Vessel 2026 P&L'!$AB$10:$AB$13) | L13: =IFERROR(K13/K$20,0) | M13: =(M9*'Vessel Assumptions'!$C$6*(1-'Vessel Assumptions'!$C$8))*'Vessel 2026 P&L'!$AB$10/SUM('Vessel 2026 P&L'!$AB$10:$AB$13) | N13: =IFERROR(M13/M$20,0) | O13: =(O9*'Vessel Assumptions'!$C$6*(1-'Vessel Assumptions'!$C$8))*'Vessel 2026 P&L'!$AB$10/SUM('Vessel 2026 P&L'!$AB$10:$AB$13) | P13: =IFERROR(O13/O$20,0) | Q13: =(Q9*'Vessel Assumptions'!$C$6*(1-'Vessel Assumptions'!$C$8))*'Vessel 2026 P&L'!$AB$10/SUM('Vessel 2026 P&L'!$AB$10:$AB$13) | R13: =IFERROR(Q13/Q$20,0) | S13: =(S9*'Vessel Assumptions'!$C$6*(1-'Vessel Assumptions'!$C$8))*'Vessel 2026 P&L'!$AB$10/SUM('Vessel 2026 P&L'!$AB$10:$AB$13) | T13: =IFERROR(S13/S$20,0) | U13: =(U9*'Vessel Assumptions'!$C$6*(1-'Vessel Assumptions'!$C$8))*'Vessel 2026 P&L'!$AB$10/SUM('Vessel 2026 P&L'!$AB$10:$AB$13) | V13: =IFERROR(U13/U$20,0) | W13: =(W9*'Vessel Assumptions'!$C$6*(1-'Vessel Assumptions'!$C$8))*'Vessel 2026 P&L'!$AB$10/SUM('Vessel 2026 P&L'!$AB$10:$AB$13) | X13: =IFERROR(W13/W$20,0) | Y13: =(Y9*'Vessel Assumptions'!$C$6*(1-'Vessel Assumptions'!$C$8))*'Vessel 2026 P&L'!$AB$10/SUM('Vessel 2026 P&L'!$AB$10:$AB$13) | Z13: =IFERROR(Y13/Y$20,0) | AB13: =SUM(C13,E13,G13,I13,K13,M13,O13,Q13,S13,U13,W13,Y13) | AC13: =IFERROR(AB13/AB$20,0)
A14: Liquor Sales | C14: =(C9*'Vessel Assumptions'!$C$6*(1-'Vessel Assumptions'!$C$8))*'Vessel 2026 P&L'!$AB$11/SUM('Vessel 2026 P&L'!$AB$10:$AB$13) | D14: =IFERROR(C14/C$20,0) | E14: =(E9*'Vessel Assumptions'!$C$6*(1-'Vessel Assumptions'!$C$8))*'Vessel 2026 P&L'!$AB$11/SUM('Vessel 2026 P&L'!$AB$10:$AB$13) | F14: =IFERROR(E14/E$20,0) | G14: =(G9*'Vessel Assumptions'!$C$6*(1-'Vessel Assumptions'!$C$8))*'Vessel 2026 P&L'!$AB$11/SUM('Vessel 2026 P&L'!$AB$10:$AB$13) | H14: =IFERROR(G14/G$20,0) | I14: =(I9*'Vessel Assumptions'!$C$6*(1-'Vessel Assumptions'!$C$8))*'Vessel 2026 P&L'!$AB$11/SUM('Vessel 2026 P&L'!$AB$10:$AB$13) | J14: =IFERROR(I14/I$20,0) | K14: =(K9*'Vessel Assumptions'!$C$6*(1-'Vessel Assumptions'!$C$8))*'Vessel 2026 P&L'!$AB$11/SUM('Vessel 2026 P&L'!$AB$10:$AB$13) | L14: =IFERROR(K14/K$20,0) | M14: =(M9*'Vessel Assumptions'!$C$6*(1-'Vessel Assumptions'!$C$8))*'Vessel 2026 P&L'!$AB$11/SUM('Vessel 2026 P&L'!$AB$10:$AB$13) | N14: =IFERROR(M14/M$20,0) | O14: =(O9*'Vessel Assumptions'!$C$6*(1-'Vessel Assumptions'!$C$8))*'Vessel 2026 P&L'!$AB$11/SUM('Vessel 2026 P&L'!$AB$10:$AB$13) | P14: =IFERROR(O14/O$20,0) | Q14: =(Q9*'Vessel Assumptions'!$C$6*(1-'Vessel Assumptions'!$C$8))*'Vessel 2026 P&L'!$AB$11/SUM('Vessel 2026 P&L'!$AB$10:$AB$13) | R14: =IFERROR(Q14/Q$20,0) | S14: =(S9*'Vessel Assumptions'!$C$6*(1-'Vessel Assumptions'!$C$8))*'Vessel 2026 P&L'!$AB$11/SUM('Vessel 2026 P&L'!$AB$10:$AB$13) | T14: =IFERROR(S14/S$20,0) | U14: =(U9*'Vessel Assumptions'!$C$6*(1-'Vessel Assumptions'!$C$8))*'Vessel 2026 P&L'!$AB$11/SUM('Vessel 2026 P&L'!$AB$10:$AB$13) | V14: =IFERROR(U14/U$20,0) | W14: =(W9*'Vessel Assumptions'!$C$6*(1-'Vessel Assumptions'!$C$8))*'Vessel 2026 P&L'!$AB$11/SUM('Vessel 2026 P&L'!$AB$10:$AB$13) | X14: =IFERROR(W14/W$20,0) | Y14: =(Y9*'Vessel Assumptions'!$C$6*(1-'Vessel Assumptions'!$C$8))*'Vessel 2026 P&L'!$AB$11/SUM('Vessel 2026 P&L'!$AB$10:$AB$13) | Z14: =IFERROR(Y14/Y$20,0) | AB14: =SUM(C14,E14,G14,I14,K14,M14,O14,Q14,S14,U14,W14,Y14) | AC14: =IFERROR(AB14/AB$20,0)
A15: Beer Sales | C15: =(C9*'Vessel Assumptions'!$C$6*(1-'Vessel Assumptions'!$C$8))*'Vessel 2026 P&L'!$AB$12/SUM('Vessel 2026 P&L'!$AB$10:$AB$13) | D15: =IFERROR(C15/C$20,0) | E15: =(E9*'Vessel Assumptions'!$C$6*(1-'Vessel Assumptions'!$C$8))*'Vessel 2026 P&L'!$AB$12/SUM('Vessel 2026 P&L'!$AB$10:$AB$13) | F15: =IFERROR(E15/E$20,0) | G15: =(G9*'Vessel Assumptions'!$C$6*(1-'Vessel Assumptions'!$C$8))*'Vessel 2026 P&L'!$AB$12/SUM('Vessel 2026 P&L'!$AB$10:$AB$13) | H15: =IFERROR(G15/G$20,0) | I15: =(I9*'Vessel Assumptions'!$C$6*(1-'Vessel Assumptions'!$C$8))*'Vessel 2026 P&L'!$AB$12/SUM('Vessel 2026 P&L'!$AB$10:$AB$13) | J15: =IFERROR(I15/I$20,0) | K15: =(K9*'Vessel Assumptions'!$C$6*(1-'Vessel Assumptions'!$C$8))*'Vessel 2026 P&L'!$AB$12/SUM('Vessel 2026 P&L'!$AB$10:$AB$13) | L15: =IFERROR(K15/K$20,0) | M15: =(M9*'Vessel Assumptions'!$C$6*(1-'Vessel Assumptions'!$C$8))*'Vessel 2026 P&L'!$AB$12/SUM('Vessel 2026 P&L'!$AB$10:$AB$13) | N15: =IFERROR(M15/M$20,0) | O15: =(O9*'Vessel Assumptions'!$C$6*(1-'Vessel Assumptions'!$C$8))*'Vessel 2026 P&L'!$AB$12/SUM('Vessel 2026 P&L'!$AB$10:$AB$13) | P15: =IFERROR(O15/O$20,0) | Q15: =(Q9*'Vessel Assumptions'!$C$6*(1-'Vessel Assumptions'!$C$8))*'Vessel 2026 P&L'!$AB$12/SUM('Vessel 2026 P&L'!$AB$10:$AB$13) | R15: =IFERROR(Q15/Q$20,0) | S15: =(S9*'Vessel Assumptions'!$C$6*(1-'Vessel Assumptions'!$C$8))*'Vessel 2026 P&L'!$AB$12/SUM('Vessel 2026 P&L'!$AB$10:$AB$13) | T15: =IFERROR(S15/S$20,0) | U15: =(U9*'Vessel Assumptions'!$C$6*(1-'Vessel Assumptions'!$C$8))*'Vessel 2026 P&L'!$AB$12/SUM('Vessel 2026 P&L'!$AB$10:$AB$13) | V15: =IFERROR(U15/U$20,0) | W15: =(W9*'Vessel Assumptions'!$C$6*(1-'Vessel Assumptions'!$C$8))*'Vessel 2026 P&L'!$AB$12/SUM('Vessel 2026 P&L'!$AB$10:$AB$13) | X15: =IFERROR(W15/W$20,0) | Y15: =(Y9*'Vessel Assumptions'!$C$6*(1-'Vessel Assumptions'!$C$8))*'Vessel 2026 P&L'!$AB$12/SUM('Vessel 2026 P&L'!$AB$10:$AB$13) | Z15: =IFERROR(Y15/Y$20,0) | AB15: =SUM(C15,E15,G15,I15,K15,M15,O15,Q15,S15,U15,W15,Y15) | AC15: =IFERROR(AB15/AB$20,0)
