Workbook

Sheet Scenario Summary
A1: METHOD TERRAPIN — SCENARIO SUMMARY
A2: T12 (GL actual) · 2026 Forecast (status quo) · 2026 Modified (changes from Aug 1 go-live, see 2026 Bridge) · 2027 Plan · blue = external actuals
A4: LITTLE WING
B5: T12 (GL actual) | C5: 2026 Forecast | D5: 2026 Modified | E5: 2027 Plan
A6: Revenue | B6: 258287 | C6: 287305 | D6: =287305+'2026 Bridge'!$D$7*'LW Assumptions'!$C$43+'2026 Bridge'!$D$8*'LW Assumptions'!$C$47 -> 295862.55 | E6: ='LW Budget'!$Z$11 -> 286740.15
A7: Cost of goods sold | B7: 81599 | C7: 99691 | D7: =99691 -> 99691 | E7: ='LW Budget'!$Z$18 -> 80932.346
A8: GROSS PROFIT | B8: =B6-B7 -> 176688 | C8: =C6-C7 -> 187614 | D8: =D6-D7 -> 196171.55 | E8: =E6-E7 -> 205807.8
A9: Labor | B9: 164857 | C9: 168162 | D9: =168162-'2026 Bridge'!$D$6*(168162-'LW Assumptions'!$C$25) -> 137302.5 | E9: ='LW Budget'!$Z$21 -> 94099.2
A10: Operating expenses (excl fees & rent) | B10: 105344 | C10: 112209 | D10: =112209+'LW Assumptions'!$C$31*('2026 Bridge'!$D$7*'LW Assumptions'!$C$43+'2026 Bridge'!$D$8*'LW Assumptions'!$C$47) -> 112422.94 | E10: ='LW Budget'!$Z$22+'LW Budget'!$Z$23+'LW Budget'!$Z$24 -> 102500.5
A11: Management fee | B11: 48000 | C11: 48000 | D11: =48000-'2026 Bridge'!$D$9*(48000-'LW Assumptions'!$C$40*(287305+'LW Assumptions'!$C$43+'LW Assumptions'!$C$47)) -> 33130.719 | E11: ='LW Budget'!$Z$25 -> 11469.606
A12: Admin fee (Vessel 5% of F&B) | B12: 0 | C12: 0 | D12: =0 -> 0 | E12: =0 -> 0
A13: Rent / occupancy | B13: 15642 | C13: 17299 | D13: ='LW Assumptions'!$C$41*(287305+'2026 Bridge'!$D$7*'LW Assumptions'!$C$43+'2026 Bridge'!$D$8*'LW Assumptions'!$C$47) -> 17751.753 | E13: ='LW Budget'!$Z$26 -> 17204.409
A14: NET OPERATING INCOME | B14: =B6-B7-B9-B10-B11-B12-B13 -> -157155 | C14: =C6-C7-C9-C10-C11-C12-C13 -> -158056 | D14: =D6-D7-D9-D10-D11-D12-D13 -> -104436.36 | E14: =E6-E7-E9-E10-E11-E12-E13 -> -19465.915
A15: NOI margin | B15: =B14/B6 -> -0.60845106 | C15: =C14/C6 -> -0.55013313 | D15: =D14/D6 -> -0.35298944 | E15: =E14/E6 -> -0.067886953
A17: VESSEL
B18: T12 (GL actual) | C18: 2026 Forecast | D18: 2026 Modified | E18: 2027 Plan
A19: Revenue | B19: 344171 | C19: 344171 | D19: =344171 -> 344171 | E19: ='Vessel Budget'!$Z$10 -> 398400
A20: Cost of goods sold | B20: 116784 | C20: 116784 | D20: =116784 -> 116784 | E20: ='Vessel Budget'!$Z$14 -> 170033.8
A21: GROSS PROFIT | B21: =B19-B20 -> 227387 | C21: =C19-C20 -> 227387 | D21: =D19-D20 -> 227387 | E21: =E19-E20 -> 228366.2
A22: Labor | B22: 75138 | C22: 75138 | D22: =75138 -> 75138 | E22: ='Vessel Budget'!$Z$20 -> 67062.843
A23: Operating expenses (excl fees & rent) | B23: 95684 | C23: 95684 | D23: =95684 -> 95684 | E23: ='Vessel Budget'!$Z$24+'Vessel Budget'!$Z$23+'Vessel Budget'!$Z$25 -> 99581
A24: Management fee | B24: 48000 | C24: 48000 | D24: =48000-'2026 Bridge'!$D$10*(48000-'Vessel Assumptions'!$C$30*344171) -> 33736.183 | E24: ='Vessel Budget'!$Z$26 -> 15936
A25: Admin fee (Vessel 5% of F&B) | B25: 0 | C25: 0 | D25: ='2026 Bridge'!$D$12*'Vessel Assumptions'!$C$32*230063 -> 4792.9792 | E25: ='Vessel Budget'!$Z$27 -> 16600
A26: Rent / occupancy | B26: 20874 | C26: 20874 | D26: =20874-'2026 Bridge'!$D$11*(20874-0) -> 12176.5 | E26: ='Vessel Budget'!$Z$28 -> 0
A27: NET OPERATING INCOME | B27: =B19-B20-B22-B23-B24-B25-B26 -> -12309 | C27: =C19-C20-C22-C23-C24-C25-C26 -> -12309 | D27: =D19-D20-D22-D23-D24-D25-D26 -> 5859.3375 | E27: =E19-E20-E22-E23-E24-E25-E26 -> 29186.357
A28: NOI margin | B28: =B27/B19 -> -0.035764199 | C28: =C27/C19 -> -0.035764199 | D28: =D27/D19 -> 0.017024495 | E28: =E27/E19 -> 0.073258928
A30: COMBINED
B31: T12 (GL actual) | C31: 2026 Forecast | D31: 2026 Modified | E31: 2027 Plan
A32: Revenue | B32: =B6+B19 -> 602458 | C32: =C6+C19 -> 631476 | D32: =D6+D19 -> 640033.55 | E32: =E6+E19 -> 685140.15
A33: Cost of goods sold | B33: =B7+B20 -> 198383 | C33: =C7+C20 -> 216475 | D33: =D7+D20 -> 216475 | E33: =E7+E20 -> 250966.15
A34: GROSS PROFIT | B34: =B32-B33 -> 404075 | C34: =C32-C33 -> 415001 | D34: =D32-D33 -> 423558.55 | E34: =E32-E33 -> 434174
A35: Labor | B35: =B9+B22 -> 239995 | C35: =C9+C22 -> 243300 | D35: =D9+D22 -> 212440.5 | E35: =E9+E22 -> 161162.04
A36: Operating expenses (excl fees & rent) | B36: =B10+B23 -> 201028 | C36: =C10+C23 -> 207893 | D36: =D10+D23 -> 208106.94 | E36: =E10+E23 -> 202081.5
A37: Management fee | B37: =B11+B24 -> 96000 | C37: =C11+C24 -> 96000 | D37: =D11+D24 -> 66866.902 | E37: =E11+E24 -> 27405.606
A38: Admin fee (Vessel 5% of F&B) | B38: =B12+B25 -> 0 | C38: =C12+C25 -> 0 | D38: =D12+D25 -> 4792.9792 | E38: =E12+E25 -> 16600
A39: Rent / occupancy | B39: =B13+B26 -> 36516 | C39: =C13+C26 -> 38173 | D39: =D13+D26 -> 29928.253 | E39: =E13+E26 -> 17204.409
A40: NET OPERATING INCOME | B40: =B32-B33-B35-B36-B37-B38-B39 -> -169464 | C40: =C32-C33-C35-C36-C37-C38-C39 -> -170365 | D40: =D32-D33-D35-D36-D37-D38-D39 -> -98577.019 | E40: =E32-E33-E35-E36-E37-E38-E39 -> 9720.4419
A41: NOI margin | B41: =B40/B32 -> -0.28128766 | C41: =C40/C32 -> -0.26978856 | D41: =D40/D32 -> -0.15401852 | E41: =E40/E32 -> 0.014187523
A43: Vessel T12 seeded with 2026 actual/forecast. Admin fee = 5% of F&B (food+bev); did not exist in T12/Forecast. 2026 Modified = changes live from Aug 1, 2026 (edit dates on 2026 Bridge).

Sheet 2026 Bridge
A1: 2026 MODIFIED — TIME-STAMPED CHANGE BRIDGE
A2: Each change has an effective date (blue = editable). 2026 impact = full-year Δ × months live in 2026 ÷ 12. Base = 2026 status-quo forecast.
A5: Change | B5: Effective date | C5: Months live 2026 | D5: Proration | E5: Full-year Δ NOI | F5: 2026 Δ NOI
A6: Little Wing — Labor restructure (6a–4p, wknd 4h 2nd barista) | B6: 46235 | C6: =MAX(0,13-MONTH(B6)) -> 5 | D6: =C6/12 -> 0.41666667 | E6: =168162-'LW Assumptions'!$C$25 -> 74062.8 | F6: =E6*D6 -> 30859.5
A7: Little Wing — Menu pricing uplift (PMIX) | B7: 46235 | C7: =MAX(0,13-MONTH(B7)) -> 5 | D7: =C7/12 -> 0.41666667 | E7: ='LW Assumptions'!$C$43*(1-'LW Assumptions'!$C$31-'LW Assumptions'!$C$41) -> 16117.13 | F7: =E7*D7 -> 6715.4709
A8: Little Wing — Retail improvement uplift | B8: 46235 | C8: =MAX(0,13-MONTH(B8)) -> 5 | D8: =C8/12 -> 0.41666667 | E8: ='LW Assumptions'!$C$47*(1-'LW Assumptions'!$C$31-'LW Assumptions'!$C$41) -> 2675.2587 | F8: =E8*D8 -> 1114.6911
A9: Little Wing — Management fee: $48K flat → 4% of rev | B9: 46235 | C9: =MAX(0,13-MONTH(B9)) -> 5 | D9: =C9/12 -> 0.41666667 | E9: =48000-'LW Assumptions'!$C$40*(287305+'LW Assumptions'!$C$43+'LW Assumptions'!$C$47) -> 35686.275 | F9: =E9*D9 -> 14869.281
A10: Vessel — Management fee: $48K flat → 4% of rev | B10: 46235 | C10: =MAX(0,13-MONTH(B10)) -> 5 | D10: =C10/12 -> 0.41666667 | E10: =48000-'Vessel Assumptions'!$C$30*344171 -> 34233.16 | F10: =E10*D10 -> 14263.817
A11: Vessel — Rent → $0 (waived) | B11: 46235 | C11: =MAX(0,13-MONTH(B11)) -> 5 | D11: =C11/12 -> 0.41666667 | E11: =20874-0 -> 20874 | F11: =E11*D11 -> 8697.5
A12: Vessel — Admin fee: +5% of F&B revenue (new charge) | B12: 46235 | C12: =MAX(0,13-MONTH(B12)) -> 5 | D12: =C12/12 -> 0.41666667 | E12: =-'Vessel Assumptions'!$C$32*230063 -> -11503.15 | F12: =E12*D12 -> -4792.9792
A14: Little Wing — interaction / rounding (4% fee & 6% rent on added revenue) | F14: ='Scenario Summary'!$D$14-'Scenario Summary'!$C$14-(F6+F7+F8+F9) -> 60.7
A17: RECONCILIATION — 2026 NOI
A18: Little Wing — 2026 Forecast (status quo) | F18: ='Scenario Summary'!$C$14 -> -158056
A19: + Little Wing changes (2026 Δ, time-stamped) | F19: =F6+F7+F8+F9+F14 -> 53619.643
A20: Little Wing — 2026 MODIFIED | F20: ='Scenario Summary'!$D$14 -> -104436.36
A22: Vessel — 2026 Forecast (status quo) | F22: ='Scenario Summary'!$C$27 -> -12309
A23: + Vessel changes (2026 Δ, time-stamped) | F23: =F10+F11+F12 -> 18168.338
A24: Vessel — 2026 MODIFIED | F24: ='Scenario Summary'!$D$27 -> 5859.3375
A26: COMBINED — 2026 MODIFIED NOI | F26: ='Scenario Summary'!$D$40 -> -98577.019

Sheet Consolidated P&L
A1: METHOD TERRAPIN — CONSOLIDATED P&L 2027
A2: Vessel (events) + Little Wing (coffee) · FY roll-up · management fee (4%) & rent above NOI · $ and % of revenue
A4: FY 2027 | B4: Vessel | D4: Little Wing | F4: Consolidated
B5: $ | C5: % rev | D5: $ | E5: % rev | F5: $ | G5: % rev
A6: Revenue | B6: ='Vessel Budget'!$Z$10 -> 398400 | C6: =B6/$B$6 -> 1 | D6: ='LW Budget'!$Z$11 -> 286740.15 | E6: =D6/$D$6 -> 1 | F6: =B6+D6 -> 685140.15 | G6: =F6/$F$6 -> 1
A7: Cost of goods sold | B7: ='Vessel Budget'!$Z$14 -> 170033.8 | C7: =B7/$B$6 -> 0.42679167 | D7: ='LW Budget'!$Z$18 -> 80932.346 | E7: =D7/$D$6 -> 0.28224979 | F7: =B7+D7 -> 250966.15 | G7: =F7/$F$6 -> 0.36629899
A8: GROSS PROFIT | B8: =B6-B7 -> 228366.2 | C8: =B8/$B$6 -> 0.57320833 | D8: =D6-D7 -> 205807.8 | E8: =D8/$D$6 -> 0.71775021 | F8: =B8+D8 -> 434174 | G8: =F8/$F$6 -> 0.63370101
A10: Labor | B10: ='Vessel Budget'!$Z$20 -> 67062.843 | C10: =B10/$B$6 -> 0.16833043 | D10: ='LW Budget'!$Z$21 -> 94099.2 | E10: =D10/$D$6 -> 0.3281689 | F10: =B10+D10 -> 161162.04 | G10: =F10/$F$6 -> 0.23522493
A11: Credit card fees | B11: ='Vessel Budget'!$Z$24 -> 9960 | C11: =B11/$B$6 -> 0.025 | D11: ='LW Budget'!$Z$22 -> 7168.5037 | E11: =D11/$D$6 -> 0.025 | F11: =B11+D11 -> 17128.504 | G11: =F11/$F$6 -> 0.025
A12: Controllable expenses | B12: ='Vessel Budget'!$Z$23 -> 80860 | C12: =B12/$B$6 -> 0.20296185 | D12: ='LW Budget'!$Z$23 -> 89675 | E12: =D12/$D$6 -> 0.3127396 | F12: =B12+D12 -> 170535 | G12: =F12/$F$6 -> 0.24890528
A13: Non-controllable expenses | B13: ='Vessel Budget'!$Z$25 -> 8761 | C13: =B13/$B$6 -> 0.021990462 | D13: ='LW Budget'!$Z$24 -> 5657 | E13: =D13/$D$6 -> 0.019728664 | F13: =B13+D13 -> 14418 | G13: =F13/$F$6 -> 0.02104387
A14: Management fee (4% of revenue) | B14: ='Vessel Budget'!$Z$26 -> 15936 | C14: =B14/$B$6 -> 0.04 | D14: ='LW Budget'!$Z$25 -> 11469.606 | E14: =D14/$D$6 -> 0.04 | F14: =B14+D14 -> 27405.606 | G14: =F14/$F$6 -> 0.04
A15: Admin fee (Vessel 5% of F&B) | B15: ='Vessel Budget'!$Z$27 -> 16600 | C15: =B15/$B$6 -> 0.041666667 | D15: =0 -> 0 | E15: =D15/$D$6 -> 0 | F15: =B15+D15 -> 16600 | G15: =F15/$F$6 -> 0.02422862
A16: Rent (Vessel $0 / LW 6%) | B16: ='Vessel Budget'!$Z$28 -> 0 | C16: =B16/$B$6 -> 0 | D16: ='LW Budget'!$Z$26 -> 17204.409 | E16: =D16/$D$6 -> 0.06 | F16: =B16+D16 -> 17204.409 | G16: =F16/$F$6 -> 0.025110788
A17: Total operating expenses | B17: =B10+B11+B12+B13+B14+B15+B16 -> 199179.84 | C17: =B17/$B$6 -> 0.49994941 | D17: =D10+D11+D12+D13+D14+D15+D16 -> 225273.72 | E17: =D17/$D$6 -> 0.78563717 | F17: =B17+D17 -> 424453.56 | G17: =F17/$F$6 -> 0.61951348
A19: NET OPERATING INCOME (after mgmt fee, admin fee & rent) | B19: =B8-B17 -> 29186.357 | C19: =B19/$B$6 -> 0.073258928 | D19: =D8-D17 -> -19465.915 | E19: =D19/$D$6 -> -0.067886953 | F19: =B19+D19 -> 9720.4419 | G19: =F19/$F$6 -> 0.014187523
A26: CONSOLIDATED NOI BY MONTH (after mgmt fee & rent)
A27: Month | B27: Vessel | C27: Little Wing | D27: Consolidated | E27: Cumulative
A28: Jan | B28: ='Vessel Budget'!B29 -> 7457.6443 | C28: ='LW Budget'!B27 -> -5818.8858 | D28: =B28+C28 -> 1638.7586 | E28: =D28 -> 1638.7586
A29: Feb | B29: ='Vessel Budget'!D29 -> -3951.4807 | C29: ='LW Budget'!D27 -> -4313.2766 | D29: =B29+C29 -> -8264.7573 | E29: =E28+D29 -> -6625.9987
A30: Mar | B30: ='Vessel Budget'!F29 -> 7457.6443 | C30: ='LW Budget'!F27 -> 1292.745 | D30: =B30+C30 -> 8750.3894 | E30: =E29+D30 -> 2124.3907
A31: Apr | B31: ='Vessel Budget'!H29 -> -3951.4807 | C31: ='LW Budget'!H27 -> -2606.5419 | D31: =B31+C31 -> -6558.0225 | E31: =E30+D31 -> -4433.6318
A32: May | B32: ='Vessel Budget'!J29 -> 4197.8943 | C32: ='LW Budget'!J27 -> 119.98458 | D32: =B32+C32 -> 4317.8789 | E32: =E31+D32 -> -115.75293
A33: Jun | B33: ='Vessel Budget'!L29 -> 2568.0193 | C33: ='LW Budget'!L27 -> 1593.017 | D33: =B33+C33 -> 4161.0364 | E33: =E32+D33 -> 4045.2834
A34: Jul | B34: ='Vessel Budget'!N29 -> 2568.0193 | C34: ='LW Budget'!N27 -> -1622.1596 | D34: =B34+C34 -> 945.85974 | E34: =E33+D34 -> 4991.1432
A35: Aug | B35: ='Vessel Budget'!P29 -> 2568.0193 | C35: ='LW Budget'!P27 -> -1622.1596 | D35: =B35+C35 -> 945.85974 | E35: =E34+D35 -> 5937.0029
A36: Sep | B36: ='Vessel Budget'!R29 -> 2568.0193 | C36: ='LW Budget'!R27 -> -1622.1596 | D36: =B36+C36 -> 945.85974 | E36: =E35+D36 -> 6882.8627
A37: Oct | B37: ='Vessel Budget'!T29 -> 2568.0193 | C37: ='LW Budget'!T27 -> -1622.1596 | D37: =B37+C37 -> 945.85974 | E37: =E36+D37 -> 7828.7224
A38: Nov | B38: ='Vessel Budget'!V29 -> 2568.0193 | C38: ='LW Budget'!V27 -> -1622.1596 | D38: =B38+C38 -> 945.85974 | E38: =E37+D38 -> 8774.5822
A39: Dec | B39: ='Vessel Budget'!X29 -> 2568.0193 | C39: ='LW Budget'!X27 -> -1622.1596 | D39: =B39+C39 -> 945.85974 | E39: =E38+D39 -> 9720.4419
A40: FY 2027 | B40: ='Vessel Budget'!$Z$29 -> 29186.357 | C40: ='LW Budget'!$Z$27 -> -19465.915 | D40: =B40+C40 -> 9720.4419

Sheet Combined 12-Mo P&L
A1: METHOD TERRAPIN — COMBINED 12-MONTH P&L (2027 PLAN)
A2: Vessel + Little Wing · monthly · mgmt fee (4%), admin fee (Vessel 5% F&B) & rent above NOI
A4: ($) | B4: Jan | C4: Feb | D4: Mar | E4: Apr | F4: May | G4: Jun | H4: Jul | I4: Aug | J4: Sep | K4: Oct | L4: Nov | M4: Dec | N4: FY 2027
A6: Revenue | B6: ='Vessel Budget'!B10+'LW Budget'!B11 -> 64814.92 | C6: ='Vessel Budget'!D10+'LW Budget'!D11 -> 33754.96 | D6: ='Vessel Budget'!F10+'LW Budget'!F11 -> 76812.606 | E6: ='Vessel Budget'!H10+'LW Budget'!H11 -> 36634.309 | F6: ='Vessel Budget'!J10+'LW Budget'!J11 -> 65234.099 | G6: ='Vessel Budget'!L10+'LW Budget'!L11 -> 62919.18 | H6: ='Vessel Budget'!N10+'LW Budget'!N11 -> 57495.012 | I6: ='Vessel Budget'!P10+'LW Budget'!P11 -> 57495.012 | J6: ='Vessel Budget'!R10+'LW Budget'!R11 -> 57495.012 | K6: ='Vessel Budget'!T10+'LW Budget'!T11 -> 57495.012 | L6: ='Vessel Budget'!V10+'LW Budget'!V11 -> 57495.012 | M6: ='Vessel Budget'!X10+'LW Budget'!X11 -> 57495.012 | N6: ='Vessel Budget'!Z10+'LW Budget'!Z11 -> 685140.15
A7: Cost of goods sold | B7: ='Vessel Budget'!B14+'LW Budget'!B18 -> 25232.008 | C7: ='Vessel Budget'!D14+'LW Budget'!D18 -> 11608.733 | D7: ='Vessel Budget'!F14+'LW Budget'!F18 -> 28618.352 | E7: ='Vessel Budget'!H14+'LW Budget'!H18 -> 12421.429 | F7: ='Vessel Budget'!J14+'LW Budget'!J18 -> 23962.719 | G7: ='Vessel Budget'!L14+'LW Budget'!L18 -> 22615.532 | H7: ='Vessel Budget'!N14+'LW Budget'!N18 -> 21084.562 | I7: ='Vessel Budget'!P14+'LW Budget'!P18 -> 21084.562 | J7: ='Vessel Budget'!R14+'LW Budget'!R18 -> 21084.562 | K7: ='Vessel Budget'!T14+'LW Budget'!T18 -> 21084.562 | L7: ='Vessel Budget'!V14+'LW Budget'!V18 -> 21084.562 | M7: ='Vessel Budget'!X14+'LW Budget'!X18 -> 21084.562 | N7: ='Vessel Budget'!Z14+'LW Budget'!Z18 -> 250966.15
A8: GROSS PROFIT | B8: =B6-B7 -> 39582.913 | C8: =C6-C7 -> 22146.227 | D8: =D6-D7 -> 48194.254 | E8: =E6-E7 -> 24212.88 | F8: =F6-F7 -> 41271.38 | G8: =G6-G7 -> 40303.648 | H8: =H6-H7 -> 36410.45 | I8: =I6-I7 -> 36410.45 | ... N8: =N6-N7 -> 434174
A10: Labor | B10: ='Vessel Budget'!B20+'LW Budget'!B21 -> 15309.539 | C10: ='Vessel Budget'!D20+'LW Budget'!D21 -> 11042.864 | D10: ='Vessel Budget'!F20+'LW Budget'!F21 -> 15309.539 | E10: ='Vessel Budget'!H20+'LW Budget'!H21 -> 11042.864 | F10: ='Vessel Budget'!J20+'LW Budget'!J21 -> 14090.489 | G10: ='Vessel Budget'!L20+'LW Budget'!L21 -> 13480.964 | H10: ='Vessel Budget'!N20+'LW Budget'!N21 -> 13480.964 | I10: ='Vessel Budget'!P20+'LW Budget'!P21 -> 13480.964 | J10: ='Vessel Budget'!R20+'LW Budget'!R21 -> 13480.964 | K10: ='Vessel Budget'!T20+'LW Budget'!T21 -> 13480.964 | L10: ='Vessel Budget'!V20+'LW Budget'!V21 -> 13480.964 | M10: ='Vessel Budget'!X20+'LW Budget'!X21 -> 13480.964 | N10: ='Vessel Budget'!Z20+'LW Budget'!Z21 -> 161162.04
A11: Credit card fees | B11: ='Vessel Budget'!B24+'LW Budget'!B22 -> 1620.373 | C11: ='Vessel Budget'!D24+'LW Budget'!D22 -> 843.874 | D11: ='Vessel Budget'!F24+'LW Budget'!F22 -> 1920.3152 | E11: ='Vessel Budget'!H24+'LW Budget'!H22 -> 915.85773 | F11: ='Vessel Budget'!J24+'LW Budget'!J22 -> 1630.8525 | G11: ='Vessel Budget'!L24+'LW Budget'!L22 -> 1572.9795 | H11: ='Vessel Budget'!N24+'LW Budget'!N22 -> 1437.3753 | I11: ='Vessel Budget'!P24+'LW Budget'!P22 -> 1437.3753 | J11: ='Vessel Budget'!R24+'LW Budget'!R22 -> 1437.3753 | K11: ='Vessel Budget'!T24+'LW Budget'!T22 -> 1437.3753 | L11: ='Vessel Budget'!V24+'LW Budget'!V22 -> 1437.3753 | M11: ='Vessel Budget'!X24+'LW Budget'!X22 -> 1437.3753 | N11: ='Vessel Budget'!Z24+'LW Budget'!Z22 -> 17128.504
A12: Controllable expenses | B12: ='Vessel Budget'!B23+'LW Budget'!B23 -> 14211.25 | C12: ='Vessel Budget'!D23+'LW Budget'!D23 -> 14211.25 | D12: ='Vessel Budget'!F23+'LW Budget'!F23 -> 14211.25 | E12: ='Vessel Budget'!H23+'LW Budget'!H23 -> 14211.25 | F12: ='Vessel Budget'!J23+'LW Budget'!J23 -> 14211.25 | G12: ='Vessel Budget'!L23+'LW Budget'!L23 -> 14211.25 | H12: ='Vessel Budget'!N23+'LW Budget'!N23 -> 14211.25 | I12: ='Vessel Budget'!P23+'LW Budget'!P23 -> 14211.25 | J12: ='Vessel Budget'!R23+'LW Budget'!R23 -> 14211.25 | K12: ='Vessel Budget'!T23+'LW Budget'!T23 -> 14211.25 | L12: ='Vessel Budget'!V23+'LW Budget'!V23 -> 14211.25 | M12: ='Vessel Budget'!X23+'LW Budget'!X23 -> 14211.25 | N12: ='Vessel Budget'!Z23+'LW Budget'!Z23 -> 170535
A13: Non-controllable expenses | B13: ='Vessel Budget'!B25+'LW Budget'!B24 -> 1201.5 | C13: ='Vessel Budget'!D25+'LW Budget'!D24 -> 1201.5 | D13: ='Vessel Budget'!F25+'LW Budget'!F24 -> 1201.5 | E13: ='Vessel Budget'!H25+'LW Budget'!H24 -> 1201.5 | F13: ='Vessel Budget'!J25+'LW Budget'!J24 -> 1201.5 | G13: ='Vessel Budget'!L25+'LW Budget'!L24 -> 1201.5 | H13: ='Vessel Budget'!N25+'LW Budget'!N24 -> 1201.5 | I13: ='Vessel Budget'!P25+'LW Budget'!P24 -> 1201.5 | J13: ='Vessel Budget'!R25+'LW Budget'!R24 -> 1201.5 | K13: ='Vessel Budget'!T25+'LW Budget'!T24 -> 1201.5 | L13: ='Vessel Budget'!V25+'LW Budget'!V24 -> 1201.5 | M13: ='Vessel Budget'!X25+'LW Budget'!X24 -> 1201.5 | N13: ='Vessel Budget'!Z25+'LW Budget'!Z24 -> 14418
A14: Management fee (4% of revenue) | B14: ='Vessel Budget'!B26+'LW Budget'!B25 -> 2592.5968 | C14: ='Vessel Budget'!D26+'LW Budget'!D25 -> 1350.1984 | D14: ='Vessel Budget'!F26+'LW Budget'!F25 -> 3072.5042 | E14: ='Vessel Budget'!H26+'LW Budget'!H25 -> 1465.3724 | F14: ='Vessel Budget'!J26+'LW Budget'!J25 -> 2609.364 | G14: ='Vessel Budget'!L26+'LW Budget'!L25 -> 2516.7672 | H14: ='Vessel Budget'!N26+'LW Budget'!N25 -> 2299.8005 | I14: ='Vessel Budget'!P26+'LW Budget'!P25 -> 2299.8005 | J14: ='Vessel Budget'!R26+'LW Budget'!R25 -> 2299.8005 | K14: ='Vessel Budget'!T26+'LW Budget'!T25 -> 2299.8005 | L14: ='Vessel Budget'!V26+'LW Budget'!V25 -> 2299.8005 | M14: ='Vessel Budget'!X26+'LW Budget'!X25 -> 2299.8005 | N14: ='Vessel Budget'!Z26+'LW Budget'!Z25 -> 27405.606
A15: Admin fee (Vessel 5% of F&B) | B15: ='Vessel Budget'!B27 -> 2000 | C15: ='Vessel Budget'!D27 -> 600 | D15: ='Vessel Budget'!F27 -> 2000 | E15: ='Vessel Budget'!H27 -> 600 | F15: ='Vessel Budget'!J27 -> 1600 | G15: ='Vessel Budget'!L27 -> 1400 | H15: ='Vessel Budget'!N27 -> 1400 | I15: ='Vessel Budget'!P27 -> 1400 | J15: ='Vessel Budget'!R27 -> 1400 | K15: ='Vessel Budget'!T27 -> 1400 | L15: ='Vessel Budget'!V27 -> 1400 | M15: ='Vessel Budget'!X27 -> 1400 | N15: ='Vessel Budget'!Z27 -> 16600
A16: Rent (Vessel $0 / LW 6%) | B16: ='Vessel Budget'!B28+'LW Budget'!B26 -> 1008.8952 | C16: ='Vessel Budget'!D28+'LW Budget'!D26 -> 1161.2976 | D16: ='Vessel Budget'!F28+'LW Budget'!F26 -> 1728.7564 | E16: ='Vessel Budget'!H28+'LW Budget'!H26 -> 1334.0585 | F16: ='Vessel Budget'!J28+'LW Budget'!J26 -> 1610.0459 | G16: ='Vessel Budget'!L28+'LW Budget'!L26 -> 1759.1508 | H16: ='Vessel Budget'!N28+'LW Budget'!N26 -> 1433.7007 | I16: ='Vessel Budget'!P28+'LW Budget'!P26 -> 1433.7007 | J16: ='Vessel Budget'!R28+'LW Budget'!R26 -> 1433.7007 | K16: ='Vessel Budget'!T28+'LW Budget'!T26 -> 1433.7007 | L16: ='Vessel Budget'!V28+'LW Budget'!V26 -> 1433.7007 | M16: ='Vessel Budget'!X28+'LW Budget'!X26 -> 1433.7007 | N16: ='Vessel Budget'!Z28+'LW Budget'!Z26 -> 17204.409
A18: NET OPERATING INCOME | B18: =B8-(B10+B11+B12+B13+B14+B15+B16) -> 1638.7586 | C18: =C8-(C10+C11+C12+C13+C14+C15+C16) -> -8264.7573 | D18: =D8-(D10+D11+D12+D13+D14+D15+D16) -> 8750.3894 | E18: =E8-(E10+E11+E12+E13+E14+E15+E16) -> -6558.0225 | F18: =F8-(F10+F11+F12+F13+F14+F15+F16) -> 4317.8789 | G18: =G8-(G10+G11+G12+G13+G14+G15+G16) -> 4161.0364 | H18: =H8-(H10+H11+H12+H13+H14+H15+H16) -> 945.85974 | I18: =I8-(I10+I11+I12+I13+I14+I15+I16) -> 945.85974 | ... N18: =N8-(N10+N11+N12+N13+N14+N15+N16) -> 9720.4419

Sheet Vessel Summary
B2: VESSEL EVENTS — 2027 OPERATING SUMMARY
B3: ="$"&TEXT('Vessel Assumptions'!$C$6,"#,##0")&" F&B min · "&TEXT('Vessel Assumptions'!$C$7,"0%")&" volume · "&TEXT('Vessel Assumptions'!$C$30,"0%")&" mgmt fee" -> $4,000 F&B min · 80% volume · 4% mgmt fee
B5: ANNUAL P&L | C5: $ | D5: % rev | F5: KEY METRICS
B6: Total revenue | C6: ='Vessel Budget'!Z10 -> 398400 | D6: =C6/C6 -> 1 | F6: Net operating margin | G6: ='Vessel Budget'!Z28/'Vessel Budget'!Z10 -> 0
B7: Total COGS | C7: ='Vessel Budget'!Z14 -> 170033.8 | D7: =C7/C6 -> 0.42679167 | F7: Prime cost % | G7: ='Vessel Budget'!Z21/'Vessel Budget'!Z10 -> 0.5951221
B8: Gross profit | C8: ='Vessel Budget'!Z15 -> 228366.2 | D8: =C8/C6 -> 0.57320833 | F8: COGS % | G8: ='Vessel Budget'!Z14/'Vessel Budget'!Z10 -> 0.42679167
B9: Total labor (incl. mgmt) | C9: ='Vessel Budget'!Z20 -> 67062.843 | D9: =C9/C6 -> 0.16833043 | F9: Total events / year | G9: ='Vessel Budget'!Z6 -> 83
B10: Prime cost | C10: ='Vessel Budget'!Z21 -> 237096.64 | D10: =C10/C6 -> 0.5951221 | F10: Avg F&B / event | G10: ='Vessel Assumptions'!C6 -> 4000
B11: Controllable (excl CC) | C11: ='Vessel Budget'!Z23 -> 80860 | D11: =C11/C6 -> 0.20296185 | F11: Revenue / event | G11: ='Vessel Budget'!Z10/'Vessel Budget'!Z6 -> 4800
B12: Credit card fees (2.5%) | C12: ='Vessel Budget'!Z24 -> 9960 | D12: =C12/C6 -> 0.025
B13: Non-controllable | C13: ='Vessel Budget'!Z25 -> 8761 | D13: =C13/C6 -> 0.021990462
B14: Management fee (4% of revenue) | C14: ='Vessel Budget'!Z26 -> 15936 | D14: =C14/C6 -> 0.04
B15: Admin fee (5% of F&B) | C15: ='Vessel Budget'!Z27 -> 16600 | D15: =C15/C6 -> 0.041666667
B16: Rent / occupancy (none) | C16: ='Vessel Budget'!Z28 -> 0 | D16: =C16/C6 -> 0
B17: NET OPERATING INCOME | C17: ='Vessel Budget'!Z29 -> 29186.357 | D17: =C17/C6 -> 0.073258928
B20: Adjust inputs on the Vessel Assumptions tab — every figure recalculates. Management fee = 4% of revenue; no separate rent.

Sheet Vessel Assumptions
B2: VESSEL · EVENT OPERATING MODEL
B3: Model drivers — adjust any input and the 2027 budget recalculates
B5: REVENUE DRIVERS
B6: F&B minimum per event | C6: 4000 | D6: the recommended minimum
B7: Event volume (% of run-rate) | C7: 0.8 | D7: =TEXT($C$7,"0%")&" of Jan–May run-rate" -> 80% of Jan–May run-rate
B8: Food share of F&B | C8: 0.749 | D8: balance is beverage
B9: Service charge (% of F&B) | C9: 0.2 | D9: revenue, not billed labor
B11: COST OF SALES (% of that category's sales)
B12: Food cost % (of food sales) | C12: 0.6 | D12: =TEXT(1-$C$12,"0%")&" margin target" -> 40% margin target
B13: Beverage cost % (of bev sales) | C13: 0.25 | D13: =TEXT(1-$C$13,"0%")&" margin" -> 75% margin
B15: LABOR
B16: Bartenders per event | C16: 1
B17: Servers per event | C17: 2
B18: Hourly rate | C18: 35
B19: Shift hours | C19: 5
B20: Hourly labor per event (calc) | C20: =(C16+C17)*C18*C19 -> 525
B21: Management labor / month | C21: ='Vessel GL Basis'!D8 -> 1182.3333 | D21: linked ← Vessel GL Basis
B22: Payroll taxes & benefits % | C22: 0.161 | D22: on all wages (hourly + mgmt)
B24: OVERHEAD & VARIABLE
B25: Controllable exp / month (excl CC) | C25: ='Vessel GL Basis'!D18 -> 6738.3333 | D25: linked ← Vessel GL Basis
B26: Non-controllable / month | C26: ='Vessel GL Basis'!D24 -> 730.08333 | D26: linked ← Vessel GL Basis
B27: Credit card fee (% of revenue) | C27: 0.025 | D27: variable — own line
B29: OWNER CHARGES (above NOI)
B30: Management fee (% of revenue) | C30: 0.04 | D30: 4% of gross revenue → Method (replaces profit split)
B31: Rent (% of revenue) | C31: 0 | D31: Vessel carries no separate rent (owner)
B32: Admin fee (% of F&B revenue) | C32: 0.05 | D32: 5% of food + beverage sales → Method admin (above NOI)

Sheet Vessel Budget
A1: 2027 BUDGET
A2: $ per month · management fee (4% of revenue) & rent shown above NOI · driven by Vessel Assumptions
A4: ($ / % of revenue) | B4: Jan | D4: Feb | F4: Mar | H4: Apr | J4: May | L4: Jun | N4: Jul | P4: Aug | R4: Sep | T4: Oct | V4: Nov | X4: Dec | Z4: FY 2027
A5: Events (2026 run-rate) | B5: 13 | D5: 4 | F5: 13 | H5: 4 | J5: 10 | L5: =AVERAGE($B5,$D5,$F5,$H5,$J5) -> 8.8 | N5: =AVERAGE($B5,$D5,$F5,$H5,$J5) -> 8.8 | P5: =AVERAGE($B5,$D5,$F5,$H5,$J5) -> 8.8 | R5: =AVERAGE($B5,$D5,$F5,$H5,$J5) -> 8.8 | T5: =AVERAGE($B5,$D5,$F5,$H5,$J5) -> 8.8 | V5: =AVERAGE($B5,$D5,$F5,$H5,$J5) -> 8.8 | X5: =AVERAGE($B5,$D5,$F5,$H5,$J5) -> 8.8 | Z5: =B5+D5+F5+H5+J5+L5+N5+P5+R5+T5+V5+X5 -> 105.6
A6: Events (budgeted, whole) | B6: =ROUND(B5*'Vessel Assumptions'!$C$7,0) -> 10 | D6: =ROUND(D5*'Vessel Assumptions'!$C$7,0) -> 3 | F6: =ROUND(F5*'Vessel Assumptions'!$C$7,0) -> 10 | H6: =ROUND(H5*'Vessel Assumptions'!$C$7,0) -> 3 | J6: =ROUND(J5*'Vessel Assumptions'!$C$7,0) -> 8 | L6: =ROUND(L5*'Vessel Assumptions'!$C$7,0) -> 7 | N6: =ROUND(N5*'Vessel Assumptions'!$C$7,0) -> 7 | P6: =ROUND(P5*'Vessel Assumptions'!$C$7,0) -> 7 | R6: =ROUND(R5*'Vessel Assumptions'!$C$7,0) -> 7 | T6: =ROUND(T5*'Vessel Assumptions'!$C$7,0) -> 7 | V6: =ROUND(V5*'Vessel Assumptions'!$C$7,0) -> 7 | X6: =ROUND(X5*'Vessel Assumptions'!$C$7,0) -> 7 | Z6: =B6+D6+F6+H6+J6+L6+N6+P6+R6+T6+V6+X6 -> 83
A7: Food revenue | B7: =B6*'Vessel Assumptions'!$C$6*'Vessel Assumptions'!$C$8 -> 29960 | C7: =B7/B10 -> 0.62416667 | D7: =D6*'Vessel Assumptions'!$C$6*'Vessel Assumptions'!$C$8 -> 8988 | E7: =D7/D10 -> 0.62416667 | F7: =F6*'Vessel Assumptions'!$C$6*'Vessel Assumptions'!$C$8 -> 29960 | G7: =F7/F10 -> 0.62416667 | H7: =H6*'Vessel Assumptions'!$C$6*'Vessel Assumptions'!$C$8 -> 8988 | I7: =H7/H10 -> 0.62416667 | J7: =J6*'Vessel Assumptions'!$C$6*'Vessel Assumptions'!$C$8 -> 23968 | K7: =J7/J10 -> 0.62416667 | L7: =L6*'Vessel Assumptions'!$C$6*'Vessel Assumptions'!$C$8 -> 20972 | M7: =L7/L10 -> 0.62416667 | N7: =N6*'Vessel Assumptions'!$C$6*'Vessel Assumptions'!$C$8 -> 20972 | O7: =N7/N10 -> 0.62416667 | P7: =P6*'Vessel Assumptions'!$C$6*'Vessel Assumptions'!$C$8 -> 20972 | Q7: =P7/P10 -> 0.62416667 | R7: =R6*'Vessel Assumptions'!$C$6*'Vessel Assumptions'!$C$8 -> 20972 | S7: =R7/R10 -> 0.62416667 | T7: =T6*'Vessel Assumptions'!$C$6*'Vessel Assumptions'!$C$8 -> 20972 | U7: =T7/T10 -> 0.62416667 | V7: =V6*'Vessel Assumptions'!$C$6*'Vessel Assumptions'!$C$8 -> 20972 | W7: =V7/V10 -> 0.62416667 | X7: =X6*'Vessel Assumptions'!$C$6*'Vessel Assumptions'!$C$8 -> 20972 | Y7: =X7/X10 -> 0.62416667 | Z7: =B7+D7+F7+H7+J7+L7+N7+P7+R7+T7+V7+X7 -> 248668 | AA7: =Z7/Z10 -> 0.62416667
A8: Beverage revenue | B8: =B6*'Vessel Assumptions'!$C$6*(1-'Vessel Assumptions'!$C$8) -> 10040 | C8: =B8/B10 -> 0.20916667 | D8: =D6*'Vessel Assumptions'!$C$6*(1-'Vessel Assumptions'!$C$8) -> 3012 | E8: =D8/D10 -> 0.20916667 | F8: =F6*'Vessel Assumptions'!$C$6*(1-'Vessel Assumptions'!$C$8) -> 10040 | G8: =F8/F10 -> 0.20916667 | H8: =H6*'Vessel Assumptions'!$C$6*(1-'Vessel Assumptions'!$C$8) -> 3012 | I8: =H8/H10 -> 0.20916667 | J8: =J6*'Vessel Assumptions'!$C$6*(1-'Vessel Assumptions'!$C$8) -> 8032 | K8: =J8/J10 -> 0.20916667 | L8: =L6*'Vessel Assumptions'!$C$6*(1-'Vessel Assumptions'!$C$8) -> 7028 | M8: =L8/L10 -> 0.20916667 | N8: =N6*'Vessel Assumptions'!$C$6*(1-'Vessel Assumptions'!$C$8) -> 7028 | O8: =N8/N10 -> 0.20916667 | P8: =P6*'Vessel Assumptions'!$C$6*(1-'Vessel Assumptions'!$C$8) -> 7028 | Q8: =P8/P10 -> 0.20916667 | R8: =R6*'Vessel Assumptions'!$C$6*(1-'Vessel Assumptions'!$C$8) -> 7028 | S8: =R8/R10 -> 0.20916667 | T8: =T6*'Vessel Assumptions'!$C$6*(1-'Vessel Assumptions'!$C$8) -> 7028 | U8: =T8/T10 -> 0.20916667 | V8: =V6*'Vessel Assumptions'!$C$6*(1-'Vessel Assumptions'!$C$8) -> 7028 | W8: =V8/V10 -> 0.20916667 | X8: =X6*'Vessel Assumptions'!$C$6*(1-'Vessel Assumptions'!$C$8) -> 7028 | Y8: =X8/X10 -> 0.20916667 | Z8: =B8+D8+F8+H8+J8+L8+N8+P8+R8+T8+V8+X8 -> 83332 | AA8: =Z8/Z10 -> 0.20916667
A9: Service charge | B9: =B6*'Vessel Assumptions'!$C$6*'Vessel Assumptions'!$C$9 -> 8000 | C9: =B9/B10 -> 0.16666667 | D9: =D6*'Vessel Assumptions'!$C$6*'Vessel Assumptions'!$C$9 -> 2400 | E9: =D9/D10 -> 0.16666667 | F9: =F6*'Vessel Assumptions'!$C$6*'Vessel Assumptions'!$C$9 -> 8000 | G9: =F9/F10 -> 0.16666667 | H9: =H6*'Vessel Assumptions'!$C$6*'Vessel Assumptions'!$C$9 -> 2400 | I9: =H9/H10 -> 0.16666667 | J9: =J6*'Vessel Assumptions'!$C$6*'Vessel Assumptions'!$C$9 -> 6400 | K9: =J9/J10 -> 0.16666667 | L9: =L6*'Vessel Assumptions'!$C$6*'Vessel Assumptions'!$C$9 -> 5600 | M9: =L9/L10 -> 0.16666667 | N9: =N6*'Vessel Assumptions'!$C$6*'Vessel Assumptions'!$C$9 -> 5600 | O9: =N9/N10 -> 0.16666667 | P9: =P6*'Vessel Assumptions'!$C$6*'Vessel Assumptions'!$C$9 -> 5600 | Q9: =P9/P10 -> 0.16666667 | R9: =R6*'Vessel Assumptions'!$C$6*'Vessel Assumptions'!$C$9 -> 5600 | S9: =R9/R10 -> 0.16666667 | T9: =T6*'Vessel Assumptions'!$C$6*'Vessel Assumptions'!$C$9 -> 5600 | U9: =T9/T10 -> 0.16666667 | V9: =V6*'Vessel Assumptions'!$C$6*'Vessel Assumptions'!$C$9 -> 5600 | W9: =V9/V10 -> 0.16666667 | X9: =X6*'Vessel Assumptions'!$C$6*'Vessel Assumptions'!$C$9 -> 5600 | Y9: =X9/X10 -> 0.16666667 | Z9: =B9+D9+F9+H9+J9+L9+N9+P9+R9+T9+V9+X9 -> 66400 | AA9: =Z9/Z10 -> 0.16666667
A10: TOTAL REVENUE | B10: =SUM(B7:B9) -> 48000 | C10: =B10/B10 -> 1 | D10: =SUM(D7:D9) -> 14400 | E10: =D10/D10 -> 1 | F10: =SUM(F7:F9) -> 48000 | G10: =F10/F10 -> 1 | H10: =SUM(H7:H9) -> 14400 | I10: =H10/H10 -> 1 | J10: =SUM(J7:J9) -> 38400 | K10: =J10/J10 -> 1 | L10: =SUM(L7:L9) -> 33600 | M10: =L10/L10 -> 1 | N10: =SUM(N7:N9) -> 33600 | O10: =N10/N10 -> 1 | P10: =SUM(P7:P9) -> 33600 | Q10: =P10/P10 -> 1 | R10: =SUM(R7:R9) -> 33600 | S10: =R10/R10 -> 1 | T10: =SUM(T7:T9) -> 33600 | U10: =T10/T10 -> 1 | V10: =SUM(V7:V9) -> 33600 | W10: =V10/V10 -> 1 | X10: =SUM(X7:X9) -> 33600 | Y10: =X10/X10 -> 1 | Z10: =B10+D10+F10+H10+J10+L10+N10+P10+R10+T10+V10+X10 -> 398400 | AA10: =Z10/Z10 -> 1
A12: Food COGS (% of food sales) | B12: =B7*'Vessel Assumptions'!$C$12 -> 17976 | C12: =B12/B7 -> 0.6 | D12: =D7*'Vessel Assumptions'!$C$12 -> 5392.8 | E12: =D12/D7 -> 0.6 | F12: =F7*'Vessel Assumptions'!$C$12 -> 17976 | G12: =F12/F7 -> 0.6 | H12: =H7*'Vessel Assumptions'!$C$12 -> 5392.8 | I12: =H12/H7 -> 0.6 | J12: =J7*'Vessel Assumptions'!$C$12 -> 14380.8 | K12: =J12/J7 -> 0.6 | L12: =L7*'Vessel Assumptions'!$C$12 -> 12583.2 | M12: =L12/L7 -> 0.6 | N12: =N7*'Vessel Assumptions'!$C$12 -> 12583.2 | O12: =N12/N7 -> 0.6 | P12: =P7*'Vessel Assumptions'!$C$12 -> 12583.2 | Q12: =P12/P7 -> 0.6 | R12: =R7*'Vessel Assumptions'!$C$12 -> 12583.2 | S12: =R12/R7 -> 0.6 | T12: =T7*'Vessel Assumptions'!$C$12 -> 12583.2 | U12: =T12/T7 -> 0.6 | V12: =V7*'Vessel Assumptions'!$C$12 -> 12583.2 | W12: =V12/V7 -> 0.6 | X12: =X7*'Vessel Assumptions'!$C$12 -> 12583.2 | Y12: =X12/X7 -> 0.6 | Z12: =B12+D12+F12+H12+J12+L12+N12+P12+R12+T12+V12+X12 -> 149200.8 | AA12: =Z12/Z7 -> 0.6
A13: Beverage COGS (% of bev sales) | B13: =B8*'Vessel Assumptions'!$C$13 -> 2510 | C13: =B13/B8 -> 0.25 | D13: =D8*'Vessel Assumptions'!$C$13 -> 753 | E13: =D13/D8 -> 0.25 | F13: =F8*'Vessel Assumptions'!$C$13 -> 2510 | G13: =F13/F8 -> 0.25 | H13: =H8*'Vessel Assumptions'!$C$13 -> 753 | I13: =H13/H8 -> 0.25 | J13: =J8*'Vessel Assumptions'!$C$13 -> 2008 | K13: =J13/J8 -> 0.25 | L13: =L8*'Vessel Assumptions'!$C$13 -> 1757 | M13: =L13/L8 -> 0.25 | N13: =N8*'Vessel Assumptions'!$C$13 -> 1757 | O13: =N13/N8 -> 0.25 | P13: =P8*'Vessel Assumptions'!$C$13 -> 1757 | Q13: =P13/P8 -> 0.25 | R13: =R8*'Vessel Assumptions'!$C$13 -> 1757 | S13: =R13/R8 -> 0.25 | T13: =T8*'Vessel Assumptions'!$C$13 -> 1757 | U13: =T13/T8 -> 0.25 | V13: =V8*'Vessel Assumptions'!$C$13 -> 1757 | W13: =V13/V8 -> 0.25 | X13: =X8*'Vessel Assumptions'!$C$13 -> 1757 | Y13: =X13/X8 -> 0.25 | Z13: =B13+D13+F13+H13+J13+L13+N13+P13+R13+T13+V13+X13 -> 20833 | AA13: =Z13/Z8 -> 0.25
A14: TOTAL COGS | B14: =B12+B13 -> 20486 | C14: =B14/B10 -> 0.42679167 | D14: =D12+D13 -> 6145.8 | E14: =D14/D10 -> 0.42679167 | F14: =F12+F13 -> 20486 | G14: =F14/F10 -> 0.42679167 | H14: =H12+H13 -> 6145.8 | I14: =H14/H10 -> 0.42679167 | J14: =J12+J13 -> 16388.8 | K14: =J14/J10 -> 0.42679167 | L14: =L12+L13 -> 14340.2 | M14: =L14/L10 -> 0.42679167 | N14: =N12+N13 -> 14340.2 | O14: =N14/N10 -> 0.42679167 | P14: =P12+P13 -> 14340.2 | Q14: =P14/P10 -> 0.42679167 | R14: =R12+R13 -> 14340.2 | S14: =R14/R10 -> 0.42679167 | T14: =T12+T13 -> 14340.2 | U14: =T14/T10 -> 0.42679167 | V14: =V12+V13 -> 14340.2 | W14: =V14/V10 -> 0.42679167 | X14: =X12+X13 -> 14340.2 | Y14: =X14/X10 -> 0.42679167 | Z14: =B14+D14+F14+H14+J14+L14+N14+P14+R14+T14+V14+X14 -> 170033.8 | AA14: =Z14/Z10 -> 0.42679167
A15: GROSS PROFIT | B15: =B10-B14 -> 27514 | C15: =B15/B10 -> 0.57320833 | D15: =D10-D14 -> 8254.2 | E15: =D15/D10 -> 0.57320833 | F15: =F10-F14 -> 27514 | G15: =F15/F10 -> 0.57320833 | H15: =H10-H14 -> 8254.2 | I15: =H15/H10 -> 0.57320833 | J15: =J10-J14 -> 22011.2 | K15: =J15/J10 -> 0.57320833 | L15: =L10-L14 -> 19259.8 | M15: =L15/L10 -> 0.57320833 | N15: =N10-N14 -> 19259.8 | O15: =N15/N10 -> 0.57320833 | P15: =P10-P14 -> 19259.8 | Q15: =P15/P10 -> 0.57320833 | R15: =R10-R14 -> 19259.8 | S15: =R15/R10 -> 0.57320833 | T15: =T10-T14 -> 19259.8 | U15: =T15/T10 -> 0.57320833 | V15: =V10-V14 -> 19259.8 | W15: =V15/V10 -> 0.57320833 | X15: =X10-X14 -> 19259.8 | Y15: =X15/X10 -> 0.57320833 | Z15: =B15+D15+F15+H15+J15+L15+N15+P15+R15+T15+V15+X15 -> 228366.2 | AA15: =Z15/Z10 -> 0.57320833
A17: ="Hourly labor ("&'Vessel Assumptions'!$C$16&" bartender"&IF('Vessel Assumptions'!$C$16=1,"","s")&" + "&'Vessel Assumptions'!$C$17&" server"&IF('Vessel Assumptions'!$C$17=1,"","s")&")" -> Hourly labor (1 bartender + 2 servers) | B17: =B6*'Vessel Assumptions'!$C$20 -> 5250 | C17: =B17/B10 -> 0.109375 | D17: =D6*'Vessel Assumptions'!$C$20 -> 1575 | E17: =D17/D10 -> 0.109375 | F17: =F6*'Vessel Assumptions'!$C$20 -> 5250 | G17: =F17/F10 -> 0.109375 | H17: =H6*'Vessel Assumptions'!$C$20 -> 1575 | I17: =H17/H10 -> 0.109375 | J17: =J6*'Vessel Assumptions'!$C$20 -> 4200 | K17: =J17/J10 -> 0.109375 | L17: =L6*'Vessel Assumptions'!$C$20 -> 3675 | M17: =L17/L10 -> 0.109375 | N17: =N6*'Vessel Assumptions'!$C$20 -> 3675 | O17: =N17/N10 -> 0.109375 | P17: =P6*'Vessel Assumptions'!$C$20 -> 3675 | Q17: =P17/P10 -> 0.109375 | R17: =R6*'Vessel Assumptions'!$C$20 -> 3675 | S17: =R17/R10 -> 0.109375 | T17: =T6*'Vessel Assumptions'!$C$20 -> 3675 | U17: =T17/T10 -> 0.109375 | V17: =V6*'Vessel Assumptions'!$C$20 -> 3675 | W17: =V17/V10 -> 0.109375 | X17: =X6*'Vessel Assumptions'!$C$20 -> 3675 | Y17: =X17/X10 -> 0.109375 | Z17: =B17+D17+F17+H17+J17+L17+N17+P17+R17+T17+V17+X17 -> 43575 | AA17: =Z17/Z10 -> 0.109375
A18: Management labor (GL FOH mgmt) | B18: ='Vessel Assumptions'!$C$21 -> 1182.3333 | C18: =B18/B10 -> 0.024631944 | D18: ='Vessel Assumptions'!$C$21 -> 1182.3333 | E18: =D18/D10 -> 0.082106481 | F18: ='Vessel Assumptions'!$C$21 -> 1182.3333 | G18: =F18/F10 -> 0.024631944 | H18: ='Vessel Assumptions'!$C$21 -> 1182.3333 | I18: =H18/H10 -> 0.082106481 | J18: ='Vessel Assumptions'!$C$21 -> 1182.3333 | K18: =J18/J10 -> 0.030789931 | L18: ='Vessel Assumptions'!$C$21 -> 1182.3333 | M18: =L18/L10 -> 0.035188492 | N18: ='Vessel Assumptions'!$C$21 -> 1182.3333 | O18: =N18/N10 -> 0.035188492 | P18: ='Vessel Assumptions'!$C$21 -> 1182.3333 | Q18: =P18/P10 -> 0.035188492 | R18: ='Vessel Assumptions'!$C$21 -> 1182.3333 | S18: =R18/R10 -> 0.035188492 | T18: ='Vessel Assumptions'!$C$21 -> 1182.3333 | U18: =T18/T10 -> 0.035188492 | V18: ='Vessel Assumptions'!$C$21 -> 1182.3333 | W18: =V18/V10 -> 0.035188492 | X18: ='Vessel Assumptions'!$C$21 -> 1182.3333 | Y18: =X18/X10 -> 0.035188492 | Z18: =B18+D18+F18+H18+J18+L18+N18+P18+R18+T18+V18+X18 -> 14188 | AA18: =Z18/Z10 -> 0.03561245
A19: Payroll taxes & benefits | B19: =(B17+B18)*'Vessel Assumptions'!$C$22 -> 1035.6057 | C19: =B19/B10 -> 0.021575118 | D19: =(D17+D18)*'Vessel Assumptions'!$C$22 -> 443.93067 | E19: =D19/D10 -> 0.030828519 | F19: =(F17+F18)*'Vessel Assumptions'!$C$22 -> 1035.6057 | G19: =F19/F10 -> 0.021575118 | H19: =(H17+H18)*'Vessel Assumptions'!$C$22 -> 443.93067 | I19: =H19/H10 -> 0.030828519 | J19: =(J17+J18)*'Vessel Assumptions'!$C$22 -> 866.55567 | K19: =J19/J10 -> 0.022566554 | L19: =(L17+L18)*'Vessel Assumptions'!$C$22 -> 782.03067 | M19: =L19/L10 -> 0.023274722 | N19: =(N17+N18)*'Vessel Assumptions'!$C$22 -> 782.03067 | O19: =N19/N10 -> 0.023274722 | P19: =(P17+P18)*'Vessel Assumptions'!$C$22 -> 782.03067 | Q19: =P19/P10 -> 0.023274722 | R19: =(R17+R18)*'Vessel Assumptions'!$C$22 -> 782.03067 | S19: =R19/R10 -> 0.023274722 | T19: =(T17+T18)*'Vessel Assumptions'!$C$22 -> 782.03067 | U19: =T19/T10 -> 0.023274722 | V19: =(V17+V18)*'Vessel Assumptions'!$C$22 -> 782.03067 | W19: =V19/V10 -> 0.023274722 | X19: =(X17+X18)*'Vessel Assumptions'!$C$22 -> 782.03067 | Y19: =X19/X10 -> 0.023274722 | Z19: =B19+D19+F19+H19+J19+L19+N19+P19+R19+T19+V19+X19 -> 9299.843 | AA19: =Z19/Z10 -> 0.023342979
A20: TOTAL LABOR | B20: =B17+B18+B19 -> 7467.939 | C20: =B20/B10 -> 0.15558206 | D20: =D17+D18+D19 -> 3201.264 | E20: =D20/D10 -> 0.22231 | F20: =F17+F18+F19 -> 7467.939 | G20: =F20/F10 -> 0.15558206 | H20: =H17+H18+H19 -> 3201.264 | I20: =H20/H10 -> 0.22231 | J20: =J17+J18+J19 -> 6248.889 | K20: =J20/J10 -> 0.16273148 | L20: =L17+L18+L19 -> 5639.364 | M20: =L20/L10 -> 0.16783821 | N20: =N17+N18+N19 -> 5639.364 | O20: =N20/N10 -> 0.16783821 | P20: =P17+P18+P19 -> 5639.364 | Q20: =P20/P10 -> 0.16783821 | R20: =R17+R18+R19 -> 5639.364 | S20: =R20/R10 -> 0.16783821 | T20: =T17+T18+T19 -> 5639.364 | U20: =T20/T10 -> 0.16783821 | V20: =V17+V18+V19 -> 5639.364 | W20: =V20/V10 -> 0.16783821 | X20: =X17+X18+X19 -> 5639.364 | Y20: =X20/X10 -> 0.16783821 | Z20: =B20+D20+F20+H20+J20+L20+N20+P20+R20+T20+V20+X20 -> 67062.843 | AA20: =Z20/Z10 -> 0.16833043
A21: PRIME COST | B21: =B14+B20 -> 27953.939 | C21: =B21/B10 -> 0.58237373 | D21: =D14+D20 -> 9347.064 | E21: =D21/D10 -> 0.64910167 | F21: =F14+F20 -> 27953.939 | G21: =F21/F10 -> 0.58237373 | H21: =H14+H20 -> 9347.064 | I21: =H21/H10 -> 0.64910167 | J21: =J14+J20 -> 22637.689 | K21: =J21/J10 -> 0.58952315 | L21: =L14+L20 -> 19979.564 | M21: =L21/L10 -> 0.59462988 | N21: =N14+N20 -> 19979.564 | O21: =N21/N10 -> 0.59462988 | P21: =P14+P20 -> 19979.564 | Q21: =P21/P10 -> 0.59462988 | R21: =R14+R20 -> 19979.564 | S21: =R21/R10 -> 0.59462988 | T21: =T14+T20 -> 19979.564 | U21: =T21/T10 -> 0.59462988 | V21: =V14+V20 -> 19979.564 | W21: =V21/V10 -> 0.59462988 | X21: =X14+X20 -> 19979.564 | Y21: =X21/X10 -> 0.59462988 | Z21: =B21+D21+F21+H21+J21+L21+N21+P21+R21+T21+V21+X21 -> 237096.64 | AA21: =Z21/Z10 -> 0.5951221
A23: Controllable expenses (excl CC) | B23: ='Vessel Assumptions'!$C$25 -> 6738.3333 | C23: =B23/B10 -> 0.14038194 | D23: ='Vessel Assumptions'!$C$25 -> 6738.3333 | E23: =D23/D10 -> 0.46793981 | F23: ='Vessel Assumptions'!$C$25 -> 6738.3333 | G23: =F23/F10 -> 0.14038194 | H23: ='Vessel Assumptions'!$C$25 -> 6738.3333 | I23: =H23/H10 -> 0.46793981 | J23: ='Vessel Assumptions'!$C$25 -> 6738.3333 | K23: =J23/J10 -> 0.17547743 | L23: ='Vessel Assumptions'!$C$25 -> 6738.3333 | M23: =L23/L10 -> 0.20054563 | N23: ='Vessel Assumptions'!$C$25 -> 6738.3333 | O23: =N23/N10 -> 0.20054563 | P23: ='Vessel Assumptions'!$C$25 -> 6738.3333 | Q23: =P23/P10 -> 0.20054563 | R23: ='Vessel Assumptions'!$C$25 -> 6738.3333 | S23: =R23/R10 -> 0.20054563 | T23: ='Vessel Assumptions'!$C$25 -> 6738.3333 | U23: =T23/T10 -> 0.20054563 | V23: ='Vessel Assumptions'!$C$25 -> 6738.3333 | W23: =V23/V10 -> 0.20054563 | X23: ='Vessel Assumptions'!$C$25 -> 6738.3333 | Y23: =X23/X10 -> 0.20054563 | Z23: =B23+D23+F23+H23+J23+L23+N23+P23+R23+T23+V23+X23 -> 80860 | AA23: =Z23/Z10 -> 0.20296185
A24: Credit card fees (2.5% of revenue) | B24: =B10*'Vessel Assumptions'!$C$27 -> 1200 | C24: =B24/B10 -> 0.025 | D24: =D10*'Vessel Assumptions'!$C$27 -> 360 | E24: =D24/D10 -> 0.025 | F24: =F10*'Vessel Assumptions'!$C$27 -> 1200 | G24: =F24/F10 -> 0.025 | H24: =H10*'Vessel Assumptions'!$C$27 -> 360 | I24: =H24/H10 -> 0.025 | J24: =J10*'Vessel Assumptions'!$C$27 -> 960 | K24: =J24/J10 -> 0.025 | L24: =L10*'Vessel Assumptions'!$C$27 -> 840 | M24: =L24/L10 -> 0.025 | N24: =N10*'Vessel Assumptions'!$C$27 -> 840 | O24: =N24/N10 -> 0.025 | P24: =P10*'Vessel Assumptions'!$C$27 -> 840 | Q24: =P24/P10 -> 0.025 | R24: =R10*'Vessel Assumptions'!$C$27 -> 840 | S24: =R24/R10 -> 0.025 | T24: =T10*'Vessel Assumptions'!$C$27 -> 840 | U24: =T24/T10 -> 0.025 | V24: =V10*'Vessel Assumptions'!$C$27 -> 840 | W24: =V24/V10 -> 0.025 | X24: =X10*'Vessel Assumptions'!$C$27 -> 840 | Y24: =X24/X10 -> 0.025 | Z24: =B24+D24+F24+H24+J24+L24+N24+P24+R24+T24+V24+X24 -> 9960 | AA24: =Z24/Z10 -> 0.025
A25: Non-controllable (insurance, legal, reserves) | B25: ='Vessel Assumptions'!$C$26 -> 730.08333 | C25: =B25/B10 -> 0.015210069 | D25: ='Vessel Assumptions'!$C$26 -> 730.08333 | E25: =D25/D10 -> 0.050700231 | F25: ='Vessel Assumptions'!$C$26 -> 730.08333 | G25: =F25/F10 -> 0.015210069 | H25: ='Vessel Assumptions'!$C$26 -> 730.08333 | I25: =H25/H10 -> 0.050700231 | J25: ='Vessel Assumptions'!$C$26 -> 730.08333 | K25: =J25/J10 -> 0.019012587 | L25: ='Vessel Assumptions'!$C$26 -> 730.08333 | M25: =L25/L10 -> 0.021728671 | N25: ='Vessel Assumptions'!$C$26 -> 730.08333 | O25: =N25/N10 -> 0.021728671 | P25: ='Vessel Assumptions'!$C$26 -> 730.08333 | Q25: =P25/P10 -> 0.021728671 | R25: ='Vessel Assumptions'!$C$26 -> 730.08333 | S25: =R25/R10 -> 0.021728671 | T25: ='Vessel Assumptions'!$C$26 -> 730.08333 | U25: =T25/T10 -> 0.021728671 | V25: ='Vessel Assumptions'!$C$26 -> 730.08333 | W25: =V25/V10 -> 0.021728671 | X25: ='Vessel Assumptions'!$C$26 -> 730.08333 | Y25: =X25/X10 -> 0.021728671 | Z25: =B25+D25+F25+H25+J25+L25+N25+P25+R25+T25+V25+X25 -> 8761 | AA25: =Z25/Z10 -> 0.021990462
A26: Management fee (4% of revenue → Method) | B26: =B10*'Vessel Assumptions'!$C$30 -> 1920 | C26: =B26/B10 -> 0.04 | D26: =D10*'Vessel Assumptions'!$C$30 -> 576 | E26: =D26/D10 -> 0.04 | F26: =F10*'Vessel Assumptions'!$C$30 -> 1920 | G26: =F26/F10 -> 0.04 | H26: =H10*'Vessel Assumptions'!$C$30 -> 576 | I26: =H26/H10 -> 0.04 | J26: =J10*'Vessel Assumptions'!$C$30 -> 1536 | K26: =J26/J10 -> 0.04 | L26: =L10*'Vessel Assumptions'!$C$30 -> 1344 | M26: =L26/L10 -> 0.04 | N26: =N10*'Vessel Assumptions'!$C$30 -> 1344 | O26: =N26/N10 -> 0.04 | P26: =P10*'Vessel Assumptions'!$C$30 -> 1344 | Q26: =P26/P10 -> 0.04 | R26: =R10*'Vessel Assumptions'!$C$30 -> 1344 | S26: =R26/R10 -> 0.04 | T26: =T10*'Vessel Assumptions'!$C$30 -> 1344 | U26: =T26/T10 -> 0.04 | V26: =V10*'Vessel Assumptions'!$C$30 -> 1344 | W26: =V26/V10 -> 0.04 | X26: =X10*'Vessel Assumptions'!$C$30 -> 1344 | Y26: =X26/X10 -> 0.04 | Z26: =B26+D26+F26+H26+J26+L26+N26+P26+R26+T26+V26+X26 -> 15936 | AA26: =Z26/Z10 -> 0.04
A27: Admin fee (5% of F&B revenue → Method) | B27: =(B7+B8)*'Vessel Assumptions'!$C$32 -> 2000 | D27: =(D7+D8)*'Vessel Assumptions'!$C$32 -> 600 | F27: =(F7+F8)*'Vessel Assumptions'!$C$32 -> 2000 | H27: =(H7+H8)*'Vessel Assumptions'!$C$32 -> 600 | J27: =(J7+J8)*'Vessel Assumptions'!$C$32 -> 1600 | L27: =(L7+L8)*'Vessel Assumptions'!$C$32 -> 1400 | N27: =(N7+N8)*'Vessel Assumptions'!$C$32 -> 1400 | P27: =(P7+P8)*'Vessel Assumptions'!$C$32 -> 1400 | R27: =(R7+R8)*'Vessel Assumptions'!$C$32 -> 1400 | T27: =(T7+T8)*'Vessel Assumptions'!$C$32 -> 1400 | V27: =(V7+V8)*'Vessel Assumptions'!$C$32 -> 1400 | X27: =(X7+X8)*'Vessel Assumptions'!$C$32 -> 1400 | Z27: =B27+D27+F27+H27+J27+L27+N27+P27+R27+T27+V27+X27 -> 16600
A28: Rent / occupancy (Vessel: none) | B28: =B10*'Vessel Assumptions'!$C$31 -> 0 | C28: =B28/B10 -> 0 | D28: =D10*'Vessel Assumptions'!$C$31 -> 0 | E28: =D28/D10 -> 0 | F28: =F10*'Vessel Assumptions'!$C$31 -> 0 | G28: =F28/F10 -> 0 | H28: =H10*'Vessel Assumptions'!$C$31 -> 0 | I28: =H28/H10 -> 0 | J28: =J10*'Vessel Assumptions'!$C$31 -> 0 | K28: =J28/J10 -> 0 | L28: =L10*'Vessel Assumptions'!$C$31 -> 0 | M28: =L28/L10 -> 0 | N28: =N10*'Vessel Assumptions'!$C$31 -> 0 | O28: =N28/N10 -> 0 | P28: =P10*'Vessel Assumptions'!$C$31 -> 0 | Q28: =P28/P10 -> 0 | R28: =R10*'Vessel Assumptions'!$C$31 -> 0 | S28: =R28/R10 -> 0 | T28: =T10*'Vessel Assumptions'!$C$31 -> 0 | U28: =T28/T10 -> 0 | V28: =V10*'Vessel Assumptions'!$C$31 -> 0 | W28: =V28/V10 -> 0 | X28: =X10*'Vessel Assumptions'!$C$31 -> 0 | Y28: =X28/X10 -> 0 | Z28: =B28+D28+F28+H28+J28+L28+N28+P28+R28+T28+V28+X28 -> 0 | AA28: =Z28/Z10 -> 0
A29: NET OPERATING INCOME (after mgmt fee, admin fee & rent) | B29: =B15-B20-(B23+B24+B25+B26+B27+B28) -> 7457.6443 | D29: =D15-D20-(D23+D24+D25+D26+D27+D28) -> -3951.4807 | F29: =F15-F20-(F23+F24+F25+F26+F27+F28) -> 7457.6443 | H29: =H15-H20-(H23+H24+H25+H26+H27+H28) -> -3951.4807 | J29: =J15-J20-(J23+J24+J25+J26+J27+J28) -> 4197.8943 | L29: =L15-L20-(L23+L24+L25+L26+L27+L28) -> 2568.0193 | N29: =N15-N20-(N23+N24+N25+N26+N27+N28) -> 2568.0193 | P29: =P15-P20-(P23+P24+P25+P26+P27+P28) -> 2568.0193 | R29: =R15-R20-(R23+R24+R25+R26+R27+R28) -> 2568.0193 | T29: =T15-T20-(T23+T24+T25+T26+T27+T28) -> 2568.0193 | V29: =V15-V20-(V23+V24+V25+V26+V27+V28) -> 2568.0193 | X29: =X15-X20-(X23+X24+X25+X26+X27+X28) -> 2568.0193 | Z29: =Z15-Z20-(Z23+Z24+Z25+Z26+Z27+Z28) -> 29186.357
C30: =B30/B10 -> 0 | E30: =D30/D10 -> 0 | G30: =F30/F10 -> 0 | I30: =H30/H10 -> 0 | K30: =J30/J10 -> 0 | M30: =L30/L10 -> 0 | O30: =N30/N10 -> 0 | Q30: =P30/P10 -> 0 | S30: =R30/R10 -> 0 | U30: =T30/T10 -> 0 | W30: =V30/V10 -> 0 | Y30: =X30/X10 -> 0 | AA30: =Z30/Z10 -> 0
C31: =B31/B10 -> 0 | E31: =D31/D10 -> 0 | G31: =F31/F10 -> 0 | I31: =H31/H10 -> 0 | K31: =J31/J10 -> 0 | M31: =L31/L10 -> 0 | O31: =N31/N10 -> 0 | Q31: =P31/P10 -> 0 | S31: =R31/R10 -> 0 | U31: =T31/T10 -> 0 | W31: =V31/V10 -> 0 | Y31: =X31/X10 -> 0 | AA31: =Z31/Z10 -> 0
A33: Management fee = 4% of revenue; admin fee = 5% of food+beverage; Vessel has no separate rent. NOI is the bottom line.

Sheet Vessel GL Basis
A1: VESSEL — GL COST BASIS
A2: Jan–May run-rate · controllable vs non-controllable (CC fees now variable, shown for reference)
B4: Expense group | C4: Annual | D4: Monthly
B6: LABOR (in model)
B8: Management labor – FOH mgmt (610300) | C8: 14188 | D8: =C8/12 -> 1182.3333
B10: CONTROLLABLE (excl credit card fees)
B11: Direct operating (supplies, linen, equip) | C11: 18543 | D11: =C11/12 -> 1545.25
B12: G&A / accounting / bank | C12: 30300 | D12: =C12/12 -> 2525
B13: Marketing | C13: 13917 | D13: =C13/12 -> 1159.75
B14: Music & entertainment | C14: 6750 | D14: =C14/12 -> 562.5
B15: Repairs & maintenance | C15: 5748 | D15: =C15/12 -> 479
B16: Utilities | C16: 5602 | D16: =C16/12 -> 466.83333
B17: Total controllable (excl CC) | C17: =SUM(C11:C16) -> 80860 | D17: =C17/12 -> 6738.3333
B18: → Controllable / month feed | C18: =C17 -> 80860 | D18: =C17/12 -> 6738.3333
B20: NON-CONTROLLABLE (in model)
B21: Insurance – liability | C21: 2106 | D21: =C21/12 -> 175.5
B22: Legal & accounting | C22: 1800 | D22: =C22/12 -> 150
B23: Replacement reserves | C23: 4855 | D23: =C23/12 -> 404.58333
B24: Total non-controllable | C24: =SUM(C21:C23) -> 8761 | D24: =C24/12 -> 730.08333
B26: VARIABLE / EXCLUDED
B27: Credit card fees (actual GL → now variable 2.5%) | C27: 2745 | D27: =C27/12 -> 228.75
B28: Management fee (→ profit split) | C28: 48000 | D28: =C28/12 -> 4000
B29: Rent / RE tax (owner) | C29: 21861 | D29: =C29/12 -> 1821.75

Sheet LW Assumptions
A1: LITTLE WING · COFFEE SHOP MODEL
A2: Single-shift efficiency model — 6am–4pm staffed (2nd barista Sat/Sun), self-serve/retail after 4pm (front desk, no cafe labor)
B4: REVENUE (Toast H1 2026 actuals ×2 — Jan–Jun item detail, reconciled to Sales Summary)
B5: Food | C5: 106838.2
B6: NA / Coffee | C6: 131727.36 | D6: the margin engine — 22.2% cost
B7: Alcohol | C7: 13996.3
B8: Retail / merch | C8: 5847.56
B9: Other | C9: 7792.6 | D9: gift cards, open items, uncategorized rings
B10: TOTAL REVENUE | C10: =SUM(C5:C9) -> 266202.02
B12: COST OF SALES (% of each category · GL actual)
B13: Food cost % | C13: 0.4407 | D13: GL cost ÷ net sales
B14: NA / Coffee cost % | C14: 0.2216
B15: Alcohol cost % | C15: 0.3328
B16: Retail cost % | C16: 0 | D16: no COGS booked in GL for retail
B17: Other cost % | C17: 0 | D17: no COGS booked in GL for other
B19: ADJUSTED LABOR (single 6am–4pm shift + 2nd barista on peak days)
B20: Opener/supervisor hours/day | C20: 10 | D20: 6am–4pm · one barista/supervisor
B21: 2nd barista avg hrs/day | C21: =2*4/7 -> 1.1428571 | D21: Sat & Sun opener/closer overlap, 4 hrs/day ×2 days ÷7 — covers the 8–11a weekend rush
B22: Days per week | C22: 7
B23: Blended wage $/hr | C23: 20 | D23: Dolce actual blended FOH rate ~$20/hr
B24: Payroll taxes & benefits % | C24: 0.16
B25: Adjusted labor / year | C25: =(C20+C21)*C22*52*C23*(1+C24) -> 94099.2 | D25: servers & cooks eliminated (self-serve/prepackaged)
B27: CURRENT LABOR (GL actual, for comparison)
B28: Current labor / year (incl burden) | C28: 164857 | D28: GL T12 actual: wages+taxes+benefits
B30: VARIABLE & OVERHEAD (annual)
B31: Credit card fee (% of revenue) | C31: 0.025 | D31: go-forward target (Current column uses GL actual → C42)
B32: Controllable exp (excl CC) | C32: 89675 | D32: paper/plastics, accounting, linen…
B33: Non-controllable | C33: 5657 | D33: insurance, legal, reserves
B35: OWNER CHARGES (above NOI · 4% mgmt fee + rent)
C36: 0
C37: 0
B39: BELOW NOI (owner / occupancy)
B40: Management fee (% of revenue) | C40: 0.04 | D40: 4% of gross revenue → Method (replaces $48K flat fee)
B41: Rent (% of revenue) | C41: 0.06 | D41: occupancy — GL actual ~6% of sales
B42: Credit card fee — GL actual (T12 $) | C42: 10012 | D42: 3.9% of rev — used for Current column; go-forward uses 2.5% target
B43: Menu price uplift ($/yr, pure margin) | C43: ='LW Menu Pricing'!$C$53 -> 17614.35 | D43: from LW Menu Pricing tab · held volume
B44: Apply price increase? (1=yes,0=no) | C44: 1 | D44: toggle the 2027 pricing scenario on/off
B45: Management labor — GL 610300 ($/yr) | C45: 12880 | D45: FOH Management wage, annualized ×12/5 — separate from hourly schedule
B46: Retail improvement uplift % (INPUT) | C46: 0.5 | D46: incremental retail rev from expanded inventory — % of current retail base
B47: → incremental retail $ / yr | C47: ='LW Assumptions'!$C$8*'LW Assumptions'!$C$46 -> 2923.78

Sheet LW P&L
A1: LITTLE WING — 2027 P&L
A2: Current staffing vs adjusted single-shift (6am–4pm, wknd 2nd barista) · annual · the gap is almost entirely labor
B4: Current | C4: % rev | D4: Adjusted | E4: % rev | F4: Change
A5: Food revenue | B5: ='LW Assumptions'!C5 -> 106838.2 | C5: =B5/B10 -> 0.40134256 | D5: ='LW Assumptions'!C5 -> 106838.2 | E5: =D5/D10 -> 0.40134256 | F5: =D5-B5 -> 0
A6: NA / Coffee revenue | B6: ='LW Assumptions'!C6 -> 131727.36 | C6: =B6/B10 -> 0.49483982 | D6: ='LW Assumptions'!C6 -> 131727.36 | E6: =D6/D10 -> 0.49483982 | F6: =D6-B6 -> 0
A7: Alcohol revenue | B7: ='LW Assumptions'!C7 -> 13996.3 | C7: =B7/B10 -> 0.052577738 | D7: ='LW Assumptions'!C7 -> 13996.3 | E7: =D7/D10 -> 0.052577738 | F7: =D7-B7 -> 0
A8: Retail / merch revenue | B8: ='LW Assumptions'!C8 -> 5847.56 | C8: =B8/B10 -> 0.021966625 | D8: ='LW Assumptions'!C8 -> 5847.56 | E8: =D8/D10 -> 0.021966625 | F8: =D8-B8 -> 0
A9: Other revenue | B9: ='LW Assumptions'!C9 -> 7792.6 | C9: =B9/B10 -> 0.029273256 | D9: ='LW Assumptions'!C9 -> 7792.6 | E9: =D9/D10 -> 0.029273256 | F9: =D9-B9 -> 0
A10: TOTAL REVENUE | B10: =SUM(B5:B9) -> 266202.02 | C10: =B10/B10 -> 1 | D10: =SUM(D5:D9) -> 266202.02 | E10: =D10/D10 -> 1 | F10: =D10-B10 -> 0
A12: Food COGS | B12: =B5*'LW Assumptions'!C13 -> 47083.595 | C12: =B12/B5 -> 0.4407 | D12: =D5*'LW Assumptions'!C13 -> 47083.595 | E12: =D12/D5 -> 0.4407 | F12: =D12-B12 -> 0
A13: NA / Coffee COGS | B13: =B6*'LW Assumptions'!C14 -> 29190.783 | C13: =B13/B6 -> 0.2216 | D13: =D6*'LW Assumptions'!C14 -> 29190.783 | E13: =D13/D6 -> 0.2216 | F13: =D13-B13 -> 0
A14: Alcohol COGS | B14: =B7*'LW Assumptions'!C15 -> 4657.9686 | C14: =B14/B7 -> 0.3328 | D14: =D7*'LW Assumptions'!C15 -> 4657.9686 | E14: =D14/D7 -> 0.3328 | F14: =D14-B14 -> 0
A15: Retail COGS | B15: =B8*'LW Assumptions'!C16 -> 0 | C15: =B15/B8 -> 0 | D15: =D8*'LW Assumptions'!C16 -> 0 | E15: =D15/D8 -> 0 | F15: =D15-B15 -> 0
A16: Other COGS | B16: =B9*'LW Assumptions'!C17 -> 0 | C16: =B16/B9 -> 0 | D16: =D9*'LW Assumptions'!C17 -> 0 | E16: =D16/D9 -> 0 | F16: =D16-B16 -> 0
A17: TOTAL COGS | B17: =SUM(B12:B16) -> 80932.346 | C17: =B17/B10 -> 0.30402604 | D17: =SUM(D12:D16) -> 80932.346 | E17: =D17/D10 -> 0.30402604 | F17: =D17-B17 -> 0
A18: GROSS PROFIT | B18: =B10-B17 -> 185269.67 | C18: =B18/B10 -> 0.69597396 | D18: =D10-D17 -> 185269.67 | E18: =D18/D10 -> 0.69597396 | F18: =D18-B18 -> 0
A20: Labor | B20: ='LW Assumptions'!C28 -> 164857 | C20: =B20/B10 -> 0.61929282 | D20: ='LW Assumptions'!C25 -> 94099.2 | E20: =D20/D10 -> 0.35348793 | F20: =D20-B20 -> -70757.8
A21: Credit card fees | B21: ='LW Assumptions'!$C$42 -> 10012 | C21: =B21/B10 -> 0.037610534 | D21: =D10*'LW Assumptions'!C31 -> 6655.0505 | E21: =D21/D10 -> 0.025 | F21: =D21-B21 -> -3356.9495
A22: Controllable (excl CC) | B22: ='LW Assumptions'!C32 -> 89675 | C22: =B22/B10 -> 0.33686822 | D22: ='LW Assumptions'!C32 -> 89675 | E22: =D22/D10 -> 0.33686822 | F22: =D22-B22 -> 0
A23: Non-controllable | B23: ='LW Assumptions'!C33 -> 5657 | C23: =B23/B10 -> 0.021250778 | D23: ='LW Assumptions'!C33 -> 5657 | E23: =D23/D10 -> 0.021250778 | F23: =D23-B23 -> 0
A24: Management fee (4% of revenue) | B24: =B10*'LW Assumptions'!$C$40 -> 10648.081 | C24: =B24/B10 -> 0.04 | D24: =D10*'LW Assumptions'!$C$40 -> 10648.081 | E24: =D24/D10 -> 0.04 | F24: =D24-B24 -> 0
A25: Rent (6% of revenue) | B25: =B10*'LW Assumptions'!$C$41 -> 15972.121 | C25: =B25/B10 -> 0.06 | D25: =D10*'LW Assumptions'!$C$41 -> 15972.121 | E25: =D25/D10 -> 0.06 | F25: =D25-B25 -> 0
A26: TOTAL COSTS BELOW GROSS | B26: =SUM(B20:B25) -> 296821.2 | C26: =B26/B10 -> 1.1150224 | D26: =SUM(D20:D25) -> 222706.45 | E26: =D26/D10 -> 0.83660692 | F26: =D26-B26 -> -74114.75
A28: NET OPERATING INCOME (after mgmt fee & rent) | B28: =B18-B26 -> -111551.53 | C28: =B28/B10 -> -0.41904839 | D28: =D18-D26 -> -37436.779 | E28: =D28/D10 -> -0.14063296 | F28: =D28-B28 -> 74114.75
A34: Labor savings from the single-shift model: | F34: =B20-D20 -> 70757.8
A35: Both columns use go-forward owner terms (4% mgmt fee + 6% rent) so the gap is purely the labor model. Management fee now scales with revenue (replaces the $48K flat fee).

Sheet LW Budget
A1: LITTLE WING — 2027 BUDGET
A2: Adjusted single-shift model (6am–4pm) · $ and % of revenue each month · driven by LW Assumptions
A4: ($ / % of revenue) | B4: Jan | D4: Feb | F4: Mar | H4: Apr | J4: May | L4: Jun | N4: Jul | P4: Aug | R4: Sep | T4: Oct | V4: Nov | X4: Dec | Z4: FY 2027
A5: Revenue index (Jan–Jun = actual Toast · avg = 1.00) | B5: 0.7037 | D5: 0.81 | F5: 1.2058 | H5: 0.9305 | J5: 1.123 | L5: 1.227 | N5: =AVERAGE($B5,$D5,$F5,$H5,$J5,$L5) -> 1 | P5: =AVERAGE($B5,$D5,$F5,$H5,$J5,$L5) -> 1 | R5: =AVERAGE($B5,$D5,$F5,$H5,$J5,$L5) -> 1 | T5: =AVERAGE($B5,$D5,$F5,$H5,$J5,$L5) -> 1 | V5: =AVERAGE($B5,$D5,$F5,$H5,$J5,$L5) -> 1 | X5: =AVERAGE($B5,$D5,$F5,$H5,$J5,$L5) -> 1 | Z5: =AVERAGE(B5,D5,F5,H5,J5,L5,N5,P5,R5,T5,V5,X5) -> 1
A6: Food revenue | B6: =('LW Assumptions'!$C$5/12)*B5 -> 6265.1701 | C6: =B6/B11 -> 0.37259589 | D6: =('LW Assumptions'!$C$5/12)*D5 -> 7211.5785 | E6: =D6/D11 -> 0.37259589 | F6: =('LW Assumptions'!$C$5/12)*F5 -> 10735.458 | G6: =F6/F11 -> 0.37259589 | H6: =('LW Assumptions'!$C$5/12)*H5 -> 8284.4121 | I6: =H6/H11 -> 0.37259589 | J6: =('LW Assumptions'!$C$5/12)*J5 -> 9998.2749 | K6: =J6/J11 -> 0.37259589 | L6: =('LW Assumptions'!$C$5/12)*L5 -> 10924.206 | M6: =L6/L11 -> 0.37259589 | N6: =('LW Assumptions'!$C$5/12)*N5 -> 8903.1833 | O6: =N6/N11 -> 0.37259589 | P6: =('LW Assumptions'!$C$5/12)*P5 -> 8903.1833 | Q6: =P6/P11 -> 0.37259589 | R6: =('LW Assumptions'!$C$5/12)*R5 -> 8903.1833 | S6: =R6/R11 -> 0.37259589 | T6: =('LW Assumptions'!$C$5/12)*T5 -> 8903.1833 | U6: =T6/T11 -> 0.37259589 | V6: =('LW Assumptions'!$C$5/12)*V5 -> 8903.1833 | W6: =V6/V11 -> 0.37259589 | X6: =('LW Assumptions'!$C$5/12)*X5 -> 8903.1833 | Y6: =X6/X11 -> 0.37259589 | Z6: =B6+D6+F6+H6+J6+L6+N6+P6+R6+T6+V6+X6 -> 106838.2 | AA6: =Z6/Z11 -> 0.37259589
A7: NA / Coffee revenue | B7: =('LW Assumptions'!$C$6/12)*B5 -> 7724.7119 | C7: =B7/B11 -> 0.45939629 | D7: =('LW Assumptions'!$C$6/12)*D5 -> 8891.5968 | E7: =D7/D11 -> 0.45939629 | F7: =('LW Assumptions'!$C$6/12)*F5 -> 13236.404 | G7: =F7/F11 -> 0.45939629 | H7: =('LW Assumptions'!$C$6/12)*H5 -> 10214.359 | I7: =H7/H11 -> 0.45939629 | J7: =('LW Assumptions'!$C$6/12)*J5 -> 12327.485 | K7: =J7/J11 -> 0.45939629 | L7: =('LW Assumptions'!$C$6/12)*L5 -> 13469.123 | M7: =L7/L11 -> 0.45939629 | N7: =('LW Assumptions'!$C$6/12)*N5 -> 10977.28 | O7: =N7/N11 -> 0.45939629 | P7: =('LW Assumptions'!$C$6/12)*P5 -> 10977.28 | Q7: =P7/P11 -> 0.45939629 | R7: =('LW Assumptions'!$C$6/12)*R5 -> 10977.28 | S7: =R7/R11 -> 0.45939629 | T7: =('LW Assumptions'!$C$6/12)*T5 -> 10977.28 | U7: =T7/T11 -> 0.45939629 | V7: =('LW Assumptions'!$C$6/12)*V5 -> 10977.28 | W7: =V7/V11 -> 0.45939629 | X7: =('LW Assumptions'!$C$6/12)*X5 -> 10977.28 | Y7: =X7/X11 -> 0.45939629 | Z7: =B7+D7+F7+H7+J7+L7+N7+P7+R7+T7+V7+X7 -> 131727.36 | AA7: =Z7/Z11 -> 0.45939629
A8: Alcohol revenue | B8: =('LW Assumptions'!$C$7/12)*B5 -> 820.76636 | C8: =B8/B11 -> 0.04881179 | D8: =('LW Assumptions'!$C$7/12)*D5 -> 944.75025 | E8: =D8/D11 -> 0.04881179 | F8: =('LW Assumptions'!$C$7/12)*F5 -> 1406.3949 | G8: =F8/F11 -> 0.04881179 | H8: =('LW Assumptions'!$C$7/12)*H5 -> 1085.2964 | I8: =H8/H11 -> 0.04881179 | J8: =('LW Assumptions'!$C$7/12)*J5 -> 1309.8204 | K8: =J8/J11 -> 0.04881179 | L8: =('LW Assumptions'!$C$7/12)*L5 -> 1431.1217 | M8: =L8/L11 -> 0.04881179 | N8: =('LW Assumptions'!$C$7/12)*N5 -> 1166.3583 | O8: =N8/N11 -> 0.04881179 | P8: =('LW Assumptions'!$C$7/12)*P5 -> 1166.3583 | Q8: =P8/P11 -> 0.04881179 | R8: =('LW Assumptions'!$C$7/12)*R5 -> 1166.3583 | S8: =R8/R11 -> 0.04881179 | T8: =('LW Assumptions'!$C$7/12)*T5 -> 1166.3583 | U8: =T8/T11 -> 0.04881179 | V8: =('LW Assumptions'!$C$7/12)*V5 -> 1166.3583 | W8: =V8/V11 -> 0.04881179 | X8: =('LW Assumptions'!$C$7/12)*X5 -> 1166.3583 | Y8: =X8/X11 -> 0.04881179 | Z8: =B8+D8+F8+H8+J8+L8+N8+P8+R8+T8+V8+X8 -> 13996.3 | AA8: =Z8/Z11 -> 0.04881179
A9: Retail / merch revenue (incl. uplift) | B9: =('LW Assumptions'!$C$8/12)*B5*(1+'LW Assumptions'!$C$46) -> 514.366 | C9: =B9/B11 -> 0.030589856 | D9: =('LW Assumptions'!$C$8/12)*D5*(1+'LW Assumptions'!$C$46) -> 592.06545 | E9: =D9/D11 -> 0.030589856 | F9: =('LW Assumptions'!$C$8/12)*F5*(1+'LW Assumptions'!$C$46) -> 881.37348 | G9: =F9/F11 -> 0.030589856 | H9: =('LW Assumptions'!$C$8/12)*H5*(1+'LW Assumptions'!$C$46) -> 680.14432 | I9: =H9/H11 -> 0.030589856 | J9: =('LW Assumptions'!$C$8/12)*J5*(1+'LW Assumptions'!$C$46) -> 820.85123 | K9: =J9/J11 -> 0.030589856 | L9: =('LW Assumptions'!$C$8/12)*L5*(1+'LW Assumptions'!$C$46) -> 896.86951 | M9: =L9/L11 -> 0.030589856 | N9: =('LW Assumptions'!$C$8/12)*N5*(1+'LW Assumptions'!$C$46) -> 730.945 | O9: =N9/N11 -> 0.030589856 | P9: =('LW Assumptions'!$C$8/12)*P5*(1+'LW Assumptions'!$C$46) -> 730.945 | Q9: =P9/P11 -> 0.030589856 | R9: =('LW Assumptions'!$C$8/12)*R5*(1+'LW Assumptions'!$C$46) -> 730.945 | S9: =R9/R11 -> 0.030589856 | T9: =('LW Assumptions'!$C$8/12)*T5*(1+'LW Assumptions'!$C$46) -> 730.945 | U9: =T9/T11 -> 0.030589856 | V9: =('LW Assumptions'!$C$8/12)*V5*(1+'LW Assumptions'!$C$46) -> 730.945 | W9: =V9/V11 -> 0.030589856 | X9: =('LW Assumptions'!$C$8/12)*X5*(1+'LW Assumptions'!$C$46) -> 730.945 | Y9: =X9/X11 -> 0.030589856 | Z9: =B9+D9+F9+H9+J9+L9+N9+P9+R9+T9+V9+X9 -> 8771.34 | AA9: =Z9/Z11 -> 0.030589856
